Workbook

Sheet Sheet3
L14: SKU | M14: Frozen | N14: SKU | O14: Fresh
J15: Ceker | K15: =121.75+133.92+119.95 -> 375.62 | M15: 279.63 | O15: =+K15-M15 -> 95.99

Sheet Pot_ISA11+Blasting
I1: =+I8/E10 -> 0
A2: Harga Perolehan
A3: Live Bird | B3: 168000000 | C3: 7000 | G3: Supplier | H3: PT Bounty Segar Distribution | I3: =+B3/C3 -> 24000
A4: Biaya Ekspedisi | B4: 7000000 | G4: Tgl. Potong | H4: 46334
A5: Biaya Potong | B5: =10553120+1762160 -> 12315280
A6: Total | B6: =SUM(B3:B5) -> 187315280
K8: Est. GP Margin | L8: =SUM(K11:K65)/M10-1 -> -0.062718215
A9: Produk | B9: Price/Kg | C9: Satuan | E9: SKU Fresh | F9: Non Blasting | G9: No. SKU | H9: Item Name | I9: Qty | J9: Yield | K9: Est. Harga Jual | L9: COGS/Kg | M9: COGS/Item | N9: (Price/Kg - COGS/Kg) | O9: (Est. Harga Jual - COGS/Item) | P9: Notes
E10: =+C3 -> 7000 | F10: =+B6 -> 187315280 | I10: =SUM(I11:I79) -> 5914.9 | J10: =+SUM(J11:J79) -> 0.84498571 | K10: =+SUM(K11:K79) -> 176190200 | M10: =+SUM(M11:M79) -> 187315280 | O10: =+SUM(O11:O79) -> -11125080
A11: AU 0.3 | B11: =_xlfn.IFNA(_xlfn.XLOOKUP(A11,'Price list'!D:D,'Price list'!E:E),0) -> 0 | C11: Kg | H11: =IF(G11=0,"",_xlfn.XLOOKUP(G11,List_item!A:A,List_item!B:B)) | J11: =IF(F11/E$10>0,F11/E$10,I11/E$10) -> 0 | K11: =+B11*(F11+I11) -> 0 | L11: =IFERROR(((K11/SUM($K$11:$K$79))*$F$10)/(F11+I11),0) -> 0 | M11: =+L11*(F11+I11) -> 0 | N11: =IF(L11=0,0,B11-L11) -> 0 | O11: =+K11-M11 -> 0
A12: AU 0.4 | B12: =_xlfn.IFNA(_xlfn.XLOOKUP(A12,'Price list'!D:D,'Price list'!E:E),0) -> 0 | C12: Kg | H12: =IF(G12=0,"",_xlfn.XLOOKUP(G12,List_item!A:A,List_item!B:B)) | J12: =IF(F12/E$10>0,F12/E$10,I12/E$10) -> 0 | K12: =+B12*(F12+I12) -> 0 | L12: =IFERROR(((K12/SUM($K$11:$K$79))*$F$10)/(F12+I12),0) -> 0 | M12: =+L12*(F12+I12) -> 0 | N12: =IF(L12=0,0,B12-L12) -> 0 | O12: =+K12-M12 -> 0
A13: AU 0.5 | B13: =_xlfn.IFNA(_xlfn.XLOOKUP(A13,'Price list'!D:D,'Price list'!E:E),0) -> 36500 | C13: Kg | H13: =IF(G13=0,"",_xlfn.XLOOKUP(G13,List_item!A:A,List_item!B:B)) | J13: =IF(F13/E$10>0,F13/E$10,I13/E$10) -> 0 | K13: =+B13*(F13+I13) -> 0 | L13: =IFERROR(((K13/SUM($K$11:$K$79))*$F$10)/(F13+I13),0) -> 0 | M13: =+L13*(F13+I13) -> 0 | N13: =IF(L13=0,0,B13-L13) -> 0 | O13: =+K13-M13 -> 0
A14: AU 0.6 | B14: =_xlfn.IFNA(_xlfn.XLOOKUP(A14,'Price list'!D:D,'Price list'!E:E),0) -> 36500 | C14: Kg | H14: =IF(G14=0,"",_xlfn.XLOOKUP(G14,List_item!A:A,List_item!B:B)) | J14: =IF(F14/E$10>0,F14/E$10,I14/E$10) -> 0 | K14: =+B14*(F14+I14) -> 0 | L14: =IFERROR(((K14/SUM($K$11:$K$79))*$F$10)/(F14+I14),0) -> 0 | M14: =+L14*(F14+I14) -> 0 | N14: =IF(L14=0,0,B14-L14) -> 0 | O14: =+K14-M14 -> 0
A15: AU 0.7 | B15: =_xlfn.IFNA(_xlfn.XLOOKUP(A15,'Price list'!D:D,'Price list'!E:E),0) -> 36500 | C15: Kg | H15: =IF(G15=0,"",_xlfn.XLOOKUP(G15,List_item!A:A,List_item!B:B)) | J15: =IF(F15/E$10>0,F15/E$10,I15/E$10) -> 0 | K15: =+B15*(F15+I15) -> 0 | L15: =IFERROR(((K15/SUM($K$11:$K$79))*$F$10)/(F15+I15),0) -> 0 | M15: =+L15*(F15+I15) -> 0 | N15: =IF(L15=0,0,B15-L15) -> 0 | O15: =+K15-M15 -> 0
A16: AU 0.8 | B16: =_xlfn.IFNA(_xlfn.XLOOKUP(A16,'Price list'!D:D,'Price list'!E:E),0) -> 36500 | C16: Kg | G16: JLB1867 | H16: =IF(G16=0,"",_xlfn.XLOOKUP(G16,List_item!A:A,List_item!B:B)) -> Karkas Uk 0.7 Karkas Uk 0.7 Frozen Premium | I16: 7.7 | J16: =IF(F16/E$10>0,F16/E$10,I16/E$10) -> 0.0011 | K16: =+B16*(F16+I16) -> 281050 | L16: =IFERROR(((K16/SUM($K$11:$K$79))*$F$10)/(F16+I16),0) -> 38804.699 | M16: =+L16*(F16+I16) -> 298796.18 | N16: =IF(L16=0,0,B16-L16) -> -2304.6992 | O16: =+K16-M16 -> -17746.184
A17: AU 0.9 | B17: =_xlfn.IFNA(_xlfn.XLOOKUP(A17,'Price list'!D:D,'Price list'!E:E),0) -> 36500 | C17: Kg | G17: JLB1859 | H17: =IF(G17=0,"",_xlfn.XLOOKUP(G17,List_item!A:A,List_item!B:B)) -> Karkas Uk 0.8 Frozen Premium | I17: 9.7 | J17: =IF(F17/E$10>0,F17/E$10,I17/E$10) -> 0.0013857143 | K17: =+B17*(F17+I17) -> 354050 | L17: =IFERROR(((K17/SUM($K$11:$K$79))*$F$10)/(F17+I17),0) -> 38804.699 | M17: =+L17*(F17+I17) -> 376405.58 | N17: =IF(L17=0,0,B17-L17) -> -2304.6992 | O17: =+K17-M17 -> -22355.583
A18: AU 1.0 | B18: =_xlfn.IFNA(_xlfn.XLOOKUP(A18,'Price list'!D:D,'Price list'!E:E),0) -> 36500 | C18: Kg | G18: JLB0690 | H18: =IF(G18=0,"",_xlfn.XLOOKUP(G18,List_item!A:A,List_item!B:B)) -> Karkas Uk 1.0 Karkas Uk 1.0 Frozen Premium | I18: 21.4 | J18: =IF(F18/E$10>0,F18/E$10,I18/E$10) -> 0.0030571429 | K18: =+B18*(F18+I18) -> 781100 | L18: =IFERROR(((K18/SUM($K$11:$K$79))*$F$10)/(F18+I18),0) -> 38804.699 | M18: =+L18*(F18+I18) -> 830420.56 | N18: =IF(L18=0,0,B18-L18) -> -2304.6992 | O18: =+K18-M18 -> -49320.564
A19: AU 1.1 | B19: =_xlfn.IFNA(_xlfn.XLOOKUP(A19,'Price list'!D:D,'Price list'!E:E),0) -> 36500 | C19: Kg | G19: JLB0756 | H19: =IF(G19=0,"",_xlfn.XLOOKUP(G19,List_item!A:A,List_item!B:B)) -> Karkas Uk 1.1 Karkas Uk 1.1 Frozen Premium | I19: 75.9 | J19: =IF(F19/E$10>0,F19/E$10,I19/E$10) -> 0.010842857 | K19: =+B19*(F19+I19) -> 2770350 | L19: =IFERROR(((K19/SUM($K$11:$K$79))*$F$10)/(F19+I19),0) -> 38804.699 | M19: =+L19*(F19+I19) -> 2945276.7 | N19: =IF(L19=0,0,B19-L19) -> -2304.6992 | O19: =+K19-M19 -> -174926.67
A20: AU 1.2 | B20: =_xlfn.IFNA(_xlfn.XLOOKUP(A20,'Price list'!D:D,'Price list'!E:E),0) -> 36500 | C20: Kg | G20: JLB0822 | H20: =IF(G20=0,"",_xlfn.XLOOKUP(G20,List_item!A:A,List_item!B:B)) -> Karkas Uk 1.2 Karkas Uk 1.2 Frozen Premium | I20: 189.6 | J20: =IF(F20/E$10>0,F20/E$10,I20/E$10) -> 0.027085714 | K20: =+B20*(F20+I20) -> 6920400 | L20: =IFERROR(((K20/SUM($K$11:$K$79))*$F$10)/(F20+I20),0) -> 38804.699 | M20: =+L20*(F20+I20) -> 7357371 | N20: =IF(L20=0,0,B20-L20) -> -2304.6992 | O20: =+K20-M20 -> -436970.98
A21: AU 1.3 | B21: =_xlfn.IFNA(_xlfn.XLOOKUP(A21,'Price list'!D:D,'Price list'!E:E),0) -> 36500 | C21: Kg | G21: JLB0856 | H21: =IF(G21=0,"",_xlfn.XLOOKUP(G21,List_item!A:A,List_item!B:B)) -> Karkas Uk 1.3 Karkas Uk 1.3 Fresh Premium | I21: 356.9 | J21: =IF(F21/E$10>0,F21/E$10,I21/E$10) -> 0.050985714 | K21: =+B21*(F21+I21) -> 13026850 | L21: =IFERROR(((K21/SUM($K$11:$K$79))*$F$10)/(F21+I21),0) -> 38804.699 | M21: =+L21*(F21+I21) -> 13849397 | N21: =IF(L21=0,0,B21-L21) -> -2304.6992 | O21: =+K21-M21 -> -822547.16
A22: AU 1.4 | B22: =_xlfn.IFNA(_xlfn.XLOOKUP(A22,'Price list'!D:D,'Price list'!E:E),0) -> 36500 | C22: Kg | G22: JLB0922 | H22: =IF(G22=0,"",_xlfn.XLOOKUP(G22,List_item!A:A,List_item!B:B)) -> Karkas Uk 1.4 Karkas Uk 1.4 Fresh Premium | I22: 608.4 | J22: =IF(F22/E$10>0,F22/E$10,I22/E$10) -> 0.086914286 | K22: =+B22*(F22+I22) -> 22206600 | L22: =IFERROR(((K22/SUM($K$11:$K$79))*$F$10)/(F22+I22),0) -> 38804.699 | M22: =+L22*(F22+I22) -> 23608779 | N22: =IF(L22=0,0,B22-L22) -> -2304.6992 | O22: =+K22-M22 -> -1402179
A23: AU 1.5 | B23: =_xlfn.IFNA(_xlfn.XLOOKUP(A23,'Price list'!D:D,'Price list'!E:E),0) -> 36500 | C23: Kg | G23: JLB0988 | H23: =IF(G23=0,"",_xlfn.XLOOKUP(G23,List_item!A:A,List_item!B:B)) -> Karkas Uk 1.5 Karkas Uk 1.5 Fresh Premium | I23: 840.7 | J23: =IF(F23/E$10>0,F23/E$10,I23/E$10) -> 0.1201 | K23: =+B23*(F23+I23) -> 30685550 | L23: =IFERROR(((K23/SUM($K$11:$K$79))*$F$10)/(F23+I23),0) -> 38804.699 | M23: =+L23*(F23+I23) -> 32623111 | N23: =IF(L23=0,0,B23-L23) -> -2304.6992 | O23: =+K23-M23 -> -1937560.7
A24: AU 1.6 | B24: =_xlfn.IFNA(_xlfn.XLOOKUP(A24,'Price list'!D:D,'Price list'!E:E),0) -> 36500 | C24: Kg | G24: JLB1054 | H24: =IF(G24=0,"",_xlfn.XLOOKUP(G24,List_item!A:A,List_item!B:B)) -> Karkas Uk 1.6 Karkas Uk 1.6 Fresh Premium | I24: 807.1 | J24: =IF(F24/E$10>0,F24/E$10,I24/E$10) -> 0.1153 | K24: =+B24*(F24+I24) -> 29459150 | L24: =IFERROR(((K24/SUM($K$11:$K$79))*$F$10)/(F24+I24),0) -> 38804.699 | M24: =+L24*(F24+I24) -> 31319273 | N24: =IF(L24=0,0,B24-L24) -> -2304.6992 | O24: =+K24-M24 -> -1860122.8
A25: AU 1.7 | B25: =_xlfn.IFNA(_xlfn.XLOOKUP(A25,'Price list'!D:D,'Price list'!E:E),0) -> 36500 | C25: Kg | G25: JLB1152 | H25: =IF(G25=0,"",_xlfn.XLOOKUP(G25,List_item!A:A,List_item!B:B)) -> Karkas Uk 1.7 Karkas Uk 1.7 Frozen Premium | I25: 638.7 | J25: =IF(F25/E$10>0,F25/E$10,I25/E$10) -> 0.091242857 | K25: =+B25*(F25+I25) -> 23312550 | L25: =IFERROR(((K25/SUM($K$11:$K$79))*$F$10)/(F25+I25),0) -> 38804.699 | M25: =+L25*(F25+I25) -> 24784561 | N25: =IF(L25=0,0,B25-L25) -> -2304.6992 | O25: =+K25-M25 -> -1472011.4
A26: AU 1.8 | B26: =_xlfn.IFNA(_xlfn.XLOOKUP(A26,'Price list'!D:D,'Price list'!E:E),0) -> 36500 | C26: Kg | G26: JLB1218 | H26: =IF(G26=0,"",_xlfn.XLOOKUP(G26,List_item!A:A,List_item!B:B)) -> Karkas Uk 1.8 Karkas Uk 1.8 Frozen Premium | I26: 553.1 | J26: =IF(F26/E$10>0,F26/E$10,I26/E$10) -> 0.079014286 | K26: =+B26*(F26+I26) -> 20188150 | L26: =IFERROR(((K26/SUM($K$11:$K$79))*$F$10)/(F26+I26),0) -> 38804.699 | M26: =+L26*(F26+I26) -> 21462879 | N26: =IF(L26=0,0,B26-L26) -> -2304.6992 | O26: =+K26-M26 -> -1274729.1
A27: AU 1.9 | B27: =_xlfn.IFNA(_xlfn.XLOOKUP(A27,'Price list'!D:D,'Price list'!E:E),0) -> 36500 | C27: Kg | G27: JLB1350 | H27: =IF(G27=0,"",_xlfn.XLOOKUP(G27,List_item!A:A,List_item!B:B)) -> Karkas Uk 2.0 Karkas Uk 2.0 Frozen Premium | I27: 192.2 | J27: =IF(F27/E$10>0,F27/E$10,I27/E$10) -> 0.027457143 | K27: =+B27*(F27+I27) -> 7015300 | L27: =IFERROR(((K27/SUM($K$11:$K$79))*$F$10)/(F27+I27),0) -> 38804.699 | M27: =+L27*(F27+I27) -> 7458263.2 | N27: =IF(L27=0,0,B27-L27) -> -2304.6992 | O27: =+K27-M27 -> -442963.19
A28: AU 2.0 | B28: =_xlfn.IFNA(_xlfn.XLOOKUP(A28,'Price list'!D:D,'Price list'!E:E),0) -> 36500 | C28: Kg | H28: =IF(G28=0,"",_xlfn.XLOOKUP(G28,List_item!A:A,List_item!B:B)) | J28: =IF(F28/E$10>0,F28/E$10,I28/E$10) -> 0 | K28: =+B28*(F28+I28) -> 0 | L28: =IFERROR(((K28/SUM($K$11:$K$79))*$F$10)/(F28+I28),0) -> 0 | M28: =+L28*(F28+I28) -> 0 | N28: =IF(L28=0,0,B28-L28) -> 0 | O28: =+K28-M28 -> 0
A29: AU UP | B29: =_xlfn.IFNA(_xlfn.XLOOKUP(A29,'Price list'!D:D,'Price list'!E:E),0) -> 0 | C29: Kg | H29: =IF(G29=0,"",_xlfn.XLOOKUP(G29,List_item!A:A,List_item!B:B)) | J29: =IF(F29/E$10>0,F29/E$10,I29/E$10) -> 0 | K29: =+B29*(F29+I29) -> 0 | L29: =IFERROR(((K29/SUM($K$11:$K$79))*$F$10)/(F29+I29),0) -> 0 | M29: =+L29*(F29+I29) -> 0 | N29: =IF(L29=0,0,B29-L29) -> 0 | O29: =+K29-M29 -> 0
A30: BLD | B30: =_xlfn.IFNA(_xlfn.XLOOKUP(A30,'Price list'!D:D,'Price list'!E:E),0) -> 50000 | C30: Kg | H30: =IF(G30=0,"",_xlfn.XLOOKUP(G30,List_item!A:A,List_item!B:B)) | J30: =IF(F30/E$10>0,F30/E$10,I30/E$10) -> 0 | K30: =+B30*(F30+I30) -> 0 | L30: =IFERROR(((K30/SUM($K$11:$K$79))*$F$10)/(F30+I30),0) -> 0 | M30: =+L30*(F30+I30) -> 0 | N30: =IF(L30=0,0,B30-L30) -> 0 | O30: =+K30-M30 -> 0
A31: BLPK | B31: =_xlfn.IFNA(_xlfn.XLOOKUP(A31,'Price list'!D:D,'Price list'!E:E),0) -> 48000 | C31: Kg | H31: =IF(G31=0,"",_xlfn.XLOOKUP(G31,List_item!A:A,List_item!B:B)) | J31: =IF(F31/E$10>0,F31/E$10,I31/E$10) -> 0 | K31: =+B31*(F31+I31) -> 0 | L31: =IFERROR(((K31/SUM($K$11:$K$79))*$F$10)/(F31+I31),0) -> 0 | M31: =+L31*(F31+I31) -> 0 | N31: =IF(L31=0,0,B31-L31) -> 0 | O31: =+K31-M31 -> 0
A32: BLP | B32: =_xlfn.IFNA(_xlfn.XLOOKUP(A32,'Price list'!D:D,'Price list'!E:E),0) -> 49000 | C32: Kg | H32: =IF(G32=0,"",_xlfn.XLOOKUP(G32,List_item!A:A,List_item!B:B)) | J32: =IF(F32/E$10>0,F32/E$10,I32/E$10) -> 0 | K32: =+B32*(F32+I32) -> 0 | L32: =IFERROR(((K32/SUM($K$11:$K$79))*$F$10)/(F32+I32),0) -> 0 | M32: =+L32*(F32+I32) -> 0 | N32: =IF(L32=0,0,B32-L32) -> 0 | O32: =+K32-M32 -> 0
A33: Krk | B33: =_xlfn.IFNA(_xlfn.XLOOKUP(A33,'Price list'!D:D,'Price list'!E:E),0) -> 5500 | C33: Kg | H33: =IF(G33=0,"",_xlfn.XLOOKUP(G33,List_item!A:A,List_item!B:B)) | J33: =IF(F33/E$10>0,F33/E$10,I33/E$10) -> 0 | K33: =+B33*(F33+I33) -> 0 | L33: =IFERROR(((K33/SUM($K$11:$K$79))*$F$10)/(F33+I33),0) -> 0 | M33: =+L33*(F33+I33) -> 0 | N33: =IF(L33=0,0,B33-L33) -> 0 | O33: =+K33-M33 -> 0
A34: kulit | B34: =_xlfn.IFNA(_xlfn.XLOOKUP(A34,'Price list'!D:D,'Price list'!E:E),0) -> 20000 | C34: Kg | H34: =IF(G34=0,"",_xlfn.XLOOKUP(G34,List_item!A:A,List_item!B:B)) | J34: =IF(F34/E$10>0,F34/E$10,I34/E$10) -> 0 | K34: =+B34*(F34+I34) -> 0 | L34: =IFERROR(((K34/SUM($K$11:$K$79))*$F$10)/(F34+I34),0) -> 0 | M34: =+L34*(F34+I34) -> 0 | N34: =IF(L34=0,0,B34-L34) -> 0 | O34: =+K34-M34 -> 0
A35: Sayap | B35: =_xlfn.IFNA(_xlfn.XLOOKUP(A35,'Price list'!D:D,'Price list'!E:E),0) -> 22000 | C35: Kg | H35: =IF(G35=0,"",_xlfn.XLOOKUP(G35,List_item!A:A,List_item!B:B)) | J35: =IF(F35/E$10>0,F35/E$10,I35/E$10) -> 0 | K35: =+B35*(F35+I35) -> 0 | L35: =IFERROR(((K35/SUM($K$11:$K$79))*$F$10)/(F35+I35),0) -> 0 | M35: =+L35*(F35+I35) -> 0 | N35: =IF(L35=0,0,B35-L35) -> 0 | O35: =+K35-M35 -> 0
A36: Sayap grade A | B36: =_xlfn.IFNA(_xlfn.XLOOKUP(A36,'Price list'!D:D,'Price list'!E:E),0) -> 18000 | C36: Kg | H36: =IF(G36=0,"",_xlfn.XLOOKUP(G36,List_item!A:A,List_item!B:B)) | J36: =IF(F36/E$10>0,F36/E$10,I36/E$10) -> 0 | K36: =+B36*(F36+I36) -> 0 | L36: =IFERROR(((K36/SUM($K$11:$K$79))*$F$10)/(F36+I36),0) -> 0 | M36: =+L36*(F36+I36) -> 0 | N36: =IF(L36=0,0,B36-L36) -> 0 | O36: =+K36-M36 -> 0
A37: TLP | B37: =_xlfn.IFNA(_xlfn.XLOOKUP(A37,'Price list'!D:D,'Price list'!E:E),0) -> 3500 | C37: Kg | H37: =IF(G37=0,"",_xlfn.XLOOKUP(G37,List_item!A:A,List_item!B:B)) | J37: =IF(F37/E$10>0,F37/E$10,I37/E$10) -> 0 | K37: =+B37*(F37+I37) -> 0 | L37: =IFERROR(((K37/SUM($K$11:$K$79))*$F$10)/(F37+I37),0) -> 0 | M37: =+L37*(F37+I37) -> 0 | N37: =IF(L37=0,0,B37-L37) -> 0 | O37: =+K37-M37 -> 0
A38: Paha Bawah | B38: =_xlfn.IFNA(_xlfn.XLOOKUP(A38,'Price list'!D:D,'Price list'!E:E),0) -> 38000 | C38: Kg | H38: =IF(G38=0,"",_xlfn.XLOOKUP(G38,List_item!A:A,List_item!B:B)) | J38: =IF(F38/E$10>0,F38/E$10,I38/E$10) -> 0 | K38: =+B38*(F38+I38) -> 0 | L38: =IFERROR(((K38/SUM($K$11:$K$79))*$F$10)/(F38+I38),0) -> 0 | M38: =+L38*(F38+I38) -> 0 | N38: =IF(L38=0,0,B38-L38) -> 0 | O38: =+K38-M38 -> 0
A39: Lemak | B39: =_xlfn.IFNA(_xlfn.XLOOKUP(A39,'Price list'!D:D,'Price list'!E:E),0) -> 18000 | C39: Kg | G39: JLB0118 | H39: =IF(G39=0,"",_xlfn.XLOOKUP(G39,List_item!A:A,List_item!B:B)) -> Boneless BL Fresh Lemak | I39: 22 | J39: =IF(F39/E$10>0,F39/E$10,I39/E$10) -> 0.0031428571 | K39: =+B39*(F39+I39) -> 396000 | L39: =IFERROR(((K39/SUM($K$11:$K$79))*$F$10)/(F39+I39),0) -> 19136.564 | M39: =+L39*(F39+I39) -> 421004.41 | N39: =IF(L39=0,0,B39-L39) -> -1136.564 | O39: =+K39-M39 -> -25004.408
A40: Kepala | B40: =_xlfn.IFNA(_xlfn.XLOOKUP(A40,'Price list'!D:D,'Price list'!E:E),0) -> 8000 | G40: JLB0092 | H40: =IF(G40=0,"",_xlfn.XLOOKUP(G40,List_item!A:A,List_item!B:B)) -> Boneless BL Fresh Kepala | I40: 323.2 | J40: =IF(F40/E$10>0,F40/E$10,I40/E$10) -> 0.046171429 | K40: =+B40*(F40+I40) -> 2585600 | L40: =IFERROR(((K40/SUM($K$11:$K$79))*$F$10)/(F40+I40),0) -> 8505.1396 | M40: =+L40*(F40+I40) -> 2748861.1 | N40: =IF(L40=0,0,B40-L40) -> -505.13956 | O40: =+K40-M40 -> -163261.11
A41: Ceker | B41: =_xlfn.IFNA(_xlfn.XLOOKUP(A41,'Price list'!D:D,'Price list'!E:E),0) -> 10000 | C41: Kg | G41: JLB0078 | H41: =IF(G41=0,"",_xlfn.XLOOKUP(G41,List_item!A:A,List_item!B:B)) -> Boneless BL Fresh Ceker | I41: 222.2 | J41: =IF(F41/E$10>0,F41/E$10,I41/E$10) -> 0.031742857 | K41: =+B41*(F41+I41) -> 2222000 | L41: =IFERROR(((K41/SUM($K$11:$K$79))*$F$10)/(F41+I41),0) -> 10631.424 | M41: =+L41*(F41+I41) -> 2362302.5 | N41: =IF(L41=0,0,B41-L41) -> -631.42445 | O41: =+K41-M41 -> -140302.51
...

Sheet Pot_ISA10+Blasting
I1: =+I8/E10 -> 0
A2: Harga Perolehan
A3: Live Bird | B3: =86856420+71978900+85096550 -> 243931870 | C3: =4002.6+3317+3921.5 -> 11241.1 | G3: Supplier | H3: Alberus | I3: =+B3/C3 -> 21700
A4: Biaya Ekspedisi | B4: 24000000 | G4: Tgl. Potong | H4: 46244
A5: Biaya Potong | B5: =16237920+1001920 -> 17239840
A6: Total | B6: =SUM(B3:B5) -> 285171710
K8: Est. GP Margin | L8: =SUM(K11:K65)/M10-1 -> 0.006998906
A9: Produk | B9: Price/Kg | C9: Satuan | E9: SKU Fresh | F9: Non Blasting | G9: No. SKU | H9: Item Name | I9: Qty | J9: Yield | K9: Est. Harga Jual | L9: COGS/Kg | M9: COGS/Item | N9: (Price/Kg - COGS/Kg) | O9: (Est. Harga Jual - COGS/Item) | P9: Notes
E10: =+C3 -> 11241.1 | F10: =+B6 -> 285171710 | I10: =SUM(I11:I79) -> 9497.3 | J10: =SUM(J11:J79) -> 0.84487283 | K10: =+SUM(K11:K79) -> 287167600 | M10: =+SUM(M11:M79) -> 285171710 | O10: =+SUM(O11:O79) -> 1995890
A11: AU 0.3 | B11: =_xlfn.IFNA(_xlfn.XLOOKUP(A11,'Price list'!D:D,'Price list'!E:E),0) -> 0 | C11: Kg | H11: =IF(G11=0,"",_xlfn.XLOOKUP(G11,List_item!A:A,List_item!B:B)) | I11: 0 | J11: =IF(F11/E$10>0,F11/E$10,I11/E$10) -> 0 | K11: =+B11*(F11+I11) -> 0 | L11: =IFERROR(((K11/SUM($K$11:$K$79))*$F$10)/(F11+I11),0) -> 0 | M11: =+L11*(F11+I11) -> 0 | N11: =IF(L11=0,0,B11-L11) -> 0 | O11: =+K11-M11 -> 0
A12: AU 0.4 | B12: =_xlfn.IFNA(_xlfn.XLOOKUP(A12,'Price list'!D:D,'Price list'!E:E),0) -> 0 | C12: Kg | H12: =IF(G12=0,"",_xlfn.XLOOKUP(G12,List_item!A:A,List_item!B:B)) | I12: 0 | J12: =IF(F12/E$10>0,F12/E$10,I12/E$10) -> 0 | K12: =+B12*(F12+I12) -> 0 | L12: =IFERROR(((K12/SUM($K$11:$K$79))*$F$10)/(F12+I12),0) -> 0 | M12: =+L12*(F12+I12) -> 0 | N12: =IF(L12=0,0,B12-L12) -> 0 | O12: =+K12-M12 -> 0
A13: AU 0.5 | B13: =_xlfn.IFNA(_xlfn.XLOOKUP(A13,'Price list'!D:D,'Price list'!E:E),0) -> 36500 | C13: Kg | H13: =IF(G13=0,"",_xlfn.XLOOKUP(G13,List_item!A:A,List_item!B:B)) | I13: 0 | J13: =IF(F13/E$10>0,F13/E$10,I13/E$10) -> 0 | K13: =+B13*(F13+I13) -> 0 | L13: =IFERROR(((K13/SUM($K$11:$K$79))*$F$10)/(F13+I13),0) -> 0 | M13: =+L13*(F13+I13) -> 0 | N13: =IF(L13=0,0,B13-L13) -> 0 | O13: =+K13-M13 -> 0
A14: AU 0.6 | B14: =_xlfn.IFNA(_xlfn.XLOOKUP(A14,'Price list'!D:D,'Price list'!E:E),0) -> 36500 | C14: Kg | G14: JLB1866 | H14: =IF(G14=0,"",_xlfn.XLOOKUP(G14,List_item!A:A,List_item!B:B)) -> Karkas Uk 0.6 Karkas Uk 0.6 Frozen Premium | I14: 26.9 | J14: =IF(F14/E$10>0,F14/E$10,I14/E$10) -> 0.0023930042 | K14: =+B14*(F14+I14) -> 981850 | L14: =IFERROR(((K14/SUM($K$11:$K$79))*$F$10)/(F14+I14),0) -> 36246.315 | M14: =+L14*(F14+I14) -> 975025.89 | N14: =IF(L14=0,0,B14-L14) -> 253.68456 | O14: =+K14-M14 -> 6824.1145
A15: AU 0.7 | B15: =_xlfn.IFNA(_xlfn.XLOOKUP(A15,'Price list'!D:D,'Price list'!E:E),0) -> 36500 | C15: Kg | G15: JLB1867 | H15: =IF(G15=0,"",_xlfn.XLOOKUP(G15,List_item!A:A,List_item!B:B)) -> Karkas Uk 0.7 Karkas Uk 0.7 Frozen Premium | I15: 101.2 | J15: =IF(F15/E$10>0,F15/E$10,I15/E$10) -> 0.0090026777 | K15: =+B15*(F15+I15) -> 3693800 | L15: =IFERROR(((K15/SUM($K$11:$K$79))*$F$10)/(F15+I15),0) -> 36246.315 | M15: =+L15*(F15+I15) -> 3668127.1 | N15: =IF(L15=0,0,B15-L15) -> 253.68456 | O15: =+K15-M15 -> 25672.877
A16: AU 0.8 | B16: =_xlfn.IFNA(_xlfn.XLOOKUP(A16,'Price list'!D:D,'Price list'!E:E),0) -> 36500 | C16: Kg | G16: JLB1859 | H16: =IF(G16=0,"",_xlfn.XLOOKUP(G16,List_item!A:A,List_item!B:B)) -> Karkas Uk 0.8 Frozen Premium | I16: 352.2 | J16: =IF(F16/E$10>0,F16/E$10,I16/E$10) -> 0.031331453 | K16: =+B16*(F16+I16) -> 12855300 | L16: =IFERROR(((K16/SUM($K$11:$K$79))*$F$10)/(F16+I16),0) -> 36246.315 | M16: =+L16*(F16+I16) -> 12765952 | N16: =IF(L16=0,0,B16-L16) -> 253.68456 | O16: =+K16-M16 -> 89347.7
A17: AU 0.9 | B17: =_xlfn.IFNA(_xlfn.XLOOKUP(A17,'Price list'!D:D,'Price list'!E:E),0) -> 36500 | C17: Kg | G17: JLB0593 | H17: =IF(G17=0,"",_xlfn.XLOOKUP(G17,List_item!A:A,List_item!B:B)) -> Karkas Uk 0.9 Karkas Uk 0.9 Fresh Premium | I17: 773.2 | J17: =IF(F17/E$10>0,F17/E$10,I17/E$10) -> 0.068783304 | K17: =+B17*(F17+I17) -> 28221800 | L17: =IFERROR(((K17/SUM($K$11:$K$79))*$F$10)/(F17+I17),0) -> 36246.315 | M17: =+L17*(F17+I17) -> 28025651 | N17: =IF(L17=0,0,B17-L17) -> 253.68456 | O17: =+K17-M17 -> 196148.9
A18: AU 1.0 | B18: =_xlfn.IFNA(_xlfn.XLOOKUP(A18,'Price list'!D:D,'Price list'!E:E),0) -> 36500 | C18: Kg | G18: JLB0658 | H18: =IF(G18=0,"",_xlfn.XLOOKUP(G18,List_item!A:A,List_item!B:B)) -> Karkas Uk 1.0 Karkas Uk 1.0 Fresh Premium | I18: 1692.7 | J18: =IF(F18/E$10>0,F18/E$10,I18/E$10) -> 0.15058135 | K18: =+B18*(F18+I18) -> 61783550 | L18: =IFERROR(((K18/SUM($K$11:$K$79))*$F$10)/(F18+I18),0) -> 36246.315 | M18: =+L18*(F18+I18) -> 61354138 | N18: =IF(L18=0,0,B18-L18) -> 253.68456 | O18: =+K18-M18 -> 429411.85
A19: AU 1.1 | B19: =_xlfn.IFNA(_xlfn.XLOOKUP(A19,'Price list'!D:D,'Price list'!E:E),0) -> 36500 | C19: Kg | G19: JLB0724 | H19: =IF(G19=0,"",_xlfn.XLOOKUP(G19,List_item!A:A,List_item!B:B)) -> Karkas Uk 1.1 Karkas Uk 1.1 Fresh Premium | I19: 1736.8 | J19: =IF(F19/E$10>0,F19/E$10,I19/E$10) -> 0.15450445 | K19: =+B19*(F19+I19) -> 63393200 | L19: =IFERROR(((K19/SUM($K$11:$K$79))*$F$10)/(F19+I19),0) -> 36246.315 | M19: =+L19*(F19+I19) -> 62952601 | N19: =IF(L19=0,0,B19-L19) -> 253.68456 | O19: =+K19-M19 -> 440599.34
A20: AU 1.2 | B20: =_xlfn.IFNA(_xlfn.XLOOKUP(A20,'Price list'!D:D,'Price list'!E:E),0) -> 36500 | C20: Kg | G20: JLB0790 | H20: =IF(G20=0,"",_xlfn.XLOOKUP(G20,List_item!A:A,List_item!B:B)) -> Karkas Uk 1.2 Karkas Uk 1.2 Fresh Premium | I20: 1438.2 | J20: =IF(F20/E$10>0,F20/E$10,I20/E$10) -> 0.12794122 | K20: =+B20*(F20+I20) -> 52494300 | L20: =IFERROR(((K20/SUM($K$11:$K$79))*$F$10)/(F20+I20),0) -> 36246.315 | M20: =+L20*(F20+I20) -> 52129451 | N20: =IF(L20=0,0,B20-L20) -> 253.68456 | O20: =+K20-M20 -> 364849.13
A21: AU 1.3 | B21: =_xlfn.IFNA(_xlfn.XLOOKUP(A21,'Price list'!D:D,'Price list'!E:E),0) -> 36500 | C21: Kg | G21: JLB0856 | H21: =IF(G21=0,"",_xlfn.XLOOKUP(G21,List_item!A:A,List_item!B:B)) -> Karkas Uk 1.3 Karkas Uk 1.3 Fresh Premium | I21: 544.5 | J21: =IF(F21/E$10>0,F21/E$10,I21/E$10) -> 0.04843832 | K21: =+B21*(F21+I21) -> 19874250 | L21: =IFERROR(((K21/SUM($K$11:$K$79))*$F$10)/(F21+I21),0) -> 36246.315 | M21: =+L21*(F21+I21) -> 19736119 | N21: =IF(L21=0,0,B21-L21) -> 253.68456 | O21: =+K21-M21 -> 138131.24
A22: AU 1.4 | B22: =_xlfn.IFNA(_xlfn.XLOOKUP(A22,'Price list'!D:D,'Price list'!E:E),0) -> 36500 | C22: Kg | G22: JLB0922 | H22: =IF(G22=0,"",_xlfn.XLOOKUP(G22,List_item!A:A,List_item!B:B)) -> Karkas Uk 1.4 Karkas Uk 1.4 Fresh Premium | I22: 72.3 | J22: =IF(F22/E$10>0,F22/E$10,I22/E$10) -> 0.0064317549 | K22: =+B22*(F22+I22) -> 2638950 | L22: =IFERROR(((K22/SUM($K$11:$K$79))*$F$10)/(F22+I22),0) -> 36246.315 | M22: =+L22*(F22+I22) -> 2620608.6 | N22: =IF(L22=0,0,B22-L22) -> 253.68456 | O22: =+K22-M22 -> 18341.393
A23: AU 1.5 | B23: =_xlfn.IFNA(_xlfn.XLOOKUP(A23,'Price list'!D:D,'Price list'!E:E),0) -> 36500 | C23: Kg | H23: =IF(G23=0,"",_xlfn.XLOOKUP(G23,List_item!A:A,List_item!B:B)) | I23: 0 | J23: =IF(F23/E$10>0,F23/E$10,I23/E$10) -> 0 | K23: =+B23*(F23+I23) -> 0 | L23: =IFERROR(((K23/SUM($K$11:$K$79))*$F$10)/(F23+I23),0) -> 0 | M23: =+L23*(F23+I23) -> 0 | N23: =IF(L23=0,0,B23-L23) -> 0 | O23: =+K23-M23 -> 0
A24: AU 1.6 | B24: =_xlfn.IFNA(_xlfn.XLOOKUP(A24,'Price list'!D:D,'Price list'!E:E),0) -> 36500 | C24: Kg | H24: =IF(G24=0,"",_xlfn.XLOOKUP(G24,List_item!A:A,List_item!B:B)) | I24: 0 | J24: =IF(F24/E$10>0,F24/E$10,I24/E$10) -> 0 | K24: =+B24*(F24+I24) -> 0 | L24: =IFERROR(((K24/SUM($K$11:$K$79))*$F$10)/(F24+I24),0) -> 0 | M24: =+L24*(F24+I24) -> 0 | N24: =IF(L24=0,0,B24-L24) -> 0 | O24: =+K24-M24 -> 0
A25: AU 1.7 | B25: =_xlfn.IFNA(_xlfn.XLOOKUP(A25,'Price list'!D:D,'Price list'!E:E),0) -> 36500 | C25: Kg | H25: =IF(G25=0,"",_xlfn.XLOOKUP(G25,List_item!A:A,List_item!B:B)) | I25: 0 | J25: =IF(F25/E$10>0,F25/E$10,I25/E$10) -> 0 | K25: =+B25*(F25+I25) -> 0 | L25: =IFERROR(((K25/SUM($K$11:$K$79))*$F$10)/(F25+I25),0) -> 0 | M25: =+L25*(F25+I25) -> 0 | N25: =IF(L25=0,0,B25-L25) -> 0 | O25: =+K25-M25 -> 0
A26: AU 1.8 | B26: =_xlfn.IFNA(_xlfn.XLOOKUP(A26,'Price list'!D:D,'Price list'!E:E),0) -> 36500 | C26: Kg | H26: =IF(G26=0,"",_xlfn.XLOOKUP(G26,List_item!A:A,List_item!B:B)) | I26: 0 | J26: =IF(F26/E$10>0,F26/E$10,I26/E$10) -> 0 | K26: =+B26*(F26+I26) -> 0 | L26: =IFERROR(((K26/SUM($K$11:$K$79))*$F$10)/(F26+I26),0) -> 0 | M26: =+L26*(F26+I26) -> 0 | N26: =IF(L26=0,0,B26-L26) -> 0 | O26: =+K26-M26 -> 0
A27: AU 1.9 | B27: =_xlfn.IFNA(_xlfn.XLOOKUP(A27,'Price list'!D:D,'Price list'!E:E),0) -> 36500 | C27: Kg | H27: =IF(G27=0,"",_xlfn.XLOOKUP(G27,List_item!A:A,List_item!B:B)) | I27: 0 | J27: =IF(F27/E$10>0,F27/E$10,I27/E$10) -> 0 | K27: =+B27*(F27+I27) -> 0 | L27: =IFERROR(((K27/SUM($K$11:$K$79))*$F$10)/(F27+I27),0) -> 0 | M27: =+L27*(F27+I27) -> 0 | N27: =IF(L27=0,0,B27-L27) -> 0 | O27: =+K27-M27 -> 0
A28: AU 2.0 | B28: =_xlfn.IFNA(_xlfn.XLOOKUP(A28,'Price list'!D:D,'Price list'!E:E),0) -> 36500 | C28: Kg | H28: =IF(G28=0,"",_xlfn.XLOOKUP(G28,List_item!A:A,List_item!B:B)) | I28: 0 | J28: =IF(F28/E$10>0,F28/E$10,I28/E$10) -> 0 | K28: =+B28*(F28+I28) -> 0 | L28: =IFERROR(((K28/SUM($K$11:$K$79))*$F$10)/(F28+I28),0) -> 0 | M28: =+L28*(F28+I28) -> 0 | N28: =IF(L28=0,0,B28-L28) -> 0 | O28: =+K28-M28 -> 0
A29: AU UP | B29: =_xlfn.IFNA(_xlfn.XLOOKUP(A29,'Price list'!D:D,'Price list'!E:E),0) -> 0 | C29: Kg | H29: =IF(G29=0,"",_xlfn.XLOOKUP(G29,List_item!A:A,List_item!B:B)) | I29: 0 | J29: =IF(F29/E$10>0,F29/E$10,I29/E$10) -> 0 | K29: =+B29*(F29+I29) -> 0 | L29: =IFERROR(((K29/SUM($K$11:$K$79))*$F$10)/(F29+I29),0) -> 0 | M29: =+L29*(F29+I29) -> 0 | N29: =IF(L29=0,0,B29-L29) -> 0 | O29: =+K29-M29 -> 0
A30: BLD | B30: =_xlfn.IFNA(_xlfn.XLOOKUP(A30,'Price list'!D:D,'Price list'!E:E),0) -> 50000 | C30: Kg | H30: =IF(G30=0,"",_xlfn.XLOOKUP(G30,List_item!A:A,List_item!B:B)) | I30: 0 | J30: =IF(F30/E$10>0,F30/E$10,I30/E$10) -> 0 | K30: =+B30*(F30+I30) -> 0 | L30: =IFERROR(((K30/SUM($K$11:$K$79))*$F$10)/(F30+I30),0) -> 0 | M30: =+L30*(F30+I30) -> 0 | N30: =IF(L30=0,0,B30-L30) -> 0 | O30: =+K30-M30 -> 0
A31: BLPK | B31: =_xlfn.IFNA(_xlfn.XLOOKUP(A31,'Price list'!D:D,'Price list'!E:E),0) -> 48000 | C31: Kg | H31: =IF(G31=0,"",_xlfn.XLOOKUP(G31,List_item!A:A,List_item!B:B)) | I31: 0 | J31: =IF(F31/E$10>0,F31/E$10,I31/E$10) -> 0 | K31: =+B31*(F31+I31) -> 0 | L31: =IFERROR(((K31/SUM($K$11:$K$79))*$F$10)/(F31+I31),0) -> 0 | M31: =+L31*(F31+I31) -> 0 | N31: =IF(L31=0,0,B31-L31) -> 0 | O31: =+K31-M31 -> 0
A32: BLP | B32: =_xlfn.IFNA(_xlfn.XLOOKUP(A32,'Price list'!D:D,'Price list'!E:E),0) -> 49000 | C32: Kg | H32: =IF(G32=0,"",_xlfn.XLOOKUP(G32,List_item!A:A,List_item!B:B)) | I32: 0 | J32: =IF(F32/E$10>0,F32/E$10,I32/E$10) -> 0 | K32: =+B32*(F32+I32) -> 0 | L32: =IFERROR(((K32/SUM($K$11:$K$79))*$F$10)/(F32+I32),0) -> 0 | M32: =+L32*(F32+I32) -> 0 | N32: =IF(L32=0,0,B32-L32) -> 0 | O32: =+K32-M32 -> 0
A33: Krk | B33: =_xlfn.IFNA(_xlfn.XLOOKUP(A33,'Price list'!D:D,'Price list'!E:E),0) -> 5500 | C33: Kg | H33: =IF(G33=0,"",_xlfn.XLOOKUP(G33,List_item!A:A,List_item!B:B)) | I33: 0 | J33: =IF(F33/E$10>0,F33/E$10,I33/E$10) -> 0 | K33: =+B33*(F33+I33) -> 0 | L33: =IFERROR(((K33/SUM($K$11:$K$79))*$F$10)/(F33+I33),0) -> 0 | M33: =+L33*(F33+I33) -> 0 | N33: =IF(L33=0,0,B33-L33) -> 0 | O33: =+K33-M33 -> 0
A34: kulit | B34: =_xlfn.IFNA(_xlfn.XLOOKUP(A34,'Price list'!D:D,'Price list'!E:E),0) -> 20000 | C34: Kg | H34: =IF(G34=0,"",_xlfn.XLOOKUP(G34,List_item!A:A,List_item!B:B)) | I34: 0 | J34: =IF(F34/E$10>0,F34/E$10,I34/E$10) -> 0 | K34: =+B34*(F34+I34) -> 0 | L34: =IFERROR(((K34/SUM($K$11:$K$79))*$F$10)/(F34+I34),0) -> 0 | M34: =+L34*(F34+I34) -> 0 | N34: =IF(L34=0,0,B34-L34) -> 0 | O34: =+K34-M34 -> 0
... A38: Paha Bawah | B38: =_xlfn.IFNA(_xlfn.XLOOKUP(A38,'Price list'!D:D,'Price list'!E:E),0) -> 38000 | C38: Kg | H38: =IF(G38=0,"",_xlfn.XLOOKUP(G38,List_item!A:A,List_item!B:B)) | I38: 0 | J38: =IF(F38/E$10>0,F38/E$10,I38/E$10) -> 0 | K38: =+B38*(F38+I38) -> 0 | L38: =IFERROR(((K38/SUM($K$11:$K$79))*$F$10)/(F38+I38),0) -> 0 | M38: =+L38*(F38+I38) -> 0 | N38: =IF(L38=0,0,B38-L38) -> 0 | O38: =+K38-M38 -> 0
A39: Lemak | B39: =_xlfn.IFNA(_xlfn.XLOOKUP(A39,'Price list'!D:D,'Price list'!E:E),0) -> 18000 | C39: Kg | G39: JLB0118 | H39: =IF(G39=0,"",_xlfn.XLOOKUP(G39,List_item!A:A,List_item!B:B)) -> Boneless BL Fresh Lemak | I39: 31.4 | J39: =IF(F39/E$10>0,F39/E$10,I39/E$10) -> 0.0027933209 | K39: =+B39*(F39+I39) -> 565200 | L39: =IFERROR(((K39/SUM($K$11:$K$79))*$F$10)/(F39+I39),0) -> 17874.895 | M39: =+L39*(F39+I39) -> 561271.71 | N39: =IF(L39=0,0,B39-L39) -> 125.10471 | O39: =+K39-M39 -> 3928.288
A40: Kepala | B40: =_xlfn.IFNA(_xlfn.XLOOKUP(A40,'Price list'!D:D,'Price list'!E:E),0) -> 8000 | G40: JLB0092 | H40: =IF(G40=0,"",_xlfn.XLOOKUP(G40,List_item!A:A,List_item!B:B)) -> Boneless BL Fresh Kepala | I40: 518.8 | J40: =IF(F40/E$10>0,F40/E$10,I40/E$10) -> 0.046152067 | K40: =+B40*(F40+I40) -> 4150400 | L40: =IFERROR(((K40/SUM($K$11:$K$79))*$F$10)/(F40+I40),0) -> 7944.3979 | M40: =+L40*(F40+I40) -> 4121553.6 | N40: =IF(L40=0,0,B40-L40) -> 55.602094 | O40: =+K40-M40 -> 28846.367
A41: Ceker | B41: =_xlfn.IFNA(_xlfn.XLOOKUP(A41,'Price list'!D:D,'Price list'!E:E),0) -> 10000 | C41: Kg | G41: JLB0078 | H41: =IF(G41=0,"",_xlfn.XLOOKUP(G41,List_item!A:A,List_item!B:B)) -> Boneless BL Fresh Ceker | I41: 329.3 | J41: =IF(F41/E$10>0,F41/E$10,I41/E$10) -> 0.029294286 | K41: =+B41*(F41+I41) -> 3293000 | L41: =IFERROR(((K41/SUM($K$11:$K$79))*$F$10)/(F41+I41),0) -> 9930.4974 | M41: =+L41*(F41+I41) -> 3270112.8 | N41: =IF(L41=0,0,B41-L41) -> 69.502618 | O41: =+K41-M41 -> 22887.212
A42: HJA | B42: =_xlfn.IFNA(_xlfn.XLOOKUP(A42,'Price list'!D:D,'Price list'!E:E),0) -> 4000 | C42: Kg | H42: =IF(G42=0,"",_xlfn.XLOOKUP(G42,List_item!A:A,List_item!B:B)) | I42: 0 | J42: =IF(F42/E$10>0,F42/E$10,I42/E$10) -> 0 | K42: =+B42*(F42+I42) -> 0 | L42: =IFERROR(((K42/SUM($K$11:$K$79))*$F$10)/(F42+I42),0) -> 0 | M42: =+L42*(F42+I42) -> 0 | N42: =IF(L42=0,0,B42-L42) -> 0 | O42: =+K42-M42 -> 0
A43: Usus | B43: =_xlfn.IFNA(_xlfn.XLOOKUP(A43,'Price list'!D:D,'Price list'!E:E),0) -> 5000 | C43: Kg | G43: JLB0135 | H43: =IF(G43=0,"",_xlfn.XLOOKUP(G43,List_item!A:A,List_item!B:B)) -> Boneless BL Fresh Usus Kotor | I43: 495 | J43: =IF(F43/E$10>0,F43/E$10,I43/E$10) -> 0.044034836 | K43: =+B43*(F43+I43) -> 2475000 | L43: =IFERROR(((K43/SUM($K$11:$K$79))*$F$10)/(F43+I43),0) -> 4965.2487 | M43: =+L43*(F43+I43) -> 2457798.1 | N43: =IF(L43=0,0,B43-L43) -> 34.751309 | O43: =+K43-M43 -> 17201.898
A44: Tungir | B44: =_xlfn.IFNA(_xlfn.XLOOKUP(A44,'Price list'!D:D,'Price list'!E:E),0) -> 16000 | C44: Kg | H44: =IF(G44=0,"",_xlfn.XLOOKUP(G44,List_item!A:A,List_item!B:B)) | I44: 0 | J44: =IF(F44/E$10>0,F44/E$10,I44/E$10) -> 0 | K44: =+B44*(F44+I44) -> 0 | L44: =IFERROR(((K44/SUM($K$11:$K$79))*$F$10)/(F44+I44),0) -> 0 | M44: =+L44*(F44+I44) -> 0 | N44: =IF(L44=0,0,B44-L44) -> 0 | O44: =+K44-M44 -> 0
...

Sheet Pot_ISA30
I1: =+I9/E11 -> 3.6277286
A2: Harga Perolehan | G2: Ref. Dokumen
A3: Live Bird | B3: =J5*24800 -> 466083760 | G3: 063/09/INV/ALBERTUS/2026 | H3: PI26090095 | I3: Supplier | J3: ALBERTUS
A4: Biaya Ekspedisi | B4: =6*1500000 -> 9000000 | G4: INV 30 SEP | H4: PI26090091 | I4: Tgl. Potong | J4: 46295 | K4: HASIL POTONG | M4: SUSUT | N4: Ayam Mati | O4: KG Mati
A5: Biaya Potong | B5: =25324515+486486 -> 25811001 | G5: RPB-RPA/26/IX/00244 | H5: PI26090082 | I5: Total KG LB | J5: =3169.2+3000+3100.6+3200+3202.5+3121.4 -> 18793.7 | K5: 17568.9 | L5: =J5-K5 -> 1224.8 | M5: =L5/J5 -> 0.065170775
A6: Total | B6: =SUBTOTAL(9,B3:B5) -> 500894761 | E6: Biaya BL
B7: =B6+F6 -> 500894761
I9: =J9+3300.2*2 -> 25394.1 | J9: =J5-J7 -> 18793.7 | K9: Est. GP Margin | L9: =SUM(K12:K68)/M11-1 -> -0.046759245
A10: Produk | B10: Price/Kg | C10: Satuan | E10: SKU Fresh | F10: Non Blasting | G10: No. SKU | H10: Item Name | I10: Qty | J10: Yield | K10: Est. Harga Jual | L10: COGS/Kg | M10: COGS/Item | N10: (Price/Kg - COGS/Kg) | O10: (Est. Harga Jual - COGS/Item) | P10: Notes
E11: 7000 | F11: =+B6 -> 500894761 | I11: =SUM(I12:I89) -> 15893.9 | J11: =SUM(J12:J89) -> 0.84570361 | K11: =SUM(K12:K89) -> 477473300 | M11: =SUM(M12:M89) -> 5.0089476e+08 | O11: =SUM(O12:O89) -> -23421461
A12: AU 0.3 | B12: =_xlfn.IFNA(_xlfn.XLOOKUP(A12,'Price list'!J:J,'Price list'!K:K),0) -> 0 | C12: Kg | H12: =IF(G12=0,"",_xlfn.XLOOKUP(G12,List_item!A:A,List_item!B:B)) | I12: 0 | J12: =IF(F12/J$5>0,F12/J$5,I12/J$5) -> 0 | K12: =+B12*(F12+I12) -> 0 | L12: =IFERROR(((K12/$K$11)*$F$11)/(F12+I12),0) -> 0 | M12: =+L12*(F12+I12) -> 0 | N12: =IF(L12=0,0,B12-L12) -> 0 | O12: =+K12-M12 -> 0
A13: AU 0.4 | B13: =_xlfn.IFNA(_xlfn.XLOOKUP(A13,'Price list'!J:J,'Price list'!K:K),0) -> 0 | C13: Kg | H13: =IF(G13=0,"",_xlfn.XLOOKUP(G13,List_item!A:A,List_item!B:B)) | I13: 0 | J13: =IF(F13/J$5>0,F13/J$5,I13/J$5) -> 0 | K13: =+B13*(F13+I13) -> 0 | L13: =IFERROR(((K13/$K$11)*$F$11)/(F13+I13),0) -> 0 | M13: =+L13*(F13+I13) -> 0 | N13: =IF(L13=0,0,B13-L13) -> 0 | O13: =+K13-M13 -> 0
A14: AU 0.5 | B14: =_xlfn.IFNA(_xlfn.XLOOKUP(A14,'Price list'!J:J,'Price list'!K:K),0) -> 37000 | C14: Kg | G14: JLB1865 | H14: =IF(G14=0,"",_xlfn.XLOOKUP(G14,List_item!A:A,List_item!B:B)) -> Karkas Uk 0.5 Karkas Uk 0.5 Frozen Premium | I14: 70.3 | J14: =IF(F14/J$5>0,F14/J$5,I14/J$5) -> 0.0037406152 | K14: =+B14*(F14+I14) -> 2601100 | L14: =IFERROR(((K14/$K$11)*$F$11)/(F14+I14),0) -> 38814.958 | M14: =+L14*(F14+I14) -> 2728691.6 | N14: =IF(L14=0,0,B14-L14) -> -1814.9581 | O14: =+K14-M14 -> -127591.56
A15: AU 0.6 | B15: =_xlfn.IFNA(_xlfn.XLOOKUP(A15,'Price list'!J:J,'Price list'!K:K),0) -> 37000 | C15: Kg | G15: JLB1866 | H15: =IF(G15=0,"",_xlfn.XLOOKUP(G15,List_item!A:A,List_item!B:B)) -> Karkas Uk 0.6 Karkas Uk 0.6 Frozen Premium | I15: 267 | J15: =IF(F15/J$5>0,F15/J$5,I15/J$5) -> 0.014206888 | K15: =+B15*(F15+I15) -> 9879000 | L15: =IFERROR(((K15/$K$11)*$F$11)/(F15+I15),0) -> 38814.958 | M15: =+L15*(F15+I15) -> 10363594 | N15: =IF(L15=0,0,B15-L15) -> -1814.9581 | O15: =+K15-M15 -> -484593.83
A16: AU 0.7 | B16: =_xlfn.IFNA(_xlfn.XLOOKUP(A16,'Price list'!J:J,'Price list'!K:K),0) -> 37000 | C16: Kg | G16: JLB1867 | H16: =IF(G16=0,"",_xlfn.XLOOKUP(G16,List_item!A:A,List_item!B:B)) -> Karkas Uk 0.7 Karkas Uk 0.7 Frozen Premium | I16: 1113.9 | J16: =IF(F16/J$5>0,F16/J$5,I16/J$5) -> 0.059269862 | K16: =+B16*(F16+I16) -> 41214300 | L16: =IFERROR(((K16/$K$11)*$F$11)/(F16+I16),0) -> 38814.958 | M16: =+L16*(F16+I16) -> 43235982 | N16: =IF(L16=0,0,B16-L16) -> -1814.9581 | O16: =+K16-M16 -> -2021681.9
A17: AU 0.8 | B17: =_xlfn.IFNA(_xlfn.XLOOKUP(A17,'Price list'!J:J,'Price list'!K:K),0) -> 37000 | C17: Kg | G17: JLB1859 | H17: =IF(G17=0,"",_xlfn.XLOOKUP(G17,List_item!A:A,List_item!B:B)) -> Karkas Uk 0.8 Frozen Premium | I17: 899.8 | J17: =IF(F17/J$5>0,F17/J$5,I17/J$5) -> 0.047877746 | K17: =+B17*(F17+I17) -> 33292600 | L17: =IFERROR(((K17/$K$11)*$F$11)/(F17+I17),0) -> 38814.958 | M17: =+L17*(F17+I17) -> 34925699 | N17: =IF(L17=0,0,B17-L17) -> -1814.9581 | O17: =+K17-M17 -> -1633099.3
A18: AU 0.9 | B18: =_xlfn.IFNA(_xlfn.XLOOKUP(A18,'Price list'!J:J,'Price list'!K:K),0) -> 37000 | C18: Kg | G18: JLB1858 | H18: =IF(G18=0,"",_xlfn.XLOOKUP(G18,List_item!A:A,List_item!B:B)) -> Karkas Uk 0.9 Frozen Premium | I18: 2093.7 | J18: =IF(F18/J$5>0,F18/J$5,I18/J$5) -> 0.11140435 | K18: =+B18*(F18+I18) -> 77466900 | L18: =IFERROR(((K18/$K$11)*$F$11)/(F18+I18),0) -> 38814.958 | M18: =+L18*(F18+I18) -> 81266878 | N18: =IF(L18=0,0,B18-L18) -> -1814.9581 | O18: =+K18-M18 -> -3799977.9
A19: AU 0.9 | B19: =_xlfn.IFNA(_xlfn.XLOOKUP(A19,'Price list'!J:J,'Price list'!K:K),0) -> 37000 | C19: Kg | G19: JLB0593 | H19: =IF(G19=0,"",_xlfn.XLOOKUP(G19,List_item!A:A,List_item!B:B)) -> Karkas Uk 0.9 Karkas Uk 0.9 Fresh Premium | I19: 1820.9 | J19: =IF(F19/J$5>0,F19/J$5,I19/J$5) -> 0.096888851 | K19: =+B19*(F19+I19) -> 67373300 | L19: =IFERROR(((K19/$K$11)*$F$11)/(F19+I19),0) -> 38814.958 | M19: =+L19*(F19+I19) -> 70678157 | N19: =IF(L19=0,0,B19-L19) -> -1814.9581 | O19: =+K19-M19 -> -3304857.3
A20: AU 1.0 | B20: =_xlfn.IFNA(_xlfn.XLOOKUP(A20,'Price list'!J:J,'Price list'!K:K),0) -> 37000 | C20: Kg | G20: JLB0690 | H20: =IF(G20=0,"",_xlfn.XLOOKUP(G20,List_item!A:A,List_item!B:B)) -> Karkas Uk 1.0 Karkas Uk 1.0 Frozen Premium | I20: 1697.1 | J20: =IF(F20/J$5>0,F20/J$5,I20/J$5) -> 0.090301537 | K20: =+B20*(F20+I20) -> 62792700 | L20: =IFERROR(((K20/$K$11)*$F$11)/(F20+I20),0) -> 38814.958 | M20: =+L20*(F20+I20) -> 65872865 | N20: =IF(L20=0,0,B20-L20) -> -1814.9581 | O20: =+K20-M20 -> -3080165.5
A21: AU 1.1 | B21: =_xlfn.IFNA(_xlfn.XLOOKUP(A21,'Price list'!J:J,'Price list'!K:K),0) -> 37000 | C21: Kg | G21: JLB0756 | H21: =IF(G21=0,"",_xlfn.XLOOKUP(G21,List_item!A:A,List_item!B:B)) -> Karkas Uk 1.1 Karkas Uk 1.1 Frozen Premium | I21: 174.4 | J21: =IF(F21/J$5>0,F21/J$5,I21/J$5) -> 0.0092797054 | K21: =+B21*(F21+I21) -> 6452800 | L21: =IFERROR(((K21/$K$11)*$F$11)/(F21+I21),0) -> 38814.958 | M21: =+L21*(F21+I21) -> 6769328.7 | N21: =IF(L21=0,0,B21-L21) -> -1814.9581 | O21: =+K21-M21 -> -316528.7
A22: AU 1.1 | B22: =_xlfn.IFNA(_xlfn.XLOOKUP(A22,'Price list'!J:J,'Price list'!K:K),0) -> 37000 | C22: Kg | G22: JLB0724 | H22: =IF(G22=0,"",_xlfn.XLOOKUP(G22,List_item!A:A,List_item!B:B)) -> Karkas Uk 1.1 Karkas Uk 1.1 Fresh Premium | I22: 1282 | J22: =IF(F22/J$5>0,F22/J$5,I22/J$5) -> 0.068214348 | K22: =+B22*(F22+I22) -> 47434000 | L22: =IFERROR(((K22/$K$11)*$F$11)/(F22+I22),0) -> 38814.958 | M22: =+L22*(F22+I22) -> 49760776 | N22: =IF(L22=0,0,B22-L22) -> -1814.9581 | O22: =+K22-M22 -> -2326776.3
A23: AU 1.2 | B23: =_xlfn.IFNA(_xlfn.XLOOKUP(A23,'Price list'!J:J,'Price list'!K:K),0) -> 37000 | C23: Kg | G23: JLB0822 | H23: =IF(G23=0,"",_xlfn.XLOOKUP(G23,List_item!A:A,List_item!B:B)) -> Karkas Uk 1.2 Karkas Uk 1.2 Frozen Premium | I23: 846.6 | J23: =IF(F23/J$5>0,F23/J$5,I23/J$5) -> 0.04504701 | K23: =+B23*(F23+I23) -> 31324200 | L23: =IFERROR(((K23/$K$11)*$F$11)/(F23+I23),0) -> 38814.958 | M23: =+L23*(F23+I23) -> 32860744 | N23: =IF(L23=0,0,B23-L23) -> -1814.9581 | O23: =+K23-M23 -> -1536543.6
A24: AU 1.3 | B24: =_xlfn.IFNA(_xlfn.XLOOKUP(A24,'Price list'!J:J,'Price list'!K:K),0) -> 37000 | C24: Kg | G24: JLB0888 | H24: =IF(G24=0,"",_xlfn.XLOOKUP(G24,List_item!A:A,List_item!B:B)) -> Karkas Uk 1.3 Karkas Uk 1.3 Frozen Premium | I24: 387.6 | J24: =IF(F24/J$5>0,F24/J$5,I24/J$5) -> 0.020623932 | K24: =+B24*(F24+I24) -> 14341200 | L24: =IFERROR(((K24/$K$11)*$F$11)/(F24+I24),0) -> 38814.958 | M24: =+L24*(F24+I24) -> 15044678 | N24: =IF(L24=0,0,B24-L24) -> -1814.9581 | O24: =+K24-M24 -> -703477.78
A25: AU 1.4 | B25: =_xlfn.IFNA(_xlfn.XLOOKUP(A25,'Price list'!J:J,'Price list'!K:K),0) -> 37000 | C25: Kg | G25: JLB0954 | H25: =IF(G25=0,"",_xlfn.XLOOKUP(G25,List_item!A:A,List_item!B:B)) -> Karkas Uk 1.4 Karkas Uk 1.4 Frozen Premium | I25: 134.3 | J25: =IF(F25/J$5>0,F25/J$5,I25/J$5) -> 0.0071460117 | K25: =+B25*(F25+I25) -> 4969100 | L25: =IFERROR(((K25/$K$11)*$F$11)/(F25+I25),0) -> 38814.958 | M25: =+L25*(F25+I25) -> 5212848.9 | N25: =IF(L25=0,0,B25-L25) -> -1814.9581 | O25: =+K25-M25 -> -243748.88
A26: AU 1.5 | B26: =_xlfn.IFNA(_xlfn.XLOOKUP(A26,'Price list'!J:J,'Price list'!K:K),0) -> 37000 | C26: Kg | H26: =IF(G26=0,"",_xlfn.XLOOKUP(G26,List_item!A:A,List_item!B:B)) | I26: 0 | J26: =IF(F26/J$5>0,F26/J$5,I26/J$5) -> 0 | K26: =+B26*(F26+I26) -> 0 | L26: =IFERROR(((K26/$K$11)*$F$11)/(F26+I26),0) -> 0 | M26: =+L26*(F26+I26) -> 0 | N26: =IF(L26=0,0,B26-L26) -> 0 | O26: =+K26-M26 -> 0
A27: AU 1.6 | B27: =_xlfn.IFNA(_xlfn.XLOOKUP(A27,'Price list'!J:J,'Price list'!K:K),0) -> 37000 | C27: Kg | H27: =IF(G27=0,"",_xlfn.XLOOKUP(G27,List_item!A:A,List_item!B:B)) | I27: 0 | J27: =IF(F27/J$5>0,F27/J$5,I27/J$5) -> 0 | K27: =+B27*(F27+I27) -> 0 | L27: =IFERROR(((K27/$K$11)*$F$11)/(F27+I27),0) -> 0 | M27: =+L27*(F27+I27) -> 0 | N27: =IF(L27=0,0,B27-L27) -> 0 | O27: =+K27-M27 -> 0
A28: AU 1.7 | B28: =_xlfn.IFNA(_xlfn.XLOOKUP(A28,'Price list'!J:J,'Price list'!K:K),0) -> 37000 | C28: Kg | H28: =IF(G28=0,"",_xlfn.XLOOKUP(G28,List_item!A:A,List_item!B:B)) | I28: 0 | J28: =IF(F28/J$5>0,F28/J$5,I28/J$5) -> 0 | K28: =+B28*(F28+I28) -> 0 | L28: =IFERROR(((K28/$K$11)*$F$11)/(F28+I28),0) -> 0 | M28: =+L28*(F28+I28) -> 0 | N28: =IF(L28=0,0,B28-L28) -> 0 | O28: =+K28-M28 -> 0
A29: AU 1.8 | B29: =_xlfn.IFNA(_xlfn.XLOOKUP(A29,'Price list'!J:J,'Price list'!K:K),0) -> 37000 | C29: Kg | H29: =IF(G29=0,"",_xlfn.XLOOKUP(G29,List_item!A:A,List_item!B:B)) | I29: 0 | J29: =IF(F29/J$5>0,F29/J$5,I29/J$5) -> 0 | K29: =+B29*(F29+I29) -> 0 | L29: =IFERROR(((K29/$K$11)*$F$11)/(F29+I29),0) -> 0 | M29: =+L29*(F29+I29) -> 0 | N29: =IF(L29=0,0,B29-L29) -> 0 | O29: =+K29-M29 -> 0
A30: AU 1.9 | B30: =_xlfn.IFNA(_xlfn.XLOOKUP(A30,'Price list'!J:J,'Price list'!K:K),0) -> 37000 | C30: Kg | H30: =IF(G30=0,"",_xlfn.XLOOKUP(G30,List_item!A:A,List_item!B:B)) | I30: 0 | J30: =IF(F30/J$5>0,F30/J$5,I30/J$5) -> 0 | K30: =+B30*(F30+I30) -> 0 | L30: =IFERROR(((K30/$K$11)*$F$11)/(F30+I30),0)+IFERROR(((K30/SUMIF(H:H,"*Boneless*",K:K))*$F$6)/I30,0) -> 0 | M30: =+L30*(F30+I30) -> 0 | N30: =IF(L30=0,0,B30-L30) -> 0 | O30: =+K30-M30 -> 0 | P30: =IFERROR(((K30/SUMIF(H:H,"*Boneless*",K:K))*$F$6),0) -> 0 | Q30: =SUMIF(H:H,"*Boneless*",K:K) -> 25941500
A31: AU 2.0 | B31: =_xlfn.IFNA(_xlfn.XLOOKUP(A31,'Price list'!J:J,'Price list'!K:K),0) -> 37000 | C31: Kg | H31: =IF(G31=0,"",_xlfn.XLOOKUP(G31,List_item!A:A,List_item!B:B)) | I31: 0 | J31: =IF(F31/J$5>0,F31/J$5,I31/J$5) -> 0 | K31: =+B31*(F31+I31) -> 0 | L31: =IFERROR(((K31/$K$11)*$F$11)/(F31+I31),0) -> 0 | M31: =+L31*(F31+I31) -> 0 | N31: =IF(L31=0,0,B31-L31) -> 0 | O31: =+K31-M31 -> 0
A32: AU UP | B32: =_xlfn.IFNA(_xlfn.XLOOKUP(A32,'Price list'!J:J,'Price list'!K:K),0) -> 0 | C32: Kg | H32: =IF(G32=0,"",_xlfn.XLOOKUP(G32,List_item!A:A,List_item!B:B)) | I32: 0 | J32: =IF(F32/J$5>0,F32/J$5,I32/J$5) -> 0 | K32: =+B32*(F32+I32) -> 0 | L32: =IFERROR(((K32/$K$11)*$F$11)/(F32+I32),0)+IFERROR(((K32/SUMIF(H:H,"*Boneless*",K:K))*$F$6)/I32,0) -> 0 | M32: =+L32*(F32+I32) -> 0 | N32: =IF(L32=0,0,B32-L32) -> 0 | O32: =+K32-M32 -> 0 | P32: =IFERROR(((K32/SUMIF(H:H,"*Boneless*",K:K))*$F$6),0) -> 0 | Q32: =SUMIF(H:H,"*Boneless*",K:K) -> 25941500
A33: BLD | B33: =_xlfn.IFNA(_xlfn.XLOOKUP(A33,'Price list'!J:J,'Price list'!K:K),0) -> 50000 | C33: Kg | H33: =IF(G33=0,"",_xlfn.XLOOKUP(G33,List_item!A:A,List_item!B:B)) | I33: 0 | J33: =IF(F33/J$5>0,F33/J$5,I33/J$5) -> 0 | K33: =+B33*(F33+I33) -> 0 | L33: =IFERROR(((K33/$K$11)*$F$11)/(F33+I33),0)+IFERROR(((K33/SUMIF(H:H,"*Boneless*",K:K))*$F$6)/I33,0) -> 0 | M33: =+L33*(F33+I33) -> 0 | N33: =IF(L33=0,0,B33-L33) -> 0 | O33: =+K33-M33 -> 0 | P33: =IFERROR(((K33/SUMIF(H:H,"*Boneless*",K:K))*$F$6),0) -> 0 | Q33: =SUMIF(H:H,"*Boneless*",K:K) -> 25941500
A34: BLPK | B34: =_xlfn.IFNA(_xlfn.XLOOKUP(A34,'Price list'!J:J,'Price list'!K:K),0) -> 48000 | C34: Kg | H34: =IF(G34=0,"",_xlfn.XLOOKUP(G34,List_item!A:A,List_item!B:B)) | I34: 0 | J34: =IF(F34/J$5>0,F34/J$5,I34/J$5) -> 0 | K34: =+B34*(F34+I34) -> 0 | L34: =IFERROR(((K34/$K$11)*$F$11)/(F34+I34),0)+IFERROR(((K34/SUMIF(H:H,"*Boneless*",K:K))*$F$6)/I34,0) -> 0 | M34: =+L34*(F34+I34) -> 0 | N34: =IF(L34=0,0,B34-L34) -> 0 | O34: =+K34-M34 -> 0 | P34: =IFERROR(((K34/SUMIF(H:H,"*Boneless*",K:K))*$F$6),0) -> 0 | Q34: =SUMIF(H:H,"*Boneless*",K:K) -> 25941500
A35: BLP | B35: =_xlfn.IFNA(_xlfn.XLOOKUP(A35,'Price list'!J:J,'Price list'!K:K),0) -> 49000 | C35: Kg | H35: =IF(G35=0,"",_xlfn.XLOOKUP(G35,List_item!A:A,List_item!B:B)) | I35: 0 | J35: =IF(F35/J$5>0,F35/J$5,I35/J$5) -> 0 | K35: =+B35*(F35+I35) -> 0 | L35: =IFERROR(((K35/$K$11)*$F$11)/(F35+I35),0)+IFERROR(((K35/SUMIF(H:H,"*Boneless*",K:K))*$F$6)/I35,0) -> 0 | M35: =+L35*(F35+I35) -> 0 | N35: =IF(L35=0,0,B35-L35) -> 0 | O35: =+K35-M35 -> 0 | P35: =IFERROR(((K35/SUMIF(H:H,"*Boneless*",K:K))*$F$6),0) -> 0 | Q35: =SUMIF(H:H,"*Boneless*",K:K) -> 25941500
A36: Krk | B36: =_xlfn.IFNA(_xlfn.XLOOKUP(A36,'Price list'!J:J,'Price list'!K:K),0) -> 12500 | C36: Kg | H36: =IF(G36=0,"",_xlfn.XLOOKUP(G36,List_item!A:A,List_item!B:B)) | I36: 0 | J36: =IF(F36/J$5>0,F36/J$5,I36/J$5) -> 0 | K36: =+B36*(F36+I36) -> 0 | L36: =IFERROR(((K36/$K$11)*$F$11)/(F36+I36),0)+IFERROR(((K36/SUMIF(H:H,"*Boneless*",K:K))*$F$6)/I36,0) -> 0 | M36: =+L36*(F36+I36) -> 0 | N36: =IF(L36=0,0,B36-L36) -> 0 | O36: =+K36-M36 -> 0 | P36: =IFERROR(((K36/SUMIF(H:H,"*Boneless*",K:K))*$F$6),0) -> 0 | Q36: =SUMIF(H:H,"*Boneless*",K:K) -> 25941500
A37: kulit | B37: =_xlfn.IFNA(_xlfn.XLOOKUP(A37,'Price list'!J:J,'Price list'!K:K),0) -> 32000 | C37: Kg | H37: =IF(G37=0,"",_xlfn.XLOOKUP(G37,List_item!A:A,List_item!B:B)) | I37: 0 | J37: =IF(F37/J$5>0,F37/J$5,I37/J$5) -> 0 | K37: =+B37*(F37+I37) -> 0 | L37: =IFERROR(((K37/$K$11)*$F$11)/(F37+I37),0)+IFERROR(((K37/SUMIF(H:H,"*Boneless*",K:K))*$F$6)/I37,0) -> 0 | M37: =+L37*(F37+I37) -> 0 | N37: =IF(L37=0,0,B37-L37) -> 0 | O37: =+K37-M37 -> 0 | P37: =IFERROR(((K37/SUMIF(H:H,"*Boneless*",K:K))*$F$6),0) -> 0 | Q37: =SUMIF(H:H,"*Boneless*",K:K) -> 25941500
A38: Sayap | B38: =_xlfn.IFNA(_xlfn.XLOOKUP(A38,'Price list'!J:J,'Price list'!K:K),0) -> 36000 | C38: Kg | H38: =IF(G38=0,"",_xlfn.XLOOKUP(G38,List_item!A:A,List_item!B:B)) | I38: 0 | J38: =IF(F38/J$5>0,F38/J$5,I38/J$5) -> 0 | K38: =+B38*(F38+I38) -> 0 | L38: =IFERROR(((K38/$K$11)*$F$11)/(F38+I38),0) -> 0 | M38: =+L38*(F38+I38) -> 0 | N38: =IF(L38=0,0,B38-L38) -> 0 | O38: =+K38-M38 -> 0
A39: Sayap grade A | B39: =_xlfn.IFNA(_xlfn.XLOOKUP(A39,'Price list'!J:J,'Price list'!K:K),0) -> 32000 | C39: Kg | H39: =IF(G39=0,"",_xlfn.XLOOKUP(G39,List_item!A:A,List_item!B:B)) | I39: 0 | J39: =IF(F39/J$5>0,F39/J$5,I39/J$5) -> 0 | K39: =+B39*(F39+I39) -> 0 | L39: =IFERROR(((K39/$K$11)*$F$11)/(F39+I39),0) -> 0 | M39: =+L39*(F39+I39) -> 0 | N39: =IF(L39=0,0,B39-L39) -> 0 | O39: =+K39-M39 -> 0
A40: TLP | B40: =_xlfn.IFNA(_xlfn.XLOOKUP(A40,'Price list'!J:J,'Price list'!K:K),0) -> 5000 | C40: Kg | H40: =IF(G40=0,"",_xlfn.XLOOKUP(G40,List_item!A:A,List_item!B:B)) | I40: 0 | J40: =IF(F40/J$5>0,F40/J$5,I40/J$5) -> 0 | K40: =+B40*(F40+I40) -> 0 | L40: =IFERROR(((K40/$K$11)*$F$11)/(F40+I40),0) -> 0 | M40: =+L40*(F40+I40) -> 0 | N40: =IF(L40=0,0,B40-L40) -> 0 | O40: =+K40-M40 -> 0
A41: Paha Bawah | B41: =_xlfn.IFNA(_xlfn.XLOOKUP(A41,'Price list'!J:J,'Price list'!K:K),0) -> 35000 | C41: Kg | H41: =IF(G41=0,"",_xlfn.XLOOKUP(G41,List_item!A:A,List_item!B:B)) | I41: 0 | J41: =IF(F41/J$5>0,F41/J$5,I41/J$5) -> 0 | K41: =+B41*(F41+I41) -> 0 | L41: =IFERROR(((K41/$K$11)*$F$11)/(F41+I41),0) -> 0 | M41: =+L41*(F41+I41) -> 0 | N41: =IF(L41=0,0,B41-L41) -> 0 | O41: =+K41-M41 -> 0
...

Sheet Pot_ISA29
I1: =+I9/E11 -> 3.7082857
A2: Harga Perolehan | G2: Ref. Dokumen
A3: Live Bird | B3: =((3100+3300+3202.8+3300+3354.8)+(3100))*25000 -> 4.8394e+08 | G3: 062/09/INVALBERTUS/2026 & 061/09/INVALBERTUS/2026 | H3: PI26090094 & PI26090093 | I3: Supplier | J3: ALBERTUS
A4: Biaya Ekspedisi | B4: =5*1500000 -> 7500000 | G4: INV 29 SEP | H4: PI26090077 | I4: Tgl. Potong | J4: 46294 | K4: HASIL POTONG | M4: SUSUT | N4: Ayam Mati | O4: KG Mati
A5: Biaya Potong | B5: 26303974 | G5: RPB-RPA/26/IX/00241 | H5: PI26090078 | I5: Total KG LB | J5: =(3100+3300+3202.8+3300+3354.8)+3100 -> 19357.6 | K5: 18248.4 | L5: =J5-K5 -> 1109.2 | M5: =L5/J5 -> 0.057300492 | N5: =4+4+2+10+36+4 -> 60 | O5: =5.2+6.2+3.2+17.4+48.3+5.8 -> 86.1
A6: Total | B6: =SUBTOTAL(9,B3:B5) -> 5.1774397e+08 | E6: Biaya BL
B7: =B6+F6 -> 5.1774397e+08
I9: =J9+3300.2*2 -> 25958 | J9: =J5-J7 -> 19357.6 | K9: Est. GP Margin | L9: =SUM(K12:K64)/M11-1 -> -0.031035173
A10: Produk | B10: Price/Kg | C10: Satuan | E10: SKU Fresh | F10: Non Blasting | G10: No. SKU | H10: Item Name | I10: Qty | J10: Yield | K10: Est. Harga Jual | L10: COGS/Kg | M10: COGS/Item | N10: (Price/Kg - COGS/Kg) | O10: (Est. Harga Jual - COGS/Item) | P10: Notes
E11: 7000 | F11: =+B6 -> 5.1774397e+08 | I11: =SUM(I12:I87) -> 16560.4 | J11: =SUM(J12:J87) -> 0.85549862 | K11: =SUM(K12:K87) -> 506989900 | M11: =SUM(M12:M87) -> 5.1774397e+08 | O11: =SUM(O12:O87) -> -10754074
A12: AU 0.3 | B12: =_xlfn.IFNA(_xlfn.XLOOKUP(A12,'Price list'!J:J,'Price list'!K:K),0) -> 0 | C12: Kg | H12: =IF(G12=0,"",_xlfn.XLOOKUP(G12,List_item!A:A,List_item!B:B)) | I12: 0 | J12: =IF(F12/J$5>0,F12/J$5,I12/J$5) -> 0 | K12: =+B12*(F12+I12) -> 0 | L12: =IFERROR(((K12/$K$11)*$F$11)/(F12+I12),0) -> 0 | M12: =+L12*(F12+I12) -> 0 | N12: =IF(L12=0,0,B12-L12) -> 0 | O12: =+K12-M12 -> 0
A13: AU 0.4 | B13: =_xlfn.IFNA(_xlfn.XLOOKUP(A13,'Price list'!J:J,'Price list'!K:K),0) -> 0 | C13: Kg | H13: =IF(G13=0,"",_xlfn.XLOOKUP(G13,List_item!A:A,List_item!B:B)) | I13: 0 | J13: =IF(F13/J$5>0,F13/J$5,I13/J$5) -> 0 | K13: =+B13*(F13+I13) -> 0 | L13: =IFERROR(((K13/$K$11)*$F$11)/(F13+I13),0) -> 0 | M13: =+L13*(F13+I13) -> 0 | N13: =IF(L13=0,0,B13-L13) -> 0 | O13: =+K13-M13 -> 0
A14: AU 0.5 | B14: =_xlfn.IFNA(_xlfn.XLOOKUP(A14,'Price list'!J:J,'Price list'!K:K),0) -> 37000 | C14: Kg | G14: JLB1865 | H14: =IF(G14=0,"",_xlfn.XLOOKUP(G14,List_item!A:A,List_item!B:B)) -> Karkas Uk 0.5 Karkas Uk 0.5 Frozen Premium | I14: 4.1 | J14: =IF(F14/J$5>0,F14/J$5,I14/J$5) -> 0.00021180312 | K14: =+B14*(F14+I14) -> 151700 | L14: =IFERROR(((K14/$K$11)*$F$11)/(F14+I14),0) -> 37784.83 | M14: =+L14*(F14+I14) -> 154917.8 | N14: =IF(L14=0,0,B14-L14) -> -784.82969 | O14: =+K14-M14 -> -3217.8017
A15: AU 0.6 | B15: =_xlfn.IFNA(_xlfn.XLOOKUP(A15,'Price list'!J:J,'Price list'!K:K),0) -> 37000 | C15: Kg | G15: JLB1866 | H15: =IF(G15=0,"",_xlfn.XLOOKUP(G15,List_item!A:A,List_item!B:B)) -> Karkas Uk 0.6 Karkas Uk 0.6 Frozen Premium | I15: 41.8 | J15: =IF(F15/J$5>0,F15/J$5,I15/J$5) -> 0.0021593586 | K15: =+B15*(F15+I15) -> 1546600 | L15: =IFERROR(((K15/$K$11)*$F$11)/(F15+I15),0) -> 37784.83 | M15: =+L15*(F15+I15) -> 1579405.9 | N15: =IF(L15=0,0,B15-L15) -> -784.82969 | O15: =+K15-M15 -> -32805.881
A16: AU 0.7 | B16: =_xlfn.IFNA(_xlfn.XLOOKUP(A16,'Price list'!J:J,'Price list'!K:K),0) -> 37000 | C16: Kg | G16: JLB1867 | H16: =IF(G16=0,"",_xlfn.XLOOKUP(G16,List_item!A:A,List_item!B:B)) -> Karkas Uk 0.7 Karkas Uk 0.7 Frozen Premium | I16: 257.2 | J16: =IF(F16/J$5>0,F16/J$5,I16/J$5) -> 0.013286771 | K16: =+B16*(F16+I16) -> 9516400 | L16: =IFERROR(((K16/$K$11)*$F$11)/(F16+I16),0) -> 37784.83 | M16: =+L16*(F16+I16) -> 9718258.2 | N16: =IF(L16=0,0,B16-L16) -> -784.82969 | O16: =+K16-M16 -> -201858.2
A17: AU 0.8 | B17: =_xlfn.IFNA(_xlfn.XLOOKUP(A17,'Price list'!J:J,'Price list'!K:K),0) -> 37000 | C17: Kg | G17: JLB1859 | H17: =IF(G17=0,"",_xlfn.XLOOKUP(G17,List_item!A:A,List_item!B:B)) -> Karkas Uk 0.8 Frozen Premium | I17: 300.2 | J17: =IF(F17/J$5>0,F17/J$5,I17/J$5) -> 0.015508121 | K17: =+B17*(F17+I17) -> 11107400 | L17: =IFERROR(((K17/$K$11)*$F$11)/(F17+I17),0) -> 37784.83 | M17: =+L17*(F17+I17) -> 11343006 | N17: =IF(L17=0,0,B17-L17) -> -784.82969 | O17: =+K17-M17 -> -235605.87
A18: AU 0.9 | B18: =_xlfn.IFNA(_xlfn.XLOOKUP(A18,'Price list'!J:J,'Price list'!K:K),0) -> 37000 | C18: Kg | G18: JLB1858 | H18: =IF(G18=0,"",_xlfn.XLOOKUP(G18,List_item!A:A,List_item!B:B)) -> Karkas Uk 0.9 Frozen Premium | I18: 1575.3 | J18: =IF(F18/J$5>0,F18/J$5,I18/J$5) -> 0.08137889 | K18: =+B18*(F18+I18) -> 58286100 | L18: =IFERROR(((K18/$K$11)*$F$11)/(F18+I18),0) -> 37784.83 | M18: =+L18*(F18+I18) -> 59522442 | N18: =IF(L18=0,0,B18-L18) -> -784.82969 | O18: =+K18-M18 -> -1236342.2
A19: AU 0.9 | B19: =_xlfn.IFNA(_xlfn.XLOOKUP(A19,'Price list'!J:J,'Price list'!K:K),0) -> 37000 | C19: Kg | G19: JLB0593 | H19: =IF(G19=0,"",_xlfn.XLOOKUP(G19,List_item!A:A,List_item!B:B)) -> Karkas Uk 0.9 Karkas Uk 0.9 Fresh Premium | I19: 570.2 | J19: =IF(F19/J$5>0,F19/J$5,I19/J$5) -> 0.029456131 | K19: =+B19*(F19+I19) -> 21097400 | L19: =IFERROR(((K19/$K$11)*$F$11)/(F19+I19),0) -> 37784.83 | M19: =+L19*(F19+I19) -> 21544910 | N19: =IF(L19=0,0,B19-L19) -> -784.82969 | O19: =+K19-M19 -> -447509.89
A20: AU 1.0 | B20: =_xlfn.IFNA(_xlfn.XLOOKUP(A20,'Price list'!J:J,'Price list'!K:K),0) -> 37000 | C20: Kg | G20: JLB0690 | H20: =IF(G20=0,"",_xlfn.XLOOKUP(G20,List_item!A:A,List_item!B:B)) -> Karkas Uk 1.0 Karkas Uk 1.0 Frozen Premium | I20: 828 | J20: =IF(F20/J$5>0,F20/J$5,I20/J$5) -> 0.042773898 | K20: =+B20*(F20+I20) -> 30636000 | L20: =IFERROR(((K20/$K$11)*$F$11)/(F20+I20),0) -> 37784.83 | M20: =+L20*(F20+I20) -> 31285839 | N20: =IF(L20=0,0,B20-L20) -> -784.82969 | O20: =+K20-M20 -> -649838.98
A21: AU 1.0 | B21: =_xlfn.IFNA(_xlfn.XLOOKUP(A21,'Price list'!J:J,'Price list'!K:K),0) -> 37000 | C21: Kg | G21: JLB0658 | H21: =IF(G21=0,"",_xlfn.XLOOKUP(G21,List_item!A:A,List_item!B:B)) -> Karkas Uk 1.0 Karkas Uk 1.0 Fresh Premium | I21: 1264.9 | J21: =IF(F21/J$5>0,F21/J$5,I21/J$5) -> 0.065343844 | K21: =+B21*(F21+I21) -> 46801300 | L21: =IFERROR(((K21/$K$11)*$F$11)/(F21+I21),0) -> 37784.83 | M21: =+L21*(F21+I21) -> 47794031 | N21: =IF(L21=0,0,B21-L21) -> -784.82969 | O21: =+K21-M21 -> -992731.08
A22: AU 1.1 | B22: =_xlfn.IFNA(_xlfn.XLOOKUP(A22,'Price list'!J:J,'Price list'!K:K),0) -> 37000 | C22: Kg | G22: JLB0756 | H22: =IF(G22=0,"",_xlfn.XLOOKUP(G22,List_item!A:A,List_item!B:B)) -> Karkas Uk 1.1 Karkas Uk 1.1 Frozen Premium | I22: 1195.7 | J22: =IF(F22/J$5>0,F22/J$5,I22/J$5) -> 0.061769021 | K22: =+B22*(F22+I22) -> 44240900 | L22: =IFERROR(((K22/$K$11)*$F$11)/(F22+I22),0) -> 37784.83 | M22: =+L22*(F22+I22) -> 45179321 | N22: =IF(L22=0,0,B22-L22) -> -784.82969 | O22: =+K22-M22 -> -938420.86
A23: AU 1.1 | B23: =_xlfn.IFNA(_xlfn.XLOOKUP(A23,'Price list'!J:J,'Price list'!K:K),0) -> 37000 | C23: Kg | G23: JLB0724 | H23: =IF(G23=0,"",_xlfn.XLOOKUP(G23,List_item!A:A,List_item!B:B)) -> Karkas Uk 1.1 Karkas Uk 1.1 Fresh Premium | I23: 1772.6 | J23: =IF(F23/J$5>0,F23/J$5,I23/J$5) -> 0.091571269 | K23: =+B23*(F23+I23) -> 65586200 | L23: =IFERROR(((K23/$K$11)*$F$11)/(F23+I23),0) -> 37784.83 | M23: =+L23*(F23+I23) -> 66977389 | N23: =IF(L23=0,0,B23-L23) -> -784.82969 | O23: =+K23-M23 -> -1391189.1
A24: AU 1.2 | B24: =_xlfn.IFNA(_xlfn.XLOOKUP(A24,'Price list'!J:J,'Price list'!K:K),0) -> 37000 | C24: Kg | G24: JLB0822 | H24: =IF(G24=0,"",_xlfn.XLOOKUP(G24,List_item!A:A,List_item!B:B)) -> Karkas Uk 1.2 Karkas Uk 1.2 Frozen Premium | I24: 2295.7 | J24: =IF(F24/J$5>0,F24/J$5,I24/J$5) -> 0.11859425 | K24: =+B24*(F24+I24) -> 84940900 | L24: =IFERROR(((K24/$K$11)*$F$11)/(F24+I24),0) -> 37784.83 | M24: =+L24*(F24+I24) -> 86742634 | N24: =IF(L24=0,0,B24-L24) -> -784.82969 | O24: =+K24-M24 -> -1801733.5
A25: AU 1.3 | B25: =_xlfn.IFNA(_xlfn.XLOOKUP(A25,'Price list'!J:J,'Price list'!K:K),0) -> 37000 | C25: Kg | G25: JLB0888 | H25: =IF(G25=0,"",_xlfn.XLOOKUP(G25,List_item!A:A,List_item!B:B)) -> Karkas Uk 1.3 Karkas Uk 1.3 Frozen Premium | I25: 885.5 | J25: =IF(F25/J$5>0,F25/J$5,I25/J$5) -> 0.045744307 | K25: =+B25*(F25+I25) -> 32763500 | L25: =IFERROR(((K25/$K$11)*$F$11)/(F25+I25),0) -> 37784.83 | M25: =+L25*(F25+I25) -> 33458467 | N25: =IF(L25=0,0,B25-L25) -> -784.82969 | O25: =+K25-M25 -> -694966.69
... A28: AU 1.6 | B28: =_xlfn.IFNA(_xlfn.XLOOKUP(A28,'Price list'!J:J,'Price list'!K:K),0) -> 37000 | C28: Kg | G28: JLB1086 | H28: =IF(G28=0,"",_xlfn.XLOOKUP(G28,List_item!A:A,List_item!B:B)) -> Karkas Uk 1.6 Karkas Uk 1.6 Frozen Premium | I28: 8.3 | J28: =IF(F28/J$5>0,F28/J$5,I28/J$5) -> 0.00042877216 | K28: =+B28*(F28+I28) -> 307100 | L28: =IFERROR(((K28/$K$11)*$F$11)/(F28+I28),0) -> 37784.83 | M28: =+L28*(F28+I28) -> 313614.09 | N28: =IF(L28=0,0,B28-L28) -> -784.82969 | O28: =+K28-M28 -> -6514.0864
A29: AU 1.7 | B29: =_xlfn.IFNA(_xlfn.XLOOKUP(A29,'Price list'!J:J,'Price list'!K:K),0) -> 37000 | C29: Kg | H29: =IF(G29=0,"",_xlfn.XLOOKUP(G29,List_item!A:A,List_item!B:B)) | I29: 0 | J29: =IF(F29/J$5>0,F29/J$5,I29/J$5) -> 0 | K29: =+B29*(F29+I29) -> 0 | L29: =IFERROR(((K29/$K$11)*$F$11)/(F29+I29),0) -> 0 | M29: =+L29*(F29+I29) -> 0 | N29: =IF(L29=0,0,B29-L29) -> 0 | O29: =+K29-M29 -> 0
A30: AU 1.8 | B30: =_xlfn.IFNA(_xlfn.XLOOKUP(A30,'Price list'!J:J,'Price list'!K:K),0) -> 37000 | C30: Kg | H30: =IF(G30=0,"",_xlfn.XLOOKUP(G30,List_item!A:A,List_item!B:B)) | I30: 0 | J30: =IF(F30/J$5>0,F30/J$5,I30/J$5) -> 0 | K30: =+B30*(F30+I30) -> 0 | L30: =IFERROR(((K30/$K$11)*$F$11)/(F30+I30),0) -> 0 | M30: =+L30*(F30+I30) -> 0 | N30: =IF(L30=0,0,B30-L30) -> 0 | O30: =+K30-M30 -> 0
A31: AU 1.9 | B31: =_xlfn.IFNA(_xlfn.XLOOKUP(A31,'Price list'!J:J,'Price list'!K:K),0) -> 37000 | C31: Kg | H31: =IF(G31=0,"",_xlfn.XLOOKUP(G31,List_item!A:A,List_item!B:B)) | I31: 0 | J31: =IF(F31/J$5>0,F31/J$5,I31/J$5) -> 0 | K31: =+B31*(F31+I31) -> 0 | L31: =IFERROR(((K31/$K$11)*$F$11)/(F31+I31),0) -> 0 | M31: =+L31*(F31+I31) -> 0 | N31: =IF(L31=0,0,B31-L31) -> 0 | O31: =+K31-M31 -> 0
A32: AU 2.0 | B32: =_xlfn.IFNA(_xlfn.XLOOKUP(A32,'Price list'!J:J,'Price list'!K:K),0) -> 37000 | C32: Kg | H32: =IF(G32=0,"",_xlfn.XLOOKUP(G32,List_item!A:A,List_item!B:B)) | I32: 0 | J32: =IF(F32/J$5>0,F32/J$5,I32/J$5) -> 0 | K32: =+B32*(F32+I32) -> 0 | L32: =IFERROR(((K32/$K$11)*$F$11)/(F32+I32),0)+IFERROR(((K32/SUMIF(H:H,"*Boneless*",K:K))*$F$6)/I32,0) -> 0 | M32: =+L32*(F32+I32) -> 0 | N32: =IF(L32=0,0,B32-L32) -> 0 | O32: =+K32-M32 -> 0 | P32: =IFERROR(((K32/SUMIF(H:H,"*Boneless*",K:K))*$F$6),0) -> 0 | Q32: =SUMIF(H:H,"*Boneless*",K:K) -> 25268200
A33: AU UP | B33: =_xlfn.IFNA(_xlfn.XLOOKUP(A33,'Price list'!J:J,'Price list'!K:K),0) -> 0 | C33: Kg | H33: =IF(G33=0,"",_xlfn.XLOOKUP(G33,List_item!A:A,List_item!B:B)) | I33: 0 | J33: =IF(F33/J$5>0,F33/J$5,I33/J$5) -> 0 | K33: =+B33*(F33+I33) -> 0 | L33: =IFERROR(((K33/$K$11)*$F$11)/(F33+I33),0) -> 0 | M33: =+L33*(F33+I33) -> 0 | N33: =IF(L33=0,0,B33-L33) -> 0 | O33: =+K33-M33 -> 0
A34: BLD | B34: =_xlfn.IFNA(_xlfn.XLOOKUP(A34,'Price list'!J:J,'Price list'!K:K),0) -> 50000 | C34: Kg | H34: =IF(G34=0,"",_xlfn.XLOOKUP(G34,List_item!A:A,List_item!B:B)) | I34: 0 | J34: =IF(F34/J$5>0,F34/J$5,I34/J$5) -> 0 | K34: =+B34*(F34+I34) -> 0 | L34: =IFERROR(((K34/$K$11)*$F$11)/(F34+I34),0)+IFERROR(((K34/SUMIF(H:H,"*Boneless*",K:K))*$F$6)/I34,0) -> 0 | M34: =+L34*(F34+I34) -> 0 | N34: =IF(L34=0,0,B34-L34) -> 0 | O34: =+K34-M34 -> 0 | P34: =IFERROR(((K34/SUMIF(H:H,"*Boneless*",K:K))*$F$6),0) -> 0 | Q34: =SUMIF(H:H,"*Boneless*",K:K) -> 25268200
A35: BLPK | B35: =_xlfn.IFNA(_xlfn.XLOOKUP(A35,'Price list'!J:J,'Price list'!K:K),0) -> 48000 | C35: Kg | H35: =IF(G35=0,"",_xlfn.XLOOKUP(G35,List_item!A:A,List_item!B:B)) | I35: 0 | J35: =IF(F35/J$5>0,F35/J$5,I35/J$5) -> 0 | K35: =+B35*(F35+I35) -> 0 | L35: =IFERROR(((K35/$K$11)*$F$11)/(F35+I35),0)+IFERROR(((K35/SUMIF(H:H,"*Boneless*",K:K))*$F$6)/I35,0) -> 0 | M35: =+L35*(F35+I35) -> 0 | N35: =IF(L35=0,0,B35-L35) -> 0 | O35: =+K35-M35 -> 0 | P35: =IFERROR(((K35/SUMIF(H:H,"*Boneless*",K:K))*$F$6),0) -> 0 | Q35: =SUMIF(H:H,"*Boneless*",K:K) -> 25268200
A36: BLP | B36: =_xlfn.IFNA(_xlfn.XLOOKUP(A36,'Price list'!J:J,'Price list'!K:K),0) -> 49000 | C36: Kg | H36: =IF(G36=0,"",_xlfn.XLOOKUP(G36,List_item!A:A,List_item!B:B)) | I36: 0 | J36: =IF(F36/J$5>0,F36/J$5,I36/J$5) -> 0 | K36: =+B36*(F36+I36) -> 0 | L36: =IFERROR(((K36/$K$11)*$F$11)/(F36+I36),0)+IFERROR(((K36/SUMIF(H:H,"*Boneless*",K:K))*$F$6)/I36,0) -> 0 | M36: =+L36*(F36+I36) -> 0 | N36: =IF(L36=0,0,B36-L36) -> 0 | O36: =+K36-M36 -> 0 | P36: =IFERROR(((K36/SUMIF(H:H,"*Boneless*",K:K))*$F$6),0) -> 0 | Q36: =SUMIF(H:H,"*Boneless*",K:K) -> 25268200
A37: Krk | B37: =_xlfn.IFNA(_xlfn.XLOOKUP(A37,'Price list'!J:J,'Price list'!K:K),0) -> 12500 | C37: Kg | H37: =IF(G37=0,"",_xlfn.XLOOKUP(G37,List_item!A:A,List_item!B:B)) | I37: 0 | J37: =IF(F37/J$5>0,F37/J$5,I37/J$5) -> 0 | K37: =+B37*(F37+I37) -> 0 | L37: =IFERROR(((K37/$K$11)*$F$11)/(F37+I37),0)+IFERROR(((K37/SUMIF(H:H,"*Boneless*",K:K))*$F$6)/I37,0) -> 0 | M37: =+L37*(F37+I37) -> 0 | N37: =IF(L37=0,0,B37-L37) -> 0 | O37: =+K37-M37 -> 0 | P37: =IFERROR(((K37/SUMIF(H:H,"*Boneless*",K:K))*$F$6),0) -> 0 | Q37: =SUMIF(H:H,"*Boneless*",K:K) -> 25268200
A38: kulit | B38: =_xlfn.IFNA(_xlfn.XLOOKUP(A38,'Price list'!J:J,'Price list'!K:K),0) -> 32000 | C38: Kg | H38: =IF(G38=0,"",_xlfn.XLOOKUP(G38,List_item!A:A,List_item!B:B)) | I38: 0 | J38: =IF(F38/J$5>0,F38/J$5,I38/J$5) -> 0 | K38: =+B38*(F38+I38) -> 0 | L38: =IFERROR(((K38/$K$11)*$F$11)/(F38+I38),0)+IFERROR(((K38/SUMIF(H:H,"*Boneless*",K:K))*$F$6)/I38,0) -> 0 | M38: =+L38*(F38+I38) -> 0 | N38: =IF(L38=0,0,B38-L38) -> 0 | O38: =+K38-M38 -> 0 | P38: =IFERROR(((K38/SUMIF(H:H,"*Boneless*",K:K))*$F$6),0) -> 0 | Q38: =SUMIF(H:H,"*Boneless*",K:K) -> 25268200
A39: Sayap | B39: =_xlfn.IFNA(_xlfn.XLOOKUP(A39,'Price list'!J:J,'Price list'!K:K),0) -> 36000 | C39: Kg | H39: =IF(G39=0,"",_xlfn.XLOOKUP(G39,List_item!A:A,List_item!B:B)) | I39: 0 | J39: =IF(F39/J$5>0,F39/J$5,I39/J$5) -> 0 | K39: =+B39*(F39+I39) -> 0 | L39: =IFERROR(((K39/$K$11)*$F$11)/(F39+I39),0)+IFERROR(((K39/SUMIF(H:H,"*Boneless*",K:K))*$F$6)/I39,0) -> 0 | M39: =+L39*(F39+I39) -> 0 | N39: =IF(L39=0,0,B39-L39) -> 0 | O39: =+K39-M39 -> 0 | P39: =IFERROR(((K39/SUMIF(H:H,"*Boneless*",K:K))*$F$6),0) -> 0 | Q39: =SUMIF(H:H,"*Boneless*",K:K) -> 25268200
A40: Sayap grade A | B40: =_xlfn.IFNA(_xlfn.XLOOKUP(A40,'Price list'!J:J,'Price list'!K:K),0) -> 32000 | C40: Kg | H40: =IF(G40=0,"",_xlfn.XLOOKUP(G40,List_item!A:A,List_item!B:B)) | I40: 0 | J40: =IF(F40/J$5>0,F40/J$5,I40/J$5) -> 0 | K40: =+B40*(F40+I40) -> 0 | L40: =IFERROR(((K40/$K$11)*$F$11)/(F40+I40),0) -> 0 | M40: =+L40*(F40+I40) -> 0 | N40: =IF(L40=0,0,B40-L40) -> 0 | O40: =+K40-M40 -> 0
