Workbook

Sheet 00_Petunjuk
A1: KGR WEEKLY OUTLOOK — PETUNJUK
B4: Tujuan | C4: Satu file per minggu (Senin–Minggu), diupdate setiap pagi, untuk keputusan harian: potong berapa dan beli live bird di harga berapa (RPA), beli apa dan berapa (Trading), stok mana yang harus dijual, dan berapa kas keluar. Halaman utama: O_Outlook.
B5: Setiap pagi (±30 menit) | C5: 1) I_Parameter: ganti Tanggal update dan Harga live bird hari ini. 2) T_Penjualan: tempel penjualan kemarin dari Accurate (Status = Aktual, isi HPP aktual dari DO kalau ada); ubah order yang sudah terkirim jadi Aktual; tambah order baru dari sales (Status = Order, tanggal kirim rencana). 3) T_Penerimaan: tempel GRN kemarin (Aktual); perbarui rencana terima trading (Rencana). 4) T_Batch: isi batch kemarin dari data ops (Aktual); perbarui rencana potong (Rencana). 5) Cek Z_Kontrol = LULUS, lalu kirim O_Outlook.
B6: Setiap Senin | C6: Buat file minggu baru: isi I_Stok_Awal dari Inventory Valuation Accurate (kg, nilai, umur), isi baris "Minggu lalu" di I_Parameter dari ringkasan outlook minggu sebelumnya, kosongkan T_Penjualan / T_Penerimaan / T_Batch, perbarui harga acuan di I_Master.
B7: Siapa mengisi | C7: Senior Inventory Accounting: aktual dari Accurate (penjualan, GRN, stok awal). Sales: order. PPIC: rencana potong (T_Batch Rencana). Purchasing / Manajer Operasional: harga LB, rencana beli trading, harga beli pengganti.
B8: Cara hitung | C8: GP produk = revenue − HPP. Penjualan aktual pakai HPP dari Accurate; order dinilai di biaya rata-rata stok minggu ini (stok awal + penerimaan). Cost of sales others (angkut, blasting) dan opex tidak termasuk. Breakeven live bird = (1 − shrink) × (yield karkas × harga karkas + Σ yield by-product × harga) − angkut − maklon × (1 − shrink). Porsi fresh rencana = kebutuhan karkas fresh ÷ karkas dari potong rencana. Stok per hari = stok kemarin + terima − jual (aktual untuk hari lewat, rencana/order mulai hari ini).
B9: Warna | C9: Biru di latar krem = input. Hijau = link dari sheet lain. Hitam = rumus. Merah = peringatan.
B10: Contoh isi | C10: File ini berisi contoh minggu 24–30 Agustus 2026, update 27 Agustus: aktual dari Accurate (DO, GRN, inventory valuation), order = pengiriman aktual 27–30 Agu, rencana potong = batch ops 27–28 Agu, harga = rata-rata Agustus. Ganti dengan data minggu berjalan.
B11: Laporan keuangan mingguan | C11: O_PnL, O_BS, O_CF. Aktual dari jurnal Accurate (T_GL) di atas neraca saldo awal (I_TB). Sisa minggu: revenue dan HPP dari order, biaya lain dari run-rate (I_RunRate), kas dari T_Kas_Rencana plus pembayaran live bird / trading / angkut-maklon yang jatuh tempo sesuai termin di I_Parameter. Setiap pagi: tempel jurnal kemarin ke T_GL. Setiap awal bulan: perbarui I_RunRate dengan aktual bulan lalu. I_TB diganti bila tanggal saldo awal diganti (mis. TB akhir bulan lalu).
B12: Arus kas aktual | C12: Setiap baris kas diberi kategori dari akun lawan terbesar dalam voucher yang sama (I_COA kolom F). Kalau salah, isi Override di T_GL kolom R.

Sheet O_Outlook
A1: KGR — WEEKLY OUTLOOK DAN KEPUTUSAN HARIAN
A2: Minggu (Senin – Minggu): | B2: =I_Parameter!$C$5 -> 46258 | C2: =I_Parameter!$C$6 -> 46264 | E2: Update: | F2: =I_Parameter!$C$4 -> 46261 | H2: Aktual = transaksi s.d. kemarin; sisa minggu = order + rencana mulai hari ini.
A4: 1. RINGKASAN MINGGU — GP produk (HPP dari Accurate; order dinilai di biaya rata-rata stok minggu ini; cost of sales others tidak termasuk)
A5: Segmen | B5: kg aktual s.d. kemarin | C5: Revenue aktual Rp | D5: GP aktual Rp | E5: kg order sisa minggu | F5: Revenue order Rp | G5: GP order Rp | H5: kg proyeksi minggu | I5: Revenue proyeksi Rp | J5: GP proyeksi Rp | K5: GP/kg proyeksi | L5: GP % proyeksi | M5: GP/kg minggu lalu | N5: Δ GP/kg
A6: RPA | B6: =SUMIFS(T_Penjualan!$H$6:$H$1505,T_Penjualan!$N$6:$N$1505,"RPA",T_Penjualan!$B$6:$B$1505,"Aktual",T_Penjualan!$P$6:$P$1505,1) -> 7942.69 | C6: =SUMIFS(T_Penjualan!$J$6:$J$1505,T_Penjualan!$N$6:$N$1505,"RPA",T_Penjualan!$B$6:$B$1505,"Aktual",T_Penjualan!$P$6:$P$1505,1) -> 2.2400658e+08 | D6: =SUMIFS(T_Penjualan!$M$6:$M$1505,T_Penjualan!$N$6:$N$1505,"RPA",T_Penjualan!$B$6:$B$1505,"Aktual",T_Penjualan!$P$6:$P$1505,1) -> -10279045 | E6: =SUMIFS(T_Penjualan!$H$6:$H$1505,T_Penjualan!$N$6:$N$1505,"RPA",T_Penjualan!$B$6:$B$1505,"Order",T_Penjualan!$P$6:$P$1505,1) -> 23783.76 | F6: =SUMIFS(T_Penjualan!$J$6:$J$1505,T_Penjualan!$N$6:$N$1505,"RPA",T_Penjualan!$B$6:$B$1505,"Order",T_Penjualan!$P$6:$P$1505,1) -> 6.3161319e+08 | G6: =SUMIFS(T_Penjualan!$M$6:$M$1505,T_Penjualan!$N$6:$N$1505,"RPA",T_Penjualan!$B$6:$B$1505,"Order",T_Penjualan!$P$6:$P$1505,1) -> -52292801 | H6: =B6+E6 -> 31726.45 | I6: =C6+F6 -> 8.5561977e+08 | J6: =D6+G6 -> -62571846 | K6: =IF(H6=0,0,J6/H6) -> -1972.2297 | L6: =IF(I6=0,0,J6/I6) -> -0.073130435 | M6: =IF(I_Parameter!C38=0,0,I_Parameter!E38/I_Parameter!C38) -> -154.72464 | N6: =K6-M6 -> -1817.505
A7: Trading | B7: =SUMIFS(T_Penjualan!$H$6:$H$1505,T_Penjualan!$N$6:$N$1505,"Trading",T_Penjualan!$B$6:$B$1505,"Aktual",T_Penjualan!$P$6:$P$1505,1) -> 15645.28 | C7: =SUMIFS(T_Penjualan!$J$6:$J$1505,T_Penjualan!$N$6:$N$1505,"Trading",T_Penjualan!$B$6:$B$1505,"Aktual",T_Penjualan!$P$6:$P$1505,1) -> 3.4712513e+08 | D7: =SUMIFS(T_Penjualan!$M$6:$M$1505,T_Penjualan!$N$6:$N$1505,"Trading",T_Penjualan!$B$6:$B$1505,"Aktual",T_Penjualan!$P$6:$P$1505,1) -> 15239014 | E7: =SUMIFS(T_Penjualan!$H$6:$H$1505,T_Penjualan!$N$6:$N$1505,"Trading",T_Penjualan!$B$6:$B$1505,"Order",T_Penjualan!$P$6:$P$1505,1) -> 16653.64 | F7: =SUMIFS(T_Penjualan!$J$6:$J$1505,T_Penjualan!$N$6:$N$1505,"Trading",T_Penjualan!$B$6:$B$1505,"Order",T_Penjualan!$P$6:$P$1505,1) -> 4.3621227e+08 | G7: =SUMIFS(T_Penjualan!$M$6:$M$1505,T_Penjualan!$N$6:$N$1505,"Trading",T_Penjualan!$B$6:$B$1505,"Order",T_Penjualan!$P$6:$P$1505,1) -> -244556.72 | H7: =B7+E7 -> 32298.92 | I7: =C7+F7 -> 7.8333739e+08 | J7: =D7+G7 -> 14994457 | K7: =IF(H7=0,0,J7/H7) -> 464.24021 | L7: =IF(I7=0,0,J7/I7) -> 0.019141761 | M7: =IF(I_Parameter!C39=0,0,I_Parameter!E39/I_Parameter!C39) -> 1972.6891 | N7: =K7-M7 -> -1508.4489
A8: TOTAL KGR | B8: =B6+B7 -> 23587.97 | C8: =C6+C7 -> 5.711317e+08 | D8: =D6+D7 -> 4959969.3 | E8: =E6+E7 -> 40437.4 | F8: =F6+F7 -> 1.0678255e+09 | G8: =G6+G7 -> -52537358 | H8: =H6+H7 -> 64025.37 | I8: =I6+I7 -> 1.6389572e+09 | J8: =J6+J7 -> -47577388 | K8: =IF(H8=0,0,J8/H8) -> -743.10212 | L8: =IF(I8=0,0,J8/I8) -> -0.029029061 | M8: =IF(I_Parameter!C38+I_Parameter!C39=0,0,(I_Parameter!E38+I_Parameter!E39)/(I_Parameter!C38+I_Parameter!C39)) -> 883.35737 | N8: =K8-M8 -> -1626.4595
A10: 2. KEPUTUSAN RPA — potong berapa, beli live bird di harga berapa
A11: Indikator | B11: Nilai | C11: Satuan | D11: Cara hitung
A12: Harga live bird hari ini (penawaran) | B12: =I_Parameter!$C$11 -> 24600 | C12: Rp/kg LB | D12: I_Parameter
A13: Order karkas fresh — hari ini s.d. horizon | B13: =SUMIFS(T_Penjualan!$H$6:$H$1505,T_Penjualan!$G$6:$G$1505,"RPA|Karkas|Fresh",T_Penjualan!$B$6:$B$1505,"Order",T_Penjualan!$A$6:$A$1505,">="&I_Parameter!$C$4,T_Penjualan!$A$6:$A$1505,"<="&(I_Parameter!$C$4+I_Parameter!$C$7-1)) -> 12307.15 | C13: kg | D13: T_Penjualan: order RPA|Karkas|Fresh dalam horizon
A14: Stok karkas fresh hari ini | B14: =IFERROR(INDEX(O_Stok!$S$6:$S$85,MATCH("RPA|Karkas|Fresh",O_Stok!$A$6:$A$85,0)),0) -> 18768.21 | C14: kg | D14: O_Stok
A15: Kebutuhan bersih karkas fresh | B15: =MAX(0,B13-B14) -> 0 | C15: kg | D15: order − stok
A16: Live bird maksimum tanpa menambah karkas frozen | B16: =IF(I_Parameter!$C$19*(1-I_Parameter!$C$8)=0,0,B15/((1-I_Parameter!$C$8)*I_Parameter!$C$19)) -> 0 | C16: kg LB | D16: kebutuhan bersih ÷ ((1 − shrink) × yield karkas)
A17: Live bird yang sudah direncanakan potong (horizon) | B17: =SUMIFS(T_Batch!$E$6:$E$55,T_Batch!$B$6:$B$55,"Rencana",T_Batch!$A$6:$A$55,">="&I_Parameter!$C$4,T_Batch!$A$6:$A$55,"<="&(I_Parameter!$C$4+I_Parameter!$C$7-1)) -> 27218.6 | C17: kg LB | D17: T_Batch: Rencana
A18: Karkas yang berpotensi jadi frozen | B18: =MAX(0,B17-B16)*(1-I_Parameter!$C$8)*I_Parameter!$C$19 -> 19474.899 | C18: kg | D18: kelebihan potong × (1 − shrink) × yield karkas
A19: Porsi karkas fresh dari potong rencana | B19: =IF(B17=0,1,MIN(1,B15/(B17*(1-I_Parameter!$C$8)*I_Parameter!$C$19))) -> 0 | C19: %
A20: Nilai output per kg live bird (porsi fresh rencana) | B20: =(1-I_Parameter!$C$8)*(I_Parameter!$C$19*(B19*I_Parameter!$C$28+(1-B19)*I_Parameter!$C$29)+I_Parameter!$C$20*I_Parameter!$C$30+I_Parameter!$C$21*I_Parameter!$C$31+I_Parameter!$C$22*I_Parameter!$C$32+I_Parameter!$C$23*I_Parameter!$C$33+I_Parameter!$C$24*I_Parameter!$C$34) -> 23277.657 | C20: Rp/kg LB | D20: harga acuan × yield parameter
A21: Breakeven live bird — porsi fresh rencana | B21: =B20-I_Parameter!$C$9-I_Parameter!$C$10*(1-I_Parameter!$C$8) -> 20725.657 | C21: Rp/kg LB | D21: nilai output − angkut − maklon
A22: Breakeven live bird — 100% karkas fresh | B22: =(1-I_Parameter!$C$8)*(I_Parameter!$C$19*I_Parameter!$C$28+I_Parameter!$C$20*I_Parameter!$C$30+I_Parameter!$C$21*I_Parameter!$C$31+I_Parameter!$C$22*I_Parameter!$C$32+I_Parameter!$C$23*I_Parameter!$C$33+I_Parameter!$C$24*I_Parameter!$C$34)-I_Parameter!$C$9-I_Parameter!$C$10*(1-I_Parameter!$C$8) -> 24336.784 | C22: Rp/kg LB | D22: batas atas
A23: Margin per kg live bird di harga hari ini | B23: =B21-B12 -> -3874.3425 | C23: Rp/kg LB | D23: breakeven − harga
A24: Perkiraan margin potong rencana | B24: =B23*B17 -> -1.0545418e+08 | C24: Rp | D24: margin/kg × kg LB rencana
A25: Potensi selisih harga karkas yang jadi frozen | B25: =B18*(I_Parameter!$C$28-I_Parameter!$C$29) -> 98289817 | C25: Rp | D25: kg frozen × (harga fresh − frozen)
A26: REKOMENDASI RPA | B26: =IF(B12>B22,"TUNDA / NEGOSIASI: harga LB "&FIXED(B12,0)&" di atas breakeven 100% fresh "&FIXED(B22,0)&" — setiap kg LB rugi walau semua karkas laku fresh",IF(B17>B16+0.5,"KURANGI potong ke maksimum "&FIXED(B16,0)&" kg LB (rencana "&FIXED(B17,0)&" kg) supaya karkas tidak jadi frozen",IF(B23<0,"POTONG HANYA SESUAI ORDER: margin per kg LB negatif ("&FIXED(B23,0)&")","LANJUT sesuai rencana: harga LB di bawah breakeven dan kebutuhan fresh tertutup"))) -> TUNDA / NEGOSIASI: harga LB 24,600 di atas breakeven 100% fresh 24,337 — setiap kg LB rugi walau semua karkas laku fresh
A28: 3. KEPUTUSAN TRADING — beli apa, berapa, di spread berapa
A29: SKU (key) | B29: Stok hari ini kg | C29: Order sisa minggu kg | D29: Rencana terima sisa minggu kg | E29: Kebutuhan bersih kg | F29: Harga jual order Rp/kg | G29: Harga beli pengganti Rp/kg | H29: Spread Rp/kg | I29: Spread % | J29: Biaya stok rata-rata Rp/kg | K29: REKOMENDASI
A30: BLD|Frozen | B30: =IFERROR(INDEX(O_Stok!$S$6:$S$85,MATCH("Trading|BLD|Frozen",O_Stok!$A$6:$A$85,0)),0) -> 4848.44 | C30: =IFERROR(INDEX(O_Stok!$T$6:$T$85,MATCH("Trading|BLD|Frozen",O_Stok!$A$6:$A$85,0)),0) -> 0 | D30: =SUMIFS(T_Penerimaan!$I$6:$I$1005,T_Penerimaan!$H$6:$H$1005,"Trading|BLD|Frozen",T_Penerimaan!$B$6:$B$1005,"Rencana",T_Penerimaan!$A$6:$A$1005,">="&I_Parameter!$C$4,T_Penerimaan!$A$6:$A$1005,"<="&I_Parameter!$C$6) -> 0 | E30: =MAX(0,C30-B30-D30) -> 0 | F30: =IFERROR(SUMIFS(T_Penjualan!$J$6:$J$1505,T_Penjualan!$G$6:$G$1505,"Trading|BLD|Frozen",T_Penjualan!$B$6:$B$1505,"Order",T_Penjualan!$A$6:$A$1505,">="&I_Parameter!$C$4)/SUMIFS(T_Penjualan!$H$6:$H$1505,T_Penjualan!$G$6:$G$1505,"Trading|BLD|Frozen",T_Penjualan!$B$6:$B$1505,"Order",T_Penjualan!$A$6:$A$1505,">="&I_Parameter!$C$4),IFERROR(INDEX(I_Master!$F$6:$F$85,MATCH("Trading|BLD|Frozen",I_Master!$A$6:$A$85,0)),0)) -> 42083 | G30: =IFERROR(INDEX(I_Master!$G$6:$G$85,MATCH("Trading|BLD|Frozen",I_Master!$A$6:$A$85,0)),"") -> 38169 | H30: =IF(OR(G30="",G30=0,F30=0),"",F30-G30) -> 3914 | I30: =IF(H30="","",H30/F30) -> 0.093006677 | J30: =IFERROR(INDEX(O_Stok!$Q$6:$Q$85,MATCH("Trading|BLD|Frozen",O_Stok!$A$6:$A$85,0)),0) -> 39097.081 | K30: =IF(E30>0.5,IF(H30="","BELI "&FIXED(E30,0)&" kg — isi harga beli pengganti",IF(H30>=I_Parameter!$C$12,"BELI "&FIXED(E30,0)&" kg (spread "&FIXED(H30,0)&"/kg)","TAHAN: spread "&FIXED(H30,0)&"/kg di bawah minimum — naikkan harga jual atau cari pemasok")),IF(AND(B30>0.5,C30<=0.5),"JUAL STOK: "&FIXED(B30,0)&" kg tanpa order",IF(AND(C30>0.5,J30>0,F30<J30),"CEK HARGA: order "&FIXED(F30,0)&"/kg di bawah biaya stok "&FIXED(J30,0)&"/kg",IF(B30>0.5,"Cukup — sisa "&FIXED(B30-C30+D30,0)&" kg setelah order","-")))) -> JUAL STOK: 4,848 kg tanpa order
A31: BLD|n/a | B31: =IFERROR(INDEX(O_Stok!$S$6:$S$85,MATCH("Trading|BLD|n/a",O_Stok!$A$6:$A$85,0)),0) -> 10.2 | C31: =IFERROR(INDEX(O_Stok!$T$6:$T$85,MATCH("Trading|BLD|n/a",O_Stok!$A$6:$A$85,0)),0) -> 0 | D31: =SUMIFS(T_Penerimaan!$I$6:$I$1005,T_Penerimaan!$H$6:$H$1005,"Trading|BLD|n/a",T_Penerimaan!$B$6:$B$1005,"Rencana",T_Penerimaan!$A$6:$A$1005,">="&I_Parameter!$C$4,T_Penerimaan!$A$6:$A$1005,"<="&I_Parameter!$C$6) -> 0 | E31: =MAX(0,C31-B31-D31) -> 0 | F31: =IFERROR(SUMIFS(T_Penjualan!$J$6:$J$1505,T_Penjualan!$G$6:$G$1505,"Trading|BLD|n/a",T_Penjualan!$B$6:$B$1505,"Order",T_Penjualan!$A$6:$A$1505,">="&I_Parameter!$C$4)/SUMIFS(T_Penjualan!$H$6:$H$1505,T_Penjualan!$G$6:$G$1505,"Trading|BLD|n/a",T_Penjualan!$B$6:$B$1505,"Order",T_Penjualan!$A$6:$A$1505,">="&I_Parameter!$C$4),IFERROR(INDEX(I_Master!$F$6:$F$85,MATCH("Trading|BLD|n/a",I_Master!$A$6:$A$85,0)),0)) -> 45000 | G31: =IFERROR(INDEX(I_Master!$G$6:$G$85,MATCH("Trading|BLD|n/a",I_Master!$A$6:$A$85,0)),"") -> 0 | H31: =IF(OR(G31="",G31=0,F31=0),"",F31-G31) | I31: =IF(H31="","",H31/F31) | J31: =IFERROR(INDEX(O_Stok!$Q$6:$Q$85,MATCH("Trading|BLD|n/a",O_Stok!$A$6:$A$85,0)),0) -> 43000 | K31: =IF(E31>0.5,IF(H31="","BELI "&FIXED(E31,0)&" kg — isi harga beli pengganti",IF(H31>=I_Parameter!$C$12,"BELI "&FIXED(E31,0)&" kg (spread "&FIXED(H31,0)&"/kg)","TAHAN: spread "&FIXED(H31,0)&"/kg di bawah minimum — naikkan harga jual atau cari pemasok")),IF(AND(B31>0.5,C31<=0.5),"JUAL STOK: "&FIXED(B31,0)&" kg tanpa order",IF(AND(C31>0.5,J31>0,F31<J31),"CEK HARGA: order "&FIXED(F31,0)&"/kg di bawah biaya stok "&FIXED(J31,0)&"/kg",IF(B31>0.5,"Cukup — sisa "&FIXED(B31-C31+D31,0)&" kg setelah order","-")))) -> JUAL STOK: 10 kg tanpa order
A32: BLP|Frozen | B32: =IFERROR(INDEX(O_Stok!$S$6:$S$85,MATCH("Trading|BLP|Frozen",O_Stok!$A$6:$A$85,0)),0) -> 10141 | C32: =IFERROR(INDEX(O_Stok!$T$6:$T$85,MATCH("Trading|BLP|Frozen",O_Stok!$A$6:$A$85,0)),0) -> 3229.2 | D32: =SUMIFS(T_Penerimaan!$I$6:$I$1005,T_Penerimaan!$H$6:$H$1005,"Trading|BLP|Frozen",T_Penerimaan!$B$6:$B$1005,"Rencana",T_Penerimaan!$A$6:$A$1005,">="&I_Parameter!$C$4,T_Penerimaan!$A$6:$A$1005,"<="&I_Parameter!$C$6) -> 0 | E32: =MAX(0,C32-B32-D32) -> 0 | F32: =IFERROR(SUMIFS(T_Penjualan!$J$6:$J$1505,T_Penjualan!$G$6:$G$1505,"Trading|BLP|Frozen",T_Penjualan!$B$6:$B$1505,"Order",T_Penjualan!$A$6:$A$1505,">="&I_Parameter!$C$4)/SUMIFS(T_Penjualan!$H$6:$H$1505,T_Penjualan!$G$6:$G$1505,"Trading|BLP|Frozen",T_Penjualan!$B$6:$B$1505,"Order",T_Penjualan!$A$6:$A$1505,">="&I_Parameter!$C$4),IFERROR(INDEX(I_Master!$F$6:$F$85,MATCH("Trading|BLP|Frozen",I_Master!$A$6:$A$85,0)),0)) -> 43086 | G32: =IFERROR(INDEX(I_Master!$G$6:$G$85,MATCH("Trading|BLP|Frozen",I_Master!$A$6:$A$85,0)),"") -> 49577 | H32: =IF(OR(G32="",G32=0,F32=0),"",F32-G32) -> -6491 | I32: =IF(H32="","",H32/F32) -> -0.15065218 | J32: =IFERROR(INDEX(O_Stok!$Q$6:$Q$85,MATCH("Trading|BLP|Frozen",O_Stok!$A$6:$A$85,0)),0) -> 47198.571 | K32: =IF(E32>0.5,IF(H32="","BELI "&FIXED(E32,0)&" kg — isi harga beli pengganti",IF(H32>=I_Parameter!$C$12,"BELI "&FIXED(E32,0)&" kg (spread "&FIXED(H32,0)&"/kg)","TAHAN: spread "&FIXED(H32,0)&"/kg di bawah minimum — naikkan harga jual atau cari pemasok")),IF(AND(B32>0.5,C32<=0.5),"JUAL STOK: "&FIXED(B32,0)&" kg tanpa order",IF(AND(C32>0.5,J32>0,F32<J32),"CEK HARGA: order "&FIXED(F32,0)&"/kg di bawah biaya stok "&FIXED(J32,0)&"/kg",IF(B32>0.5,"Cukup — sisa "&FIXED(B32-C32+D32,0)&" kg setelah order","-")))) -> CEK HARGA: order 43,086/kg di bawah biaya stok 47,199/kg
A33: BLPK|Frozen | B33: =IFERROR(INDEX(O_Stok!$S$6:$S$85,MATCH("Trading|BLPK|Frozen",O_Stok!$A$6:$A$85,0)),0) -> 8.53 | C33: =IFERROR(INDEX(O_Stok!$T$6:$T$85,MATCH("Trading|BLPK|Frozen",O_Stok!$A$6:$A$85,0)),0) -> 0 | D33: =SUMIFS(T_Penerimaan!$I$6:$I$1005,T_Penerimaan!$H$6:$H$1005,"Trading|BLPK|Frozen",T_Penerimaan!$B$6:$B$1005,"Rencana",T_Penerimaan!$A$6:$A$1005,">="&I_Parameter!$C$4,T_Penerimaan!$A$6:$A$1005,"<="&I_Parameter!$C$6) -> 0 | E33: =MAX(0,C33-B33-D33) -> 0 | F33: =IFERROR(SUMIFS(T_Penjualan!$J$6:$J$1505,T_Penjualan!$G$6:$G$1505,"Trading|BLPK|Frozen",T_Penjualan!$B$6:$B$1505,"Order",T_Penjualan!$A$6:$A$1505,">="&I_Parameter!$C$4)/SUMIFS(T_Penjualan!$H$6:$H$1505,T_Penjualan!$G$6:$G$1505,"Trading|BLPK|Frozen",T_Penjualan!$B$6:$B$1505,"Order",T_Penjualan!$A$6:$A$1505,">="&I_Parameter!$C$4),IFERROR(INDEX(I_Master!$F$6:$F$85,MATCH("Trading|BLPK|Frozen",I_Master!$A$6:$A$85,0)),0)) -> 34000 | G33: =IFERROR(INDEX(I_Master!$G$6:$G$85,MATCH("Trading|BLPK|Frozen",I_Master!$A$6:$A$85,0)),"") -> 0 | H33: =IF(OR(G33="",G33=0,F33=0),"",F33-G33) | I33: =IF(H33="","",H33/F33) | J33: =IFERROR(INDEX(O_Stok!$Q$6:$Q$85,MATCH("Trading|BLPK|Frozen",O_Stok!$A$6:$A$85,0)),0) -> 32000 | K33: =IF(E33>0.5,IF(H33="","BELI "&FIXED(E33,0)&" kg — isi harga beli pengganti",IF(H33>=I_Parameter!$C$12,"BELI "&FIXED(E33,0)&" kg (spread "&FIXED(H33,0)&"/kg)","TAHAN: spread "&FIXED(H33,0)&"/kg di bawah minimum — naikkan harga jual atau cari pemasok")),IF(AND(B33>0.5,C33<=0.5),"JUAL STOK: "&FIXED(B33,0)&" kg tanpa order",IF(AND(C33>0.5,J33>0,F33<J33),"CEK HARGA: order "&FIXED(F33,0)&"/kg di bawah biaya stok "&FIXED(J33,0)&"/kg",IF(B33>0.5,"Cukup — sisa "&FIXED(B33-C33+D33,0)&" kg setelah order","-")))) -> JUAL STOK: 9 kg tanpa order
A34: HJA (Hati/Jantung/Ampela)|n/a | B34: =IFERROR(INDEX(O_Stok!$S$6:$S$85,MATCH("Trading|HJA (Hati/Jantung/Ampela)|n/a",O_Stok!$A$6:$A$85,0)),0) -> 4300.37 | C34: =IFERROR(INDEX(O_Stok!$T$6:$T$85,MATCH("Trading|HJA (Hati/Jantung/Ampela)|n/a",O_Stok!$A$6:$A$85,0)),0) -> 0 | D34: =SUMIFS(T_Penerimaan!$I$6:$I$1005,T_Penerimaan!$H$6:$H$1005,"Trading|HJA (Hati/Jantung/Ampela)|n/a",T_Penerimaan!$B$6:$B$1005,"Rencana",T_Penerimaan!$A$6:$A$1005,">="&I_Parameter!$C$4,T_Penerimaan!$A$6:$A$1005,"<="&I_Parameter!$C$6) -> 0 | E34: =MAX(0,C34-B34-D34) -> 0 | F34: =IFERROR(SUMIFS(T_Penjualan!$J$6:$J$1505,T_Penjualan!$G$6:$G$1505,"Trading|HJA (Hati/Jantung/Ampela)|n/a",T_Penjualan!$B$6:$B$1505,"Order",T_Penjualan!$A$6:$A$1505,">="&I_Parameter!$C$4)/SUMIFS(T_Penjualan!$H$6:$H$1505,T_Penjualan!$G$6:$G$1505,"Trading|HJA (Hati/Jantung/Ampela)|n/a",T_Penjualan!$B$6:$B$1505,"Order",T_Penjualan!$A$6:$A$1505,">="&I_Parameter!$C$4),IFERROR(INDEX(I_Master!$F$6:$F$85,MATCH("Trading|HJA (Hati/Jantung/Ampela)|n/a",I_Master!$A$6:$A$85,0)),0)) -> 15500 | G34: =IFERROR(INDEX(I_Master!$G$6:$G$85,MATCH("Trading|HJA (Hati/Jantung/Ampela)|n/a",I_Master!$A$6:$A$85,0)),"") -> 0 | H34: =IF(OR(G34="",G34=0,F34=0),"",F34-G34) | I34: =IF(H34="","",H34/F34) | J34: =IFERROR(INDEX(O_Stok!$Q$6:$Q$85,MATCH("Trading|HJA (Hati/Jantung/Ampela)|n/a",O_Stok!$A$6:$A$85,0)),0) -> 4860.4618 | K34: =IF(E34>0.5,IF(H34="","BELI "&FIXED(E34,0)&" kg — isi harga beli pengganti",IF(H34>=I_Parameter!$C$12,"BELI "&FIXED(E34,0)&" kg (spread "&FIXED(H34,0)&"/kg)","TAHAN: spread "&FIXED(H34,0)&"/kg di bawah minimum — naikkan harga jual atau cari pemasok")),IF(AND(B34>0.5,C34<=0.5),"JUAL STOK: "&FIXED(B34,0)&" kg tanpa order",IF(AND(C34>0.5,J34>0,F34<J34),"CEK HARGA: order "&FIXED(F34,0)&"/kg di bawah biaya stok "&FIXED(J34,0)&"/kg",IF(B34>0.5,"Cukup — sisa "&FIXED(B34-C34+D34,0)&" kg setelah order","-")))) -> JUAL STOK: 4,300 kg tanpa order
A35: KRK (Kerangka)|n/a | B35: =IFERROR(INDEX(O_Stok!$S$6:$S$85,MATCH("Trading|KRK (Kerangka)|n/a",O_Stok!$A$6:$A$85,0)),0) -> 25815.44 | C35: =IFERROR(INDEX(O_Stok!$T$6:$T$85,MATCH("Trading|KRK (Kerangka)|n/a",O_Stok!$A$6:$A$85,0)),0) -> 6011.3 | D35: =SUMIFS(T_Penerimaan!$I$6:$I$1005,T_Penerimaan!$H$6:$H$1005,"Trading|KRK (Kerangka)|n/a",T_Penerimaan!$B$6:$B$1005,"Rencana",T_Penerimaan!$A$6:$A$1005,">="&I_Parameter!$C$4,T_Penerimaan!$A$6:$A$1005,"<="&I_Parameter!$C$6) -> 0 | E35: =MAX(0,C35-B35-D35) -> 0 | F35: =IFERROR(SUMIFS(T_Penjualan!$J$6:$J$1505,T_Penjualan!$G$6:$G$1505,"Trading|KRK (Kerangka)|n/a",T_Penjualan!$B$6:$B$1505,"Order",T_Penjualan!$A$6:$A$1505,">="&I_Parameter!$C$4)/SUMIFS(T_Penjualan!$H$6:$H$1505,T_Penjualan!$G$6:$G$1505,"Trading|KRK (Kerangka)|n/a",T_Penjualan!$B$6:$B$1505,"Order",T_Penjualan!$A$6:$A$1505,">="&I_Parameter!$C$4),IFERROR(INDEX(I_Master!$F$6:$F$85,MATCH("Trading|KRK (Kerangka)|n/a",I_Master!$A$6:$A$85,0)),0)) -> 10903 | G35: =IFERROR(INDEX(I_Master!$G$6:$G$85,MATCH("Trading|KRK (Kerangka)|n/a",I_Master!$A$6:$A$85,0)),"") -> 11169 | H35: =IF(OR(G35="",G35=0,F35=0),"",F35-G35) -> -266 | I35: =IF(H35="","",H35/F35) -> -0.024396955 | J35: =IFERROR(INDEX(O_Stok!$Q$6:$Q$85,MATCH("Trading|KRK (Kerangka)|n/a",O_Stok!$A$6:$A$85,0)),0) -> 10310.872 | K35: =IF(E35>0.5,IF(H35="","BELI "&FIXED(E35,0)&" kg — isi harga beli pengganti",IF(H35>=I_Parameter!$C$12,"BELI "&FIXED(E35,0)&" kg (spread "&FIXED(H35,0)&"/kg)","TAHAN: spread "&FIXED(H35,0)&"/kg di bawah minimum — naikkan harga jual atau cari pemasok")),IF(AND(B35>0.5,C35<=0.5),"JUAL STOK: "&FIXED(B35,0)&" kg tanpa order",IF(AND(C35>0.5,J35>0,F35<J35),"CEK HARGA: order "&FIXED(F35,0)&"/kg di bawah biaya stok "&FIXED(J35,0)&"/kg",IF(B35>0.5,"Cukup — sisa "&FIXED(B35-C35+D35,0)&" kg setelah order","-")))) -> Cukup — sisa 19,804 kg setelah order
A36: Karkas|n/a | B36: =IFERROR(INDEX(O_Stok!$S$6:$S$85,MATCH("Trading|Karkas|n/a",O_Stok!$A$6:$A$85,0)),0) -> 46572.5 | C36: =IFERROR(INDEX(O_Stok!$T$6:$T$85,MATCH("Trading|Karkas|n/a",O_Stok!$A$6:$A$85,0)),0) -> 7007.77 | D36: =SUMIFS(T_Penerimaan!$I$6:$I$1005,T_Penerimaan!$H$6:$H$1005,"Trading|Karkas|n/a",T_Penerimaan!$B$6:$B$1005,"Rencana",T_Penerimaan!$A$6:$A$1005,">="&I_Parameter!$C$4,T_Penerimaan!$A$6:$A$1005,"<="&I_Parameter!$C$6) -> 0 | E36: =MAX(0,C36-B36-D36) -> 0 | F36: =IFERROR(SUMIFS(T_Penjualan!$J$6:$J$1505,T_Penjualan!$G$6:$G$1505,"Trading|Karkas|n/a",T_Penjualan!$B$6:$B$1505,"Order",T_Penjualan!$A$6:$A$1505,">="&I_Parameter!$C$4)/SUMIFS(T_Penjualan!$H$6:$H$1505,T_Penjualan!$G$6:$G$1505,"Trading|Karkas|n/a",T_Penjualan!$B$6:$B$1505,"Order",T_Penjualan!$A$6:$A$1505,">="&I_Parameter!$C$4),IFERROR(INDEX(I_Master!$F$6:$F$85,MATCH("Trading|Karkas|n/a",I_Master!$A$6:$A$85,0)),0)) -> 31277 | G36: =IFERROR(INDEX(I_Master!$G$6:$G$85,MATCH("Trading|Karkas|n/a",I_Master!$A$6:$A$85,0)),"") -> 30050 | H36: =IF(OR(G36="",G36=0,F36=0),"",F36-G36) -> 1227 | I36: =IF(H36="","",H36/F36) -> 0.039230105 | J36: =IFERROR(INDEX(O_Stok!$Q$6:$Q$85,MATCH("Trading|Karkas|n/a",O_Stok!$A$6:$A$85,0)),0) -> 30065.464 | K36: =IF(E36>0.5,IF(H36="","BELI "&FIXED(E36,0)&" kg — isi harga beli pengganti",IF(H36>=I_Parameter!$C$12,"BELI "&FIXED(E36,0)&" kg (spread "&FIXED(H36,0)&"/kg)","TAHAN: spread "&FIXED(H36,0)&"/kg di bawah minimum — naikkan harga jual atau cari pemasok")),IF(AND(B36>0.5,C36<=0.5),"JUAL STOK: "&FIXED(B36,0)&" kg tanpa order",IF(AND(C36>0.5,J36>0,F36<J36),"CEK HARGA: order "&FIXED(F36,0)&"/kg di bawah biaya stok "&FIXED(J36,0)&"/kg",IF(B36>0.5,"Cukup — sisa "&FIXED(B36-C36+D36,0)&" kg setelah order","-")))) -> Cukup — sisa 39,565 kg setelah order
A37: Kulit|Frozen | B37: =IFERROR(INDEX(O_Stok!$S$6:$S$85,MATCH("Trading|Kulit|Frozen",O_Stok!$A$6:$A$85,0)),0) -> 4067.31 | C37: =IFERROR(INDEX(O_Stok!$T$6:$T$85,MATCH("Trading|Kulit|Frozen",O_Stok!$A$6:$A$85,0)),0) -> 105.37 | D37: =SUMIFS(T_Penerimaan!$I$6:$I$1005,T_Penerimaan!$H$6:$H$1005,"Trading|Kulit|Frozen",T_Penerimaan!$B$6:$B$1005,"Rencana",T_Penerimaan!$A$6:$A$1005,">="&I_Parameter!$C$4,T_Penerimaan!$A$6:$A$1005,"<="&I_Parameter!$C$6) -> 0 | E37: =MAX(0,C37-B37-D37) -> 0 | F37: =IFERROR(SUMIFS(T_Penjualan!$J$6:$J$1505,T_Penjualan!$G$6:$G$1505,"Trading|Kulit|Frozen",T_Penjualan!$B$6:$B$1505,"Order",T_Penjualan!$A$6:$A$1505,">="&I_Parameter!$C$4)/SUMIFS(T_Penjualan!$H$6:$H$1505,T_Penjualan!$G$6:$G$1505,"Trading|Kulit|Frozen",T_Penjualan!$B$6:$B$1505,"Order",T_Penjualan!$A$6:$A$1505,">="&I_Parameter!$C$4),IFERROR(INDEX(I_Master!$F$6:$F$85,MATCH("Trading|Kulit|Frozen",I_Master!$A$6:$A$85,0)),0)) -> 29000 | G37: =IFERROR(INDEX(I_Master!$G$6:$G$85,MATCH("Trading|Kulit|Frozen",I_Master!$A$6:$A$85,0)),"") -> 29577 | H37: =IF(OR(G37="",G37=0,F37=0),"",F37-G37) -> -577 | I37: =IF(H37="","",H37/F37) -> -0.019896552 | J37: =IFERROR(INDEX(O_Stok!$Q$6:$Q$85,MATCH("Trading|Kulit|Frozen",O_Stok!$A$6:$A$85,0)),0) -> 26380.955 | K37: =IF(E37>0.5,IF(H37="","BELI "&FIXED(E37,0)&" kg — isi harga beli pengganti",IF(H37>=I_Parameter!$C$12,"BELI "&FIXED(E37,0)&" kg (spread "&FIXED(H37,0)&"/kg)","TAHAN: spread "&FIXED(H37,0)&"/kg di bawah minimum — naikkan harga jual atau cari pemasok")),IF(AND(B37>0.5,C37<=0.5),"JUAL STOK: "&FIXED(B37,0)&" kg tanpa order",IF(AND(C37>0.5,J37>0,F37<J37),"CEK HARGA: order "&FIXED(F37,0)&"/kg di bawah biaya stok "&FIXED(J37,0)&"/kg",IF(B37>0.5,"Cukup — sisa "&FIXED(B37-C37+D37,0)&" kg setelah order","-")))) -> Cukup — sisa 3,962 kg setelah order
A38: Kulit|n/a | B38: =IFERROR(INDEX(O_Stok!$S$6:$S$85,MATCH("Trading|Kulit|n/a",O_Stok!$A$6:$A$85,0)),0) -> 1395.69 | C38: =IFERROR(INDEX(O_Stok!$T$6:$T$85,MATCH("Trading|Kulit|n/a",O_Stok!$A$6:$A$85,0)),0) -> 0 | D38: =SUMIFS(T_Penerimaan!$I$6:$I$1005,T_Penerimaan!$H$6:$H$1005,"Trading|Kulit|n/a",T_Penerimaan!$B$6:$B$1005,"Rencana",T_Penerimaan!$A$6:$A$1005,">="&I_Parameter!$C$4,T_Penerimaan!$A$6:$A$1005,"<="&I_Parameter!$C$6) -> 0 | E38: =MAX(0,C38-B38-D38) -> 0 | F38: =IFERROR(SUMIFS(T_Penjualan!$J$6:$J$1505,T_Penjualan!$G$6:$G$1505,"Trading|Kulit|n/a",T_Penjualan!$B$6:$B$1505,"Order",T_Penjualan!$A$6:$A$1505,">="&I_Parameter!$C$4)/SUMIFS(T_Penjualan!$H$6:$H$1505,T_Penjualan!$G$6:$G$1505,"Trading|Kulit|n/a",T_Penjualan!$B$6:$B$1505,"Order",T_Penjualan!$A$6:$A$1505,">="&I_Parameter!$C$4),IFERROR(INDEX(I_Master!$F$6:$F$85,MATCH("Trading|Kulit|n/a",I_Master!$A$6:$A$85,0)),0)) -> 26261 | G38: =IFERROR(INDEX(I_Master!$G$6:$G$85,MATCH("Trading|Kulit|n/a",I_Master!$A$6:$A$85,0)),"") -> 0 | H38: =IF(OR(G38="",G38=0,F38=0),"",F38-G38) | I38: =IF(H38="","",H38/F38) | J38: =IFERROR(INDEX(O_Stok!$Q$6:$Q$85,MATCH("Trading|Kulit|n/a",O_Stok!$A$6:$A$85,0)),0) -> 21000 | K38: =IF(E38>0.5,IF(H38="","BELI "&FIXED(E38,0)&" kg — isi harga beli pengganti",IF(H38>=I_Parameter!$C$12,"BELI "&FIXED(E38,0)&" kg (spread "&FIXED(H38,0)&"/kg)","TAHAN: spread "&FIXED(H38,0)&"/kg di bawah minimum — naikkan harga jual atau cari pemasok")),IF(AND(B38>0.5,C38<=0.5),"JUAL STOK: "&FIXED(B38,0)&" kg tanpa order",IF(AND(C38>0.5,J38>0,F38<J38),"CEK HARGA: order "&FIXED(F38,0)&"/kg di bawah biaya stok "&FIXED(J38,0)&"/kg",IF(B38>0.5,"Cukup — sisa "&FIXED(B38-C38+D38,0)&" kg setelah order","-")))) -> JUAL STOK: 1,396 kg tanpa order
A39: Sayap|n/a | B39: =IFERROR(INDEX(O_Stok!$S$6:$S$85,MATCH("Trading|Sayap|n/a",O_Stok!$A$6:$A$85,0)),0) -> 0 | C39: =IFERROR(INDEX(O_Stok!$T$6:$T$85,MATCH("Trading|Sayap|n/a",O_Stok!$A$6:$A$85,0)),0) -> 300 | D39: =SUMIFS(T_Penerimaan!$I$6:$I$1005,T_Penerimaan!$H$6:$H$1005,"Trading|Sayap|n/a",T_Penerimaan!$B$6:$B$1005,"Rencana",T_Penerimaan!$A$6:$A$1005,">="&I_Parameter!$C$4,T_Penerimaan!$A$6:$A$1005,"<="&I_Parameter!$C$6) -> 6985 | E39: =MAX(0,C39-B39-D39) -> 0 | F39: =IFERROR(SUMIFS(T_Penjualan!$J$6:$J$1505,T_Penjualan!$G$6:$G$1505,"Trading|Sayap|n/a",T_Penjualan!$B$6:$B$1505,"Order",T_Penjualan!$A$6:$A$1505,">="&I_Parameter!$C$4)/SUMIFS(T_Penjualan!$H$6:$H$1505,T_Penjualan!$G$6:$G$1505,"Trading|Sayap|n/a",T_Penjualan!$B$6:$B$1505,"Order",T_Penjualan!$A$6:$A$1505,">="&I_Parameter!$C$4),IFERROR(INDEX(I_Master!$F$6:$F$85,MATCH("Trading|Sayap|n/a",I_Master!$A$6:$A$85,0)),0)) -> 31000 | G39: =IFERROR(INDEX(I_Master!$G$6:$G$85,MATCH("Trading|Sayap|n/a",I_Master!$A$6:$A$85,0)),"") -> 0 | H39: =IF(OR(G39="",G39=0,F39=0),"",F39-G39) | I39: =IF(H39="","",H39/F39) | J39: =IFERROR(INDEX(O_Stok!$Q$6:$Q$85,MATCH("Trading|Sayap|n/a",O_Stok!$A$6:$A$85,0)),0) -> 28632.78 | K39: =IF(E39>0.5,IF(H39="","BELI "&FIXED(E39,0)&" kg — isi harga beli pengganti",IF(H39>=I_Parameter!$C$12,"BELI "&FIXED(E39,0)&" kg (spread "&FIXED(H39,0)&"/kg)","TAHAN: spread "&FIXED(H39,0)&"/kg di bawah minimum — naikkan harga jual atau cari pemasok")),IF(AND(B39>0.5,C39<=0.5),"JUAL STOK: "&FIXED(B39,0)&" kg tanpa order",IF(AND(C39>0.5,J39>0,F39<J39),"CEK HARGA: order "&FIXED(F39,0)&"/kg di bawah biaya stok "&FIXED(J39,0)&"/kg",IF(B39>0.5,"Cukup — sisa "&FIXED(B39-C39+D39,0)&" kg setelah order","-")))) -> -
A40: Usus|Fresh | B40: =IFERROR(INDEX(O_Stok!$S$6:$S$85,MATCH("Trading|Usus|Fresh",O_Stok!$A$6:$A$85,0)),0) -> 0 | C40: =IFERROR(INDEX(O_Stok!$T$6:$T$85,MATCH("Trading|Usus|Fresh",O_Stok!$A$6:$A$85,0)),0) -> 0 | D40: =SUMIFS(T_Penerimaan!$I$6:$I$1005,T_Penerimaan!$H$6:$H$1005,"Trading|Usus|Fresh",T_Penerimaan!$B$6:$B$1005,"Rencana",T_Penerimaan!$A$6:$A$1005,">="&I_Parameter!$C$4,T_Penerimaan!$A$6:$A$1005,"<="&I_Parameter!$C$6) -> 0 | E40: =MAX(0,C40-B40-D40) -> 0 | F40: =IFERROR(SUMIFS(T_Penjualan!$J$6:$J$1505,T_Penjualan!$G$6:$G$1505,"Trading|Usus|Fresh",T_Penjualan!$B$6:$B$1505,"Order",T_Penjualan!$A$6:$A$1505,">="&I_Parameter!$C$4)/SUMIFS(T_Penjualan!$H$6:$H$1505,T_Penjualan!$G$6:$G$1505,"Trading|Usus|Fresh",T_Penjualan!$B$6:$B$1505,"Order",T_Penjualan!$A$6:$A$1505,">="&I_Parameter!$C$4),IFERROR(INDEX(I_Master!$F$6:$F$85,MATCH("Trading|Usus|Fresh",I_Master!$A$6:$A$85,0)),0)) -> 14000 | G40: =IFERROR(INDEX(I_Master!$G$6:$G$85,MATCH("Trading|Usus|Fresh",I_Master!$A$6:$A$85,0)),"") -> 0 | H40: =IF(OR(G40="",G40=0,F40=0),"",F40-G40) | I40: =IF(H40="","",H40/F40) | J40: =IFERROR(INDEX(O_Stok!$Q$6:$Q$85,MATCH("Trading|Usus|Fresh",O_Stok!$A$6:$A$85,0)),0) -> 0 | K40: =IF(E40>0.5,IF(H40="","BELI "&FIXED(E40,0)&" kg — isi harga beli pengganti",IF(H40>=I_Parameter!$C$12,"BELI "&FIXED(E40,0)&" kg (spread "&FIXED(H40,0)&"/kg)","TAHAN: spread "&FIXED(H40,0)&"/kg di bawah minimum — naikkan harga jual atau cari pemasok")),IF(AND(B40>0.5,C40<=0.5),"JUAL STOK: "&FIXED(B40,0)&" kg tanpa order",IF(AND(C40>0.5,J40>0,F40<J40),"CEK HARGA: order "&FIXED(F40,0)&"/kg di bawah biaya stok "&FIXED(J40,0)&"/kg",IF(B40>0.5,"Cukup — sisa "&FIXED(B40-C40+D40,0)&" kg setelah order","-")))) -> -
A42: 4. STOK — yang harus dijual / dibeli (detail per SKU di sheet O_Stok kolom Z)
A43: Status | B43: Jumlah SKU | C43: kg hari ini | D43: Nilai Rp
A44: KURANG (stok minus di minggu ini) | B44: =COUNTIF(O_Stok!$Z$6:$Z$85,"KURANG*") -> 0 | C44: =SUMIFS(O_Stok!$S$6:$S$85,O_Stok!$Z$6:$Z$85,"KURANG*") -> 0 | D44: =SUMIFS(O_Stok!$Y$6:$Y$85,O_Stok!$Z$6:$Z$85,"KURANG*") -> 0
...

Sheet O_PnL
A1: LABA RUGI MINGGUAN (format P&L deck) — Rp
A2: Aktual = jurnal Accurate (T_GL). Sisa minggu = order × harga (revenue), order × biaya rata-rata stok (COGS), run-rate untuk biaya lain. Biaya ditampilkan negatif.
A5: Baris | B5: Minggu lalu (aktual) | C5: Minggu ini aktual s.d. kemarin | D5: Sisa minggu (outlook) | E5: Proyeksi minggu ini | F5: Δ vs minggu lalu | G5: Bulan berjalan aktual (MTD) | H5: MTD + sisa minggu | I5: Basis sisa minggu
A6: Revenue - LB Main Product | B6: =-SUMIFS(T_GL!$J$6:$J$4005,T_GL!$L$6:$L$4005,"Revenue - LB Main Product",T_GL!$A$6:$A$4005,">="&(I_Parameter!$C$5-7),T_GL!$A$6:$A$4005,"<="&(I_Parameter!$C$5-1)) -> 687779970 | C6: =-SUMIFS(T_GL!$J$6:$J$4005,T_GL!$L$6:$L$4005,"Revenue - LB Main Product",T_GL!$A$6:$A$4005,">="&I_Parameter!$C$5,T_GL!$A$6:$A$4005,"<="&(I_Parameter!$C$4-1)) -> 342934170 | D6: =SUMIFS(T_Penjualan!$J$6:$J$1505,T_Penjualan!$N$6:$N$1505,"RPA",T_Penjualan!$O$6:$O$1505,"<>By-product",T_Penjualan!$B$6:$B$1505,"Order",T_Penjualan!$P$6:$P$1505,1) -> 6.0992013e+08 | E6: =C6+D6 -> 9.528543e+08 | F6: =E6-B6 -> 2.6507433e+08 | G6: =-SUMIFS(T_GL!$J$6:$J$4005,T_GL!$L$6:$L$4005,"Revenue - LB Main Product",T_GL!$A$6:$A$4005,">="&DATE(YEAR(I_Parameter!$C$4),MONTH(I_Parameter!$C$4),1),T_GL!$A$6:$A$4005,"<="&(I_Parameter!$C$4-1)) -> 1808448555 | H6: =G6+D6 -> 2.4183687e+09 | I6: order RPA (non by-product) × harga
A7: Revenue - LB By Product | B7: =-SUMIFS(T_GL!$J$6:$J$4005,T_GL!$L$6:$L$4005,"Revenue - LB By Product",T_GL!$A$6:$A$4005,">="&(I_Parameter!$C$5-7),T_GL!$A$6:$A$4005,"<="&(I_Parameter!$C$5-1)) -> 22934700 | C7: =-SUMIFS(T_GL!$J$6:$J$4005,T_GL!$L$6:$L$4005,"Revenue - LB By Product",T_GL!$A$6:$A$4005,">="&I_Parameter!$C$5,T_GL!$A$6:$A$4005,"<="&(I_Parameter!$C$4-1)) -> 6237550 | D7: =SUMIFS(T_Penjualan!$J$6:$J$1505,T_Penjualan!$N$6:$N$1505,"RPA",T_Penjualan!$O$6:$O$1505,"By-product",T_Penjualan!$B$6:$B$1505,"Order",T_Penjualan!$P$6:$P$1505,1) -> 21693061 | E7: =C7+D7 -> 27930611 | F7: =E7-B7 -> 4995910.9 | G7: =-SUMIFS(T_GL!$J$6:$J$4005,T_GL!$L$6:$L$4005,"Revenue - LB By Product",T_GL!$A$6:$A$4005,">="&DATE(YEAR(I_Parameter!$C$4),MONTH(I_Parameter!$C$4),1),T_GL!$A$6:$A$4005,"<="&(I_Parameter!$C$4-1)) -> 44484650 | H7: =G7+D7 -> 66177711 | I7: order by-product × harga
A8: Revenue - Trading | B8: =-SUMIFS(T_GL!$J$6:$J$4005,T_GL!$L$6:$L$4005,"Revenue - Trading",T_GL!$A$6:$A$4005,">="&(I_Parameter!$C$5-7),T_GL!$A$6:$A$4005,"<="&(I_Parameter!$C$5-1)) -> 861591700 | C8: =-SUMIFS(T_GL!$J$6:$J$4005,T_GL!$L$6:$L$4005,"Revenue - Trading",T_GL!$A$6:$A$4005,">="&I_Parameter!$C$5,T_GL!$A$6:$A$4005,"<="&(I_Parameter!$C$4-1)) -> 239801150 | D8: =SUMIFS(T_Penjualan!$J$6:$J$1505,T_Penjualan!$N$6:$N$1505,"Trading",T_Penjualan!$B$6:$B$1505,"Order",T_Penjualan!$P$6:$P$1505,1) -> 4.3621227e+08 | E8: =C8+D8 -> 6.7601342e+08 | F8: =E8-B8 -> -1.8557828e+08 | G8: =-SUMIFS(T_GL!$J$6:$J$4005,T_GL!$L$6:$L$4005,"Revenue - Trading",T_GL!$A$6:$A$4005,">="&DATE(YEAR(I_Parameter!$C$4),MONTH(I_Parameter!$C$4),1),T_GL!$A$6:$A$4005,"<="&(I_Parameter!$C$4-1)) -> 4532942834 | H8: =G8+D8 -> 4.9691551e+09 | I8: order Trading × harga
A9: TOTAL REVENUE | B9: =SUM(B6:B8) -> 1572306370 | C9: =SUM(C6:C8) -> 588972870 | D9: =SUM(D6:D8) -> 1.0678255e+09 | E9: =SUM(E6:E8) -> 1.6567983e+09 | F9: =SUM(F6:F8) -> 84491960 | G9: =SUM(G6:G8) -> 6385876039 | H9: =SUM(H6:H8) -> 7.4537015e+09
A10: COGS - Live Bird | B10: =-SUMIFS(T_GL!$J$6:$J$4005,T_GL!$L$6:$L$4005,"COGS - Live Bird",T_GL!$A$6:$A$4005,">="&(I_Parameter!$C$5-7),T_GL!$A$6:$A$4005,"<="&(I_Parameter!$C$5-1)) -> -7.1068474e+08 | C10: =-SUMIFS(T_GL!$J$6:$J$4005,T_GL!$L$6:$L$4005,"COGS - Live Bird",T_GL!$A$6:$A$4005,">="&I_Parameter!$C$5,T_GL!$A$6:$A$4005,"<="&(I_Parameter!$C$4-1)) -> -3.5421495e+08 | D10: =-SUMIFS(T_Penjualan!$L$6:$L$1505,T_Penjualan!$N$6:$N$1505,"RPA",T_Penjualan!$B$6:$B$1505,"Order",T_Penjualan!$P$6:$P$1505,1) -> -6.8390599e+08 | E10: =C10+D10 -> -1.0381209e+09 | F10: =E10-B10 -> -3.2743621e+08 | G10: =-SUMIFS(T_GL!$J$6:$J$4005,T_GL!$L$6:$L$4005,"COGS - Live Bird",T_GL!$A$6:$A$4005,">="&DATE(YEAR(I_Parameter!$C$4),MONTH(I_Parameter!$C$4),1),T_GL!$A$6:$A$4005,"<="&(I_Parameter!$C$4-1)) -> -1.8551981e+09 | H10: =G10+D10 -> -2.5391041e+09 | I10: order × biaya rata-rata stok RPA
A11: COGS - Trading | B11: =-SUMIFS(T_GL!$J$6:$J$4005,T_GL!$L$6:$L$4005,"COGS - Trading",T_GL!$A$6:$A$4005,">="&(I_Parameter!$C$5-7),T_GL!$A$6:$A$4005,"<="&(I_Parameter!$C$5-1)) -> -8.2594611e+08 | C11: =-SUMIFS(T_GL!$J$6:$J$4005,T_GL!$L$6:$L$4005,"COGS - Trading",T_GL!$A$6:$A$4005,">="&I_Parameter!$C$5,T_GL!$A$6:$A$4005,"<="&(I_Parameter!$C$4-1)) -> -2.1278991e+08 | D11: =-SUMIFS(T_Penjualan!$L$6:$L$1505,T_Penjualan!$N$6:$N$1505,"Trading",T_Penjualan!$B$6:$B$1505,"Order",T_Penjualan!$P$6:$P$1505,1) -> -4.3645682e+08 | E11: =C11+D11 -> -6.4924674e+08 | F11: =E11-B11 -> 1.7669937e+08 | G11: =-SUMIFS(T_GL!$J$6:$J$4005,T_GL!$L$6:$L$4005,"COGS - Trading",T_GL!$A$6:$A$4005,">="&DATE(YEAR(I_Parameter!$C$4),MONTH(I_Parameter!$C$4),1),T_GL!$A$6:$A$4005,"<="&(I_Parameter!$C$4-1)) -> -4.083272e+09 | H11: =G11+D11 -> -4.5197288e+09 | I11: order × biaya rata-rata stok Trading
A12: Other COGS - Expedition | B12: =-SUMIFS(T_GL!$J$6:$J$4005,T_GL!$L$6:$L$4005,"Other COGS - Expedition",T_GL!$A$6:$A$4005,">="&(I_Parameter!$C$5-7),T_GL!$A$6:$A$4005,"<="&(I_Parameter!$C$5-1)) -> -29000000 | C12: =-SUMIFS(T_GL!$J$6:$J$4005,T_GL!$L$6:$L$4005,"Other COGS - Expedition",T_GL!$A$6:$A$4005,">="&I_Parameter!$C$5,T_GL!$A$6:$A$4005,"<="&(I_Parameter!$C$4-1)) -> -17000000 | D12: =-(I_RunRate!$B$6*((I_Parameter!$C$6-I_Parameter!$C$4+1)/DAY(EOMONTH(I_Parameter!$C$4,0)))+I_RunRate!$C$6) -> -3592975.2 | E12: =C12+D12 -> -20592975 | F12: =E12-B12 -> 8407024.8 | G12: =-SUMIFS(T_GL!$J$6:$J$4005,T_GL!$L$6:$L$4005,"Other COGS - Expedition",T_GL!$A$6:$A$4005,">="&DATE(YEAR(I_Parameter!$C$4),MONTH(I_Parameter!$C$4),1),T_GL!$A$6:$A$4005,"<="&(I_Parameter!$C$4-1)) -> -76800000 | H12: =G12+D12 -> -80392975 | I12: run-rate (I_RunRate)
A13: COGS - Blasting | B13: =-SUMIFS(T_GL!$J$6:$J$4005,T_GL!$L$6:$L$4005,"COGS - Blasting",T_GL!$A$6:$A$4005,">="&(I_Parameter!$C$5-7),T_GL!$A$6:$A$4005,"<="&(I_Parameter!$C$5-1)) -> -10858005 | C13: =-SUMIFS(T_GL!$J$6:$J$4005,T_GL!$L$6:$L$4005,"COGS - Blasting",T_GL!$A$6:$A$4005,">="&I_Parameter!$C$5,T_GL!$A$6:$A$4005,"<="&(I_Parameter!$C$4-1)) -> -4525920 | D13: =-(I_RunRate!$B$7*((I_Parameter!$C$6-I_Parameter!$C$4+1)/DAY(EOMONTH(I_Parameter!$C$4,0)))+I_RunRate!$C$7) -> -11839861 | E13: =C13+D13 -> -16365781 | F13: =E13-B13 -> -5507775.6 | G13: =-SUMIFS(T_GL!$J$6:$J$4005,T_GL!$L$6:$L$4005,"COGS - Blasting",T_GL!$A$6:$A$4005,">="&DATE(YEAR(I_Parameter!$C$4),MONTH(I_Parameter!$C$4),1),T_GL!$A$6:$A$4005,"<="&(I_Parameter!$C$4-1)) -> -23202730 | H13: =G13+D13 -> -35042591 | I13: run-rate (I_RunRate)
A14: TOTAL COST OF SALES | B14: =SUM(B10:B13) -> -1.5764889e+09 | C14: =SUM(C10:C13) -> -5.8853079e+08 | D14: =SUM(D10:D13) -> -1.1357957e+09 | E14: =SUM(E10:E13) -> -1.7243264e+09 | F14: =SUM(F10:F13) -> -1.4783759e+08 | G14: =SUM(G10:G13) -> -6.0384728e+09 | H14: =SUM(H10:H13) -> -7.1742684e+09
A15: GROSS PROFIT | B15: =B9+B14 -> -4182480.4 | C15: =C9+C14 -> 442084.15 | D15: =D9+D14 -> -67970193 | E15: =E9+E14 -> -67528109 | F15: =F9+F14 -> -63345629 | G15: =G9+G14 -> 3.4740325e+08 | H15: =H9+H14 -> 2.7943306e+08
A16: GP margin | B16: =IF(B9=0,0,B15/B9) -> -0.0026600925 | C16: =IF(C9=0,0,C15/C9) -> 0.00075060189 | D16: =IF(D9=0,0,D15/D9) -> -0.063652906 | E16: =IF(E9=0,0,E15/E9) -> -0.040758195 | F16: =IF(F9=0,0,F15/F9) -> -0.74972374 | G16: =IF(G9=0,0,G15/G9) -> 0.054401816 | H16: =IF(H9=0,0,H15/H9) -> 0.037489167
A17: Delivery Expenses | B17: =-SUMIFS(T_GL!$J$6:$J$4005,T_GL!$L$6:$L$4005,"Delivery Expenses",T_GL!$A$6:$A$4005,">="&(I_Parameter!$C$5-7),T_GL!$A$6:$A$4005,"<="&(I_Parameter!$C$5-1)) -> -10976006 | C17: =-SUMIFS(T_GL!$J$6:$J$4005,T_GL!$L$6:$L$4005,"Delivery Expenses",T_GL!$A$6:$A$4005,">="&I_Parameter!$C$5,T_GL!$A$6:$A$4005,"<="&(I_Parameter!$C$4-1)) -> -1400000 | D17: =-(I_RunRate!$B$8*((I_Parameter!$C$6-I_Parameter!$C$4+1)/DAY(EOMONTH(I_Parameter!$C$4,0)))+I_RunRate!$C$8) -> -1987096.8 | E17: =C17+D17 -> -3387096.8 | F17: =E17-B17 -> 7588909.2 | G17: =-SUMIFS(T_GL!$J$6:$J$4005,T_GL!$L$6:$L$4005,"Delivery Expenses",T_GL!$A$6:$A$4005,">="&DATE(YEAR(I_Parameter!$C$4),MONTH(I_Parameter!$C$4),1),T_GL!$A$6:$A$4005,"<="&(I_Parameter!$C$4-1)) -> -38821994 | H17: =G17+D17 -> -40809091 | I17: run-rate (I_RunRate)
A18: Commission Expenses | B18: =-SUMIFS(T_GL!$J$6:$J$4005,T_GL!$L$6:$L$4005,"Commission Expenses",T_GL!$A$6:$A$4005,">="&(I_Parameter!$C$5-7),T_GL!$A$6:$A$4005,"<="&(I_Parameter!$C$5-1)) -> 0 | C18: =-SUMIFS(T_GL!$J$6:$J$4005,T_GL!$L$6:$L$4005,"Commission Expenses",T_GL!$A$6:$A$4005,">="&I_Parameter!$C$5,T_GL!$A$6:$A$4005,"<="&(I_Parameter!$C$4-1)) -> 0 | D18: =-(I_RunRate!$B$9*((I_Parameter!$C$6-I_Parameter!$C$4+1)/DAY(EOMONTH(I_Parameter!$C$4,0)))+I_RunRate!$C$9) -> -467040.77 | E18: =C18+D18 -> -467040.77 | F18: =E18-B18 -> -467040.77 | G18: =-SUMIFS(T_GL!$J$6:$J$4005,T_GL!$L$6:$L$4005,"Commission Expenses",T_GL!$A$6:$A$4005,">="&DATE(YEAR(I_Parameter!$C$4),MONTH(I_Parameter!$C$4),1),T_GL!$A$6:$A$4005,"<="&(I_Parameter!$C$4-1)) -> -962000 | H18: =G18+D18 -> -1429040.8 | I18: run-rate (I_RunRate)
A19: Packaging | B19: =-SUMIFS(T_GL!$J$6:$J$4005,T_GL!$L$6:$L$4005,"Packaging",T_GL!$A$6:$A$4005,">="&(I_Parameter!$C$5-7),T_GL!$A$6:$A$4005,"<="&(I_Parameter!$C$5-1)) -> -742255 | C19: =-SUMIFS(T_GL!$J$6:$J$4005,T_GL!$L$6:$L$4005,"Packaging",T_GL!$A$6:$A$4005,">="&I_Parameter!$C$5,T_GL!$A$6:$A$4005,"<="&(I_Parameter!$C$4-1)) -> 0 | D19: =-(I_RunRate!$B$10*((I_Parameter!$C$6-I_Parameter!$C$4+1)/DAY(EOMONTH(I_Parameter!$C$4,0)))+I_RunRate!$C$10) -> -5021905.3 | E19: =C19+D19 -> -5021905.3 | F19: =E19-B19 -> -4279650.3 | G19: =-SUMIFS(T_GL!$J$6:$J$4005,T_GL!$L$6:$L$4005,"Packaging",T_GL!$A$6:$A$4005,">="&DATE(YEAR(I_Parameter!$C$4),MONTH(I_Parameter!$C$4),1),T_GL!$A$6:$A$4005,"<="&(I_Parameter!$C$4-1)) -> -11226650 | H19: =G19+D19 -> -16248555 | I19: run-rate (I_RunRate)
A20: Salaries and allowance | B20: =-SUMIFS(T_GL!$J$6:$J$4005,T_GL!$L$6:$L$4005,"Salaries and allowance",T_GL!$A$6:$A$4005,">="&(I_Parameter!$C$5-7),T_GL!$A$6:$A$4005,"<="&(I_Parameter!$C$5-1)) -> 0 | C20: =-SUMIFS(T_GL!$J$6:$J$4005,T_GL!$L$6:$L$4005,"Salaries and allowance",T_GL!$A$6:$A$4005,">="&I_Parameter!$C$5,T_GL!$A$6:$A$4005,"<="&(I_Parameter!$C$4-1)) -> 0 | D20: =-(I_RunRate!$B$11*((I_Parameter!$C$6-I_Parameter!$C$4+1)/DAY(EOMONTH(I_Parameter!$C$4,0)))+I_RunRate!$C$11) -> -6733725 | E20: =C20+D20 -> -6733725 | F20: =E20-B20 -> -6733725 | G20: =-SUMIFS(T_GL!$J$6:$J$4005,T_GL!$L$6:$L$4005,"Salaries and allowance",T_GL!$A$6:$A$4005,">="&DATE(YEAR(I_Parameter!$C$4),MONTH(I_Parameter!$C$4),1),T_GL!$A$6:$A$4005,"<="&(I_Parameter!$C$4-1)) -> 0 | H20: =G20+D20 -> -6733725 | I20: run-rate (I_RunRate)
A21: Storage Expenses | B21: =-SUMIFS(T_GL!$J$6:$J$4005,T_GL!$L$6:$L$4005,"Storage Expenses",T_GL!$A$6:$A$4005,">="&(I_Parameter!$C$5-7),T_GL!$A$6:$A$4005,"<="&(I_Parameter!$C$5-1)) -> -81094312 | C21: =-SUMIFS(T_GL!$J$6:$J$4005,T_GL!$L$6:$L$4005,"Storage Expenses",T_GL!$A$6:$A$4005,">="&I_Parameter!$C$5,T_GL!$A$6:$A$4005,"<="&(I_Parameter!$C$4-1)) -> 0 | D21: =-(I_RunRate!$B$12*((I_Parameter!$C$6-I_Parameter!$C$4+1)/DAY(EOMONTH(I_Parameter!$C$4,0)))+I_RunRate!$C$12) -> -10620868 | E21: =C21+D21 -> -10620868 | F21: =E21-B21 -> 70473444 | G21: =-SUMIFS(T_GL!$J$6:$J$4005,T_GL!$L$6:$L$4005,"Storage Expenses",T_GL!$A$6:$A$4005,">="&DATE(YEAR(I_Parameter!$C$4),MONTH(I_Parameter!$C$4),1),T_GL!$A$6:$A$4005,"<="&(I_Parameter!$C$4-1)) -> -89014384 | H21: =G21+D21 -> -99635252 | I21: run-rate (I_RunRate)
A22: Office Transportation expenses | B22: =-SUMIFS(T_GL!$J$6:$J$4005,T_GL!$L$6:$L$4005,"Office Transportation expenses",T_GL!$A$6:$A$4005,">="&(I_Parameter!$C$5-7),T_GL!$A$6:$A$4005,"<="&(I_Parameter!$C$5-1)) -> -7012864 | C22: =-SUMIFS(T_GL!$J$6:$J$4005,T_GL!$L$6:$L$4005,"Office Transportation expenses",T_GL!$A$6:$A$4005,">="&I_Parameter!$C$5,T_GL!$A$6:$A$4005,"<="&(I_Parameter!$C$4-1)) -> 0 | D22: =-(I_RunRate!$B$13*((I_Parameter!$C$6-I_Parameter!$C$4+1)/DAY(EOMONTH(I_Parameter!$C$4,0)))+I_RunRate!$C$13) -> -2433327 | E22: =C22+D22 -> -2433327 | F22: =E22-B22 -> 4579537 | G22: =-SUMIFS(T_GL!$J$6:$J$4005,T_GL!$L$6:$L$4005,"Office Transportation expenses",T_GL!$A$6:$A$4005,">="&DATE(YEAR(I_Parameter!$C$4),MONTH(I_Parameter!$C$4),1),T_GL!$A$6:$A$4005,"<="&(I_Parameter!$C$4-1)) -> -23102127 | H22: =G22+D22 -> -25535454 | I22: run-rate (I_RunRate)
A23: Rent Expenses | B23: =-SUMIFS(T_GL!$J$6:$J$4005,T_GL!$L$6:$L$4005,"Rent Expenses",T_GL!$A$6:$A$4005,">="&(I_Parameter!$C$5-7),T_GL!$A$6:$A$4005,"<="&(I_Parameter!$C$5-1)) -> 0 | C23: =-SUMIFS(T_GL!$J$6:$J$4005,T_GL!$L$6:$L$4005,"Rent Expenses",T_GL!$A$6:$A$4005,">="&I_Parameter!$C$5,T_GL!$A$6:$A$4005,"<="&(I_Parameter!$C$4-1)) -> 0 | D23: =-(I_RunRate!$B$14*((I_Parameter!$C$6-I_Parameter!$C$4+1)/DAY(EOMONTH(I_Parameter!$C$4,0)))+I_RunRate!$C$14) -> -424196.9 | E23: =C23+D23 -> -424196.9 | F23: =E23-B23 -> -424196.9 | G23: =-SUMIFS(T_GL!$J$6:$J$4005,T_GL!$L$6:$L$4005,"Rent Expenses",T_GL!$A$6:$A$4005,">="&DATE(YEAR(I_Parameter!$C$4),MONTH(I_Parameter!$C$4),1),T_GL!$A$6:$A$4005,"<="&(I_Parameter!$C$4-1)) -> 0 | H23: =G23+D23 -> -424196.9 | I23: run-rate (I_RunRate)
A24: Professional Fee | B24: =-SUMIFS(T_GL!$J$6:$J$4005,T_GL!$L$6:$L$4005,"Professional Fee",T_GL!$A$6:$A$4005,">="&(I_Parameter!$C$5-7),T_GL!$A$6:$A$4005,"<="&(I_Parameter!$C$5-1)) -> -2564102 | C24: =-SUMIFS(T_GL!$J$6:$J$4005,T_GL!$L$6:$L$4005,"Professional Fee",T_GL!$A$6:$A$4005,">="&I_Parameter!$C$5,T_GL!$A$6:$A$4005,"<="&(I_Parameter!$C$4-1)) -> -7692308 | D24: =-(I_RunRate!$B$15*((I_Parameter!$C$6-I_Parameter!$C$4+1)/DAY(EOMONTH(I_Parameter!$C$4,0)))+I_RunRate!$C$15) -> 0 | E24: =C24+D24 -> -7692308 | F24: =E24-B24 -> -5128206 | G24: =-SUMIFS(T_GL!$J$6:$J$4005,T_GL!$L$6:$L$4005,"Professional Fee",T_GL!$A$6:$A$4005,">="&DATE(YEAR(I_Parameter!$C$4),MONTH(I_Parameter!$C$4),1),T_GL!$A$6:$A$4005,"<="&(I_Parameter!$C$4-1)) -> -10256410 | H24: =G24+D24 -> -10256410 | I24: run-rate (I_RunRate)
A25: Office Supplies & Utilities | B25: =-SUMIFS(T_GL!$J$6:$J$4005,T_GL!$L$6:$L$4005,"Office Supplies & Utilities",T_GL!$A$6:$A$4005,">="&(I_Parameter!$C$5-7),T_GL!$A$6:$A$4005,"<="&(I_Parameter!$C$5-1)) -> -3034793 | C25: =-SUMIFS(T_GL!$J$6:$J$4005,T_GL!$L$6:$L$4005,"Office Supplies & Utilities",T_GL!$A$6:$A$4005,">="&I_Parameter!$C$5,T_GL!$A$6:$A$4005,"<="&(I_Parameter!$C$4-1)) -> 0 | D25: =-(I_RunRate!$B$16*((I_Parameter!$C$6-I_Parameter!$C$4+1)/DAY(EOMONTH(I_Parameter!$C$4,0)))+I_RunRate!$C$16) -> -805045.16 | E25: =C25+D25 -> -805045.16 | F25: =E25-B25 -> 2229747.8 | G25: =-SUMIFS(T_GL!$J$6:$J$4005,T_GL!$L$6:$L$4005,"Office Supplies & Utilities",T_GL!$A$6:$A$4005,">="&DATE(YEAR(I_Parameter!$C$4),MONTH(I_Parameter!$C$4),1),T_GL!$A$6:$A$4005,"<="&(I_Parameter!$C$4-1)) -> -5508133 | H25: =G25+D25 -> -6313178.2 | I25: run-rate (I_RunRate)
A26: Maintenance Expenses | B26: =-SUMIFS(T_GL!$J$6:$J$4005,T_GL!$L$6:$L$4005,"Maintenance Expenses",T_GL!$A$6:$A$4005,">="&(I_Parameter!$C$5-7),T_GL!$A$6:$A$4005,"<="&(I_Parameter!$C$5-1)) -> 0 | C26: =-SUMIFS(T_GL!$J$6:$J$4005,T_GL!$L$6:$L$4005,"Maintenance Expenses",T_GL!$A$6:$A$4005,">="&I_Parameter!$C$5,T_GL!$A$6:$A$4005,"<="&(I_Parameter!$C$4-1)) -> 0 | D26: =-(I_RunRate!$B$17*((I_Parameter!$C$6-I_Parameter!$C$4+1)/DAY(EOMONTH(I_Parameter!$C$4,0)))+I_RunRate!$C$17) -> 0 | E26: =C26+D26 -> 0 | F26: =E26-B26 -> 0 | G26: =-SUMIFS(T_GL!$J$6:$J$4005,T_GL!$L$6:$L$4005,"Maintenance Expenses",T_GL!$A$6:$A$4005,">="&DATE(YEAR(I_Parameter!$C$4),MONTH(I_Parameter!$C$4),1),T_GL!$A$6:$A$4005,"<="&(I_Parameter!$C$4-1)) -> 0 | H26: =G26+D26 -> 0 | I26: run-rate (I_RunRate)
A27: Tax expenses | B27: =-SUMIFS(T_GL!$J$6:$J$4005,T_GL!$L$6:$L$4005,"Tax expenses",T_GL!$A$6:$A$4005,">="&(I_Parameter!$C$5-7),T_GL!$A$6:$A$4005,"<="&(I_Parameter!$C$5-1)) -> -1368362 | C27: =-SUMIFS(T_GL!$J$6:$J$4005,T_GL!$L$6:$L$4005,"Tax expenses",T_GL!$A$6:$A$4005,">="&I_Parameter!$C$5,T_GL!$A$6:$A$4005,"<="&(I_Parameter!$C$4-1)) -> -1392166 | D27: =-(I_RunRate!$B$18*((I_Parameter!$C$6-I_Parameter!$C$4+1)/DAY(EOMONTH(I_Parameter!$C$4,0)))+I_RunRate!$C$18) -> 70092.129 | E27: =C27+D27 -> -1322073.9 | F27: =E27-B27 -> 46288.129 | G27: =-SUMIFS(T_GL!$J$6:$J$4005,T_GL!$L$6:$L$4005,"Tax expenses",T_GL!$A$6:$A$4005,">="&DATE(YEAR(I_Parameter!$C$4),MONTH(I_Parameter!$C$4),1),T_GL!$A$6:$A$4005,"<="&(I_Parameter!$C$4-1)) -> -4998457.7 | H27: =G27+D27 -> -4928365.5 | I27: run-rate (I_RunRate)
A28: Other operating expenses | B28: =-SUMIFS(T_GL!$J$6:$J$4005,T_GL!$L$6:$L$4005,"Other operating expenses",T_GL!$A$6:$A$4005,">="&(I_Parameter!$C$5-7),T_GL!$A$6:$A$4005,"<="&(I_Parameter!$C$5-1)) -> 0 | C28: =-SUMIFS(T_GL!$J$6:$J$4005,T_GL!$L$6:$L$4005,"Other operating expenses",T_GL!$A$6:$A$4005,">="&I_Parameter!$C$5,T_GL!$A$6:$A$4005,"<="&(I_Parameter!$C$4-1)) -> 0 | D28: =-(I_RunRate!$B$19*((I_Parameter!$C$6-I_Parameter!$C$4+1)/DAY(EOMONTH(I_Parameter!$C$4,0)))+I_RunRate!$C$19) -> 0 | E28: =C28+D28 -> 0 | F28: =E28-B28 -> 0 | G28: =-SUMIFS(T_GL!$J$6:$J$4005,T_GL!$L$6:$L$4005,"Other operating expenses",T_GL!$A$6:$A$4005,">="&DATE(YEAR(I_Parameter!$C$4),MONTH(I_Parameter!$C$4),1),T_GL!$A$6:$A$4005,"<="&(I_Parameter!$C$4-1)) -> 0 | H28: =G28+D28 -> 0 | I28: run-rate (I_RunRate)
A29: TOTAL OPERATING EXPENSES (excl. D&A) | B29: =SUM(B17:B28) -> -106792694 | C29: =SUM(C17:C28) -> -10484474 | D29: =SUM(D17:D28) -> -28423113 | E29: =SUM(E17:E28) -> -38907587 | F29: =SUM(F17:F28) -> 67885107 | G29: =SUM(G17:G28) -> -1.8389016e+08 | H29: =SUM(H17:H28) -> -2.1231327e+08
A30: OPERATING INCOME | B30: =B15+B29 -> -1.1097517e+08 | C30: =C15+C29 -> -10042390 | D30: =D15+D29 -> -96393306 | E30: =E15+E29 -> -1.064357e+08 | F30: =F15+F29 -> 4539478.5 | G30: =G15+G29 -> 1.635131e+08 | H30: =H15+H29 -> 67119793
A31: Interest Expense | B31: =-SUMIFS(T_GL!$J$6:$J$4005,T_GL!$L$6:$L$4005,"Interest Expense",T_GL!$A$6:$A$4005,">="&(I_Parameter!$C$5-7),T_GL!$A$6:$A$4005,"<="&(I_Parameter!$C$5-1)) -> 0 | C31: =-SUMIFS(T_GL!$J$6:$J$4005,T_GL!$L$6:$L$4005,"Interest Expense",T_GL!$A$6:$A$4005,">="&I_Parameter!$C$5,T_GL!$A$6:$A$4005,"<="&(I_Parameter!$C$4-1)) -> 0 | D31: =-(I_RunRate!$B$20*((I_Parameter!$C$6-I_Parameter!$C$4+1)/DAY(EOMONTH(I_Parameter!$C$4,0)))+I_RunRate!$C$20) -> -3153763.4 | E31: =C31+D31 -> -3153763.4 | F31: =E31-B31 -> -3153763.4 | G31: =-SUMIFS(T_GL!$J$6:$J$4005,T_GL!$L$6:$L$4005,"Interest Expense",T_GL!$A$6:$A$4005,">="&DATE(YEAR(I_Parameter!$C$4),MONTH(I_Parameter!$C$4),1),T_GL!$A$6:$A$4005,"<="&(I_Parameter!$C$4-1)) -> 0 | H31: =G31+D31 -> -3153763.4 | I31: run-rate (I_RunRate)
A32: Other Income | B32: =-SUMIFS(T_GL!$J$6:$J$4005,T_GL!$L$6:$L$4005,"Other Income",T_GL!$A$6:$A$4005,">="&(I_Parameter!$C$5-7),T_GL!$A$6:$A$4005,"<="&(I_Parameter!$C$5-1)) -> 19058.51 | C32: =-SUMIFS(T_GL!$J$6:$J$4005,T_GL!$L$6:$L$4005,"Other Income",T_GL!$A$6:$A$4005,">="&I_Parameter!$C$5,T_GL!$A$6:$A$4005,"<="&(I_Parameter!$C$4-1)) -> -0.21 | D32: =(I_RunRate!$B$21*((I_Parameter!$C$6-I_Parameter!$C$4+1)/DAY(EOMONTH(I_Parameter!$C$4,0)))+I_RunRate!$C$21) -> 3401693 | E32: =C32+D32 -> 3401692.8 | F32: =E32-B32 -> 3382634.3 | G32: =-SUMIFS(T_GL!$J$6:$J$4005,T_GL!$L$6:$L$4005,"Other Income",T_GL!$A$6:$A$4005,">="&DATE(YEAR(I_Parameter!$C$4),MONTH(I_Parameter!$C$4),1),T_GL!$A$6:$A$4005,"<="&(I_Parameter!$C$4-1)) -> 1753081.5 | H32: =G32+D32 -> 5154774.6 | I32: run-rate (I_RunRate)
A33: Other Expense | B33: =-SUMIFS(T_GL!$J$6:$J$4005,T_GL!$L$6:$L$4005,"Other Expense",T_GL!$A$6:$A$4005,">="&(I_Parameter!$C$5-7),T_GL!$A$6:$A$4005,"<="&(I_Parameter!$C$5-1)) -> -11650 | C33: =-SUMIFS(T_GL!$J$6:$J$4005,T_GL!$L$6:$L$4005,"Other Expense",T_GL!$A$6:$A$4005,">="&I_Parameter!$C$5,T_GL!$A$6:$A$4005,"<="&(I_Parameter!$C$4-1)) -> 0 | D33: =-(I_RunRate!$B$22*((I_Parameter!$C$6-I_Parameter!$C$4+1)/DAY(EOMONTH(I_Parameter!$C$4,0)))+I_RunRate!$C$22) -> -47270.71 | E33: =C33+D33 -> -47270.71 | F33: =E33-B33 -> -35620.71 | G33: =-SUMIFS(T_GL!$J$6:$J$4005,T_GL!$L$6:$L$4005,"Other Expense",T_GL!$A$6:$A$4005,">="&DATE(YEAR(I_Parameter!$C$4),MONTH(I_Parameter!$C$4),1),T_GL!$A$6:$A$4005,"<="&(I_Parameter!$C$4-1)) -> -16400 | H33: =G33+D33 -> -63670.71 | I33: run-rate (I_RunRate)
A34: TOTAL OTHER INCOME (EXPENSE) | B34: =SUM(B31:B33) -> 7408.51 | C34: =SUM(C31:C33) -> -0.21 | D34: =SUM(D31:D33) -> 200658.97 | E34: =SUM(E31:E33) -> 200658.76 | F34: =SUM(F31:F33) -> 193250.25 | G34: =SUM(G31:G33) -> 1736681.5 | H34: =SUM(H31:H33) -> 1937340.5
A35: NIBT (before D&A) | B35: =B30+B34 -> -1.1096777e+08 | C35: =C30+C34 -> -10042390 | D35: =D30+D34 -> -96192647 | E35: =E30+E34 -> -1.0623504e+08 | F35: =F30+F34 -> 4732728.7 | G35: =G30+G34 -> 1.6524978e+08 | H35: =H30+H34 -> 69057134
A36: Depreciation & amortisation | B36: =-SUMIFS(T_GL!$J$6:$J$4005,T_GL!$L$6:$L$4005,"Depreciation & amortisation",T_GL!$A$6:$A$4005,">="&(I_Parameter!$C$5-7),T_GL!$A$6:$A$4005,"<="&(I_Parameter!$C$5-1)) -> 0 | C36: =-SUMIFS(T_GL!$J$6:$J$4005,T_GL!$L$6:$L$4005,"Depreciation & amortisation",T_GL!$A$6:$A$4005,">="&I_Parameter!$C$5,T_GL!$A$6:$A$4005,"<="&(I_Parameter!$C$4-1)) -> 0 | D36: =-(I_RunRate!$B$23*((I_Parameter!$C$6-I_Parameter!$C$4+1)/DAY(EOMONTH(I_Parameter!$C$4,0)))+I_RunRate!$C$23) -> -1341091.7 | E36: =C36+D36 -> -1341091.7 | F36: =E36-B36 -> -1341091.7 | G36: =-SUMIFS(T_GL!$J$6:$J$4005,T_GL!$L$6:$L$4005,"Depreciation & amortisation",T_GL!$A$6:$A$4005,">="&DATE(YEAR(I_Parameter!$C$4),MONTH(I_Parameter!$C$4),1),T_GL!$A$6:$A$4005,"<="&(I_Parameter!$C$4-1)) -> 0 | H36: =G36+D36 -> -1341091.7 | I36: run-rate (I_RunRate)
A37: NET INCOME | B37: =B35+B36 -> -1.1096777e+08 | C37: =C35+C36 -> -10042390 | D37: =D35+D36 -> -97533739 | E37: =E35+E36 -> -1.0757613e+08 | F37: =F35+F36 -> 3391637 | G37: =G35+G36 -> 1.6524978e+08 | H37: =H35+H36 -> 67716042
A39: Catatan: aktual = jurnal Accurate (tanggal SI/PI); blok 1 O_Outlook = pengiriman (DO). Jurnal akhir bulan (unbilled, penyesuaian) baru masuk setelah diposting.

Sheet O_BS
A1: NERACA MINGGUAN — Rp
A2: Aktual = saldo awal TB + jurnal s.d. tanggal. Proyeksi akhir minggu = saldo kemarin + arus rencana (lihat blok "Arus rencana minggu ini" di bawah).
B4: =I_Parameter!$C$47 -> 46234 | C4: =I_Parameter!$C$5-1 -> 46257 | D4: =I_Parameter!$C$4-1 -> 46260 | E4: =I_Parameter!$C$6 -> 46264
A5: Pos | B5: Saldo awal (TB) | C5: Akhir minggu lalu | D5: Kemarin (aktual) | E5: Proyeksi akhir minggu ini | F5: Δ minggu ini (proyeksi − akhir minggu lalu) | G5: Δ rencana (debit +)
A6: ASSETS
A7: Cash and cash equivalents | B7: =(SUMIFS(I_TB!$C$6:$C$265,I_TB!$E$6:$E$265,"Cash and cash equivalents")+SUMIFS(T_GL!$J$6:$J$4005,T_GL!$M$6:$M$4005,"Cash and cash equivalents",T_GL!$A$6:$A$4005,"<="&B$4)) -> 5.9984142e+08 | C7: =(SUMIFS(I_TB!$C$6:$C$265,I_TB!$E$6:$E$265,"Cash and cash equivalents")+SUMIFS(T_GL!$J$6:$J$4005,T_GL!$M$6:$M$4005,"Cash and cash equivalents",T_GL!$A$6:$A$4005,"<="&C$4)) -> 3.7909117e+08 | D7: =(SUMIFS(I_TB!$C$6:$C$265,I_TB!$E$6:$E$265,"Cash and cash equivalents")+SUMIFS(T_GL!$J$6:$J$4005,T_GL!$M$6:$M$4005,"Cash and cash equivalents",T_GL!$A$6:$A$4005,"<="&D$4)) -> 1.2892513e+09 | E7: =D7+G7 -> 8.1819823e+08 | F7: =E7-C7 -> 439107064 | G7: =-SUMIFS(T_Kas_Rencana!$E$6:$E$305,T_Kas_Rencana!$C$6:$C$305,"Cash and cash equivalents",T_Kas_Rencana!$F$6:$F$305,1)+$B$73 -> -471053116
A8: Trade Receivables - Third Parties | B8: =(SUMIFS(I_TB!$C$6:$C$265,I_TB!$E$6:$E$265,"Trade Receivables - Third Parties")+SUMIFS(T_GL!$J$6:$J$4005,T_GL!$M$6:$M$4005,"Trade Receivables - Third Parties",T_GL!$A$6:$A$4005,"<="&B$4)) -> 310674730 | C8: =(SUMIFS(I_TB!$C$6:$C$265,I_TB!$E$6:$E$265,"Trade Receivables - Third Parties")+SUMIFS(T_GL!$J$6:$J$4005,T_GL!$M$6:$M$4005,"Trade Receivables - Third Parties",T_GL!$A$6:$A$4005,"<="&C$4)) -> 637472980 | D8: =(SUMIFS(I_TB!$C$6:$C$265,I_TB!$E$6:$E$265,"Trade Receivables - Third Parties")+SUMIFS(T_GL!$J$6:$J$4005,T_GL!$M$6:$M$4005,"Trade Receivables - Third Parties",T_GL!$A$6:$A$4005,"<="&D$4)) -> 991265050 | E8: =D8+G8 -> 6.2518396e+08 | F8: =E8-C8 -> -12289018 | G8: =-SUMIFS(T_Kas_Rencana!$E$6:$E$305,T_Kas_Rencana!$C$6:$C$305,"Trade Receivables - Third Parties",T_Kas_Rencana!$F$6:$F$305,1)+$B$67 -> -3.6608109e+08
A9: Trade Receivables - Related Parties | B9: =(SUMIFS(I_TB!$C$6:$C$265,I_TB!$E$6:$E$265,"Trade Receivables - Related Parties")+SUMIFS(T_GL!$J$6:$J$4005,T_GL!$M$6:$M$4005,"Trade Receivables - Related Parties",T_GL!$A$6:$A$4005,"<="&B$4)) -> 0 | C9: =(SUMIFS(I_TB!$C$6:$C$265,I_TB!$E$6:$E$265,"Trade Receivables - Related Parties")+SUMIFS(T_GL!$J$6:$J$4005,T_GL!$M$6:$M$4005,"Trade Receivables - Related Parties",T_GL!$A$6:$A$4005,"<="&C$4)) -> 0 | D9: =(SUMIFS(I_TB!$C$6:$C$265,I_TB!$E$6:$E$265,"Trade Receivables - Related Parties")+SUMIFS(T_GL!$J$6:$J$4005,T_GL!$M$6:$M$4005,"Trade Receivables - Related Parties",T_GL!$A$6:$A$4005,"<="&D$4)) -> 0 | E9: =D9+G9 -> 0 | F9: =E9-C9 -> 0 | G9: =-SUMIFS(T_Kas_Rencana!$E$6:$E$305,T_Kas_Rencana!$C$6:$C$305,"Trade Receivables - Related Parties",T_Kas_Rencana!$F$6:$F$305,1)+0 -> 0
A10: Other Receivable - Third Party | B10: =(SUMIFS(I_TB!$C$6:$C$265,I_TB!$E$6:$E$265,"Other Receivable - Third Party")+SUMIFS(T_GL!$J$6:$J$4005,T_GL!$M$6:$M$4005,"Other Receivable - Third Party",T_GL!$A$6:$A$4005,"<="&B$4)) -> 0 | C10: =(SUMIFS(I_TB!$C$6:$C$265,I_TB!$E$6:$E$265,"Other Receivable - Third Party")+SUMIFS(T_GL!$J$6:$J$4005,T_GL!$M$6:$M$4005,"Other Receivable - Third Party",T_GL!$A$6:$A$4005,"<="&C$4)) -> 0 | D10: =(SUMIFS(I_TB!$C$6:$C$265,I_TB!$E$6:$E$265,"Other Receivable - Third Party")+SUMIFS(T_GL!$J$6:$J$4005,T_GL!$M$6:$M$4005,"Other Receivable - Third Party",T_GL!$A$6:$A$4005,"<="&D$4)) -> 0 | E10: =D10+G10 -> 0 | F10: =E10-C10 -> 0 | G10: =-SUMIFS(T_Kas_Rencana!$E$6:$E$305,T_Kas_Rencana!$C$6:$C$305,"Other Receivable - Third Party",T_Kas_Rencana!$F$6:$F$305,1)+0 -> 0
A11: Other Receivable - Affiliated Party | B11: =(SUMIFS(I_TB!$C$6:$C$265,I_TB!$E$6:$E$265,"Other Receivable - Affiliated Party")+SUMIFS(T_GL!$J$6:$J$4005,T_GL!$M$6:$M$4005,"Other Receivable - Affiliated Party",T_GL!$A$6:$A$4005,"<="&B$4)) -> 0 | C11: =(SUMIFS(I_TB!$C$6:$C$265,I_TB!$E$6:$E$265,"Other Receivable - Affiliated Party")+SUMIFS(T_GL!$J$6:$J$4005,T_GL!$M$6:$M$4005,"Other Receivable - Affiliated Party",T_GL!$A$6:$A$4005,"<="&C$4)) -> 0 | D11: =(SUMIFS(I_TB!$C$6:$C$265,I_TB!$E$6:$E$265,"Other Receivable - Affiliated Party")+SUMIFS(T_GL!$J$6:$J$4005,T_GL!$M$6:$M$4005,"Other Receivable - Affiliated Party",T_GL!$A$6:$A$4005,"<="&D$4)) -> 0 | E11: =D11+G11 -> 0 | F11: =E11-C11 -> 0 | G11: =-SUMIFS(T_Kas_Rencana!$E$6:$E$305,T_Kas_Rencana!$C$6:$C$305,"Other Receivable - Affiliated Party",T_Kas_Rencana!$F$6:$F$305,1)+0 -> 0
A12: Advance Payment | B12: =(SUMIFS(I_TB!$C$6:$C$265,I_TB!$E$6:$E$265,"Advance Payment")+SUMIFS(T_GL!$J$6:$J$4005,T_GL!$M$6:$M$4005,"Advance Payment",T_GL!$A$6:$A$4005,"<="&B$4)) -> 1.4720445e+09 | C12: =(SUMIFS(I_TB!$C$6:$C$265,I_TB!$E$6:$E$265,"Advance Payment")+SUMIFS(T_GL!$J$6:$J$4005,T_GL!$M$6:$M$4005,"Advance Payment",T_GL!$A$6:$A$4005,"<="&C$4)) -> 6.2222191e+08 | D12: =(SUMIFS(I_TB!$C$6:$C$265,I_TB!$E$6:$E$265,"Advance Payment")+SUMIFS(T_GL!$J$6:$J$4005,T_GL!$M$6:$M$4005,"Advance Payment",T_GL!$A$6:$A$4005,"<="&D$4)) -> 6.4230947e+08 | E12: =D12+G12 -> 6.2247411e+08 | F12: =E12-C12 -> 252200 | G12: =-SUMIFS(T_Kas_Rencana!$E$6:$E$305,T_Kas_Rencana!$C$6:$C$305,"Advance Payment",T_Kas_Rencana!$F$6:$F$305,1)+0 -> -19835360
A13: Inventory - Product | B13: =(SUMIFS(I_TB!$C$6:$C$265,I_TB!$E$6:$E$265,"Inventory - Product")+SUMIFS(T_GL!$J$6:$J$4005,T_GL!$M$6:$M$4005,"Inventory - Product",T_GL!$A$6:$A$4005,"<="&B$4)) -> 7.7119464e+08 | C13: =(SUMIFS(I_TB!$C$6:$C$265,I_TB!$E$6:$E$265,"Inventory - Product")+SUMIFS(T_GL!$J$6:$J$4005,T_GL!$M$6:$M$4005,"Inventory - Product",T_GL!$A$6:$A$4005,"<="&C$4)) -> 1.2620242e+09 | D13: =(SUMIFS(I_TB!$C$6:$C$265,I_TB!$E$6:$E$265,"Inventory - Product")+SUMIFS(T_GL!$J$6:$J$4005,T_GL!$M$6:$M$4005,"Inventory - Product",T_GL!$A$6:$A$4005,"<="&D$4)) -> 1.5681049e+09 | E13: =D13+G13 -> 1.6367554e+09 | F13: =E13-C13 -> 3.747312e+08 | G13: =-SUMIFS(T_Kas_Rencana!$E$6:$E$305,T_Kas_Rencana!$C$6:$C$305,"Inventory - Product",T_Kas_Rencana!$F$6:$F$305,1)+($B$60-$B$68) -> 68650474
A14: Inventory - Trading | B14: =(SUMIFS(I_TB!$C$6:$C$265,I_TB!$E$6:$E$265,"Inventory - Trading")+SUMIFS(T_GL!$J$6:$J$4005,T_GL!$M$6:$M$4005,"Inventory - Trading",T_GL!$A$6:$A$4005,"<="&B$4)) -> 2.1245601e+09 | C14: =(SUMIFS(I_TB!$C$6:$C$265,I_TB!$E$6:$E$265,"Inventory - Trading")+SUMIFS(T_GL!$J$6:$J$4005,T_GL!$M$6:$M$4005,"Inventory - Trading",T_GL!$A$6:$A$4005,"<="&C$4)) -> 2.5185822e+09 | D14: =(SUMIFS(I_TB!$C$6:$C$265,I_TB!$E$6:$E$265,"Inventory - Trading")+SUMIFS(T_GL!$J$6:$J$4005,T_GL!$M$6:$M$4005,"Inventory - Trading",T_GL!$A$6:$A$4005,"<="&D$4)) -> 2.5921095e+09 | E14: =D14+G14 -> 2.3556527e+09 | F14: =E14-C14 -> -1.6292957e+08 | G14: =-SUMIFS(T_Kas_Rencana!$E$6:$E$305,T_Kas_Rencana!$C$6:$C$305,"Inventory - Trading",T_Kas_Rencana!$F$6:$F$305,1)+($B$63-$B$69) -> -2.3645686e+08
A15: Prepaid Tax | B15: =(SUMIFS(I_TB!$C$6:$C$265,I_TB!$E$6:$E$265,"Prepaid Tax")+SUMIFS(T_GL!$J$6:$J$4005,T_GL!$M$6:$M$4005,"Prepaid Tax",T_GL!$A$6:$A$4005,"<="&B$4)) -> 1.2366855e+08 | C15: =(SUMIFS(I_TB!$C$6:$C$265,I_TB!$E$6:$E$265,"Prepaid Tax")+SUMIFS(T_GL!$J$6:$J$4005,T_GL!$M$6:$M$4005,"Prepaid Tax",T_GL!$A$6:$A$4005,"<="&C$4)) -> 1.508409e+08 | D15: =(SUMIFS(I_TB!$C$6:$C$265,I_TB!$E$6:$E$265,"Prepaid Tax")+SUMIFS(T_GL!$J$6:$J$4005,T_GL!$M$6:$M$4005,"Prepaid Tax",T_GL!$A$6:$A$4005,"<="&D$4)) -> 1.5780993e+08 | E15: =D15+G15 -> 1.5780993e+08 | F15: =E15-C15 -> 6969037 | G15: =-SUMIFS(T_Kas_Rencana!$E$6:$E$305,T_Kas_Rencana!$C$6:$C$305,"Prepaid Tax",T_Kas_Rencana!$F$6:$F$305,1)+0 -> 0
