Workbook

Sheet Model_Details
A1: KGR GROUP — Demand Forecast & Inventory Optimizer (Working Paper)
A3: Joint-Production Optimizer
A5: MODEL INFORMATION
A6: Entity | B6: KGR (perusahaan trading & potong ayam)
A7: Model purpose | B7: Demand forecast per potongan + keputusan beli ayam hidup (joint production)
A8: Methodology | B8: Overlay stack + scenario (Bear/Base/Bull) + multi-product newsvendor (joint supply)
A9: Basis | B9: Unit fisik - kg per potongan & ekor ayam
A10: Forecast horizon | B10: 7 hari ke depan (harian), window beli mingguan
A11: Historical data | B11: Penjualan harian per SKU (dummy 3 minggu pada skeleton)
A12: Scenarios | B12: Bear / Base / Bull
A14: SHEET MAP
A15: Sheet | B15: Purpose | C15: Type | D15: Status
A16: I_Products | B16: Master potongan/SKU: harga, shelf life, tier | G16: Input | H16: Edit
A17: I_Yield | B17: Yield matrix: 1 ekor → kg tiap potongan (KOPLING) | G17: Input | H17: Paste aktual RPA
A18: I_Live_Bird | B18: Biaya ayam hidup + constraint + model controls | G18: Input | H18: Edit
A19: I_Sales_History | B19: Penjualan harian per SKU (kg) + flag stockout | G19: Input | H19: Paste data riil
A20: I_Market_Intelligence | B20: Seasonality DOW + override Lebaran/hari libur | G20: Input | H20: Isi judgment
A21: I_MEV | B21: Driver makro ayam (pakan, DOC, harga hidup) | G21: Input | H21: TBC — overlay OFF
A22: O_Demand_Rate | B22: Demand rate historis per SKU (censored) | G22: Calc | H22: Auto
A23: O_Scenario_Multipliers | B23: Multiplier skenario per SKU via tier | G23: Calc | H23: Auto
A24: O_Monte_Carlo | B24: Band probabilistik P10/P50/P90 per SKU | G24: Calc | H24: Auto
A25: O_Granger_Test | B25: Validasi MEV (placeholder) | G25: Calc | H25: TBC
A26: O_Demand_Forecast | B26: LAYER 1 — forecast kg per SKU × skenario | G26: Output | H26: Auto
A27: O_Optimizer | B27: LAYER 2 — beli berapa ekor (joint production) | G27: Output | H27: Auto + 1 decision
... A30: Z_Model_Governance | B30: Versi, sign-off, disclosure | G30: Reference | H30: Active
A32: COLOR LEGEND
A33: Sample | B33: Teks biru = input aktual (hardcode) — edit
A34: Sample | B34: Kuning = asumsi/judgment yang harus diisi
A35: Sample | B35: Teks hitam = output formula — jangan edit
A36: Sample | B36: Oranye = flag / perlu review
A37: Sample | B37: Biru muda + tebal = baris total
A39: OPEN ITEMS
A40: Item | B40: Owner | C40: Status | D40: Notes
A41: Yield aktual per kelas bobot | B41: RPA / Ops | C41: Pending | D41: Skeleton pakai 1 kelas bobot + yield placeholder
A42: Data penjualan harian riil per SKU | B42: Sales | C42: Pending | D42: Skeleton pakai dummy 3 minggu
A43: Harga jual aktual per potongan | B43: Finance | C43: Pending | D43: I_Products kolom harga
A44: Seasonality DOW + uplift Lebaran | B44: Head of Sales | C44: Pending | D44: I_Market_Intelligence — paling fondasional
A45: Validasi MEV (Granger ≥60 obs) | B45: Finance | C45: Pending | D45: Pakai indeks harga ayam/pakan seri panjang
A46: Optimizer stokastik harian + perishability | B46: Analytics | C46: Pending | D46: Excel = aproksimasi mingguan; versi rigor di Python
A47: Jalur potong alternatif (jual karkas utuh) | B47: Ops | C47: Pending | D47: Skeleton asumsikan semua dideboning

Sheet I_Products
A1: I_Products — Master Potongan / SKU
A2: Input aktual KGR. Harga & shelf life = placeholder; ganti dengan angka riil.
A3: SKU Code | B3: SKU Name | C3: Cut Type | D3: Fresh Shelf (hari) | E3: Frozen-Capable | F3: Frozen Shelf (hari) | G3: Sell Price (IDR/kg) | H3: Frozen Price Factor | I3: Tier | J3: Notes
A4: BLD | B4: Boneless Dada (fillet) | C4: Boneless | D4: 2 | E4: Y | F4: 90 | G4: 55000 | H4: 0.9 | I4: Neutral | J4: Binding cut — demand tertinggi
A5: BLP | B5: Boneless Paha (fillet) | C5: Boneless | D5: 2 | E5: Y | F5: 90 | G5: 48000 | H5: 0.9 | I5: Neutral
A6: SYP | B6: Sayap | C6: Bone-in | D6: 2 | E6: Y | F6: 90 | G6: 38000 | H6: 0.92 | I6: Neutral
A7: CKR | B7: Ceker | C7: Byproduct | D7: 2 | E7: Y | F7: 120 | G7: 28000 | H7: 0.95 | I7: Cyclical | J7: Demand ekspor-sensitif
A8: KPL | B8: Kepala | C8: Byproduct | D8: 1 | E8: Y | F8: 90 | G8: 12000 | H8: 0.95 | I8: Cyclical
A9: KLT | B9: Kulit | C9: Byproduct | D9: 1 | E9: Y | F9: 90 | G9: 25000 | H9: 0.92 | I9: Cyclical
A10: JRN | B10: Jeroan (ati ampela) | C10: Byproduct | D10: 1 | E10: Y | F10: 60 | G10: 22000 | H10: 0.9 | I10: Cyclical
A11: TLG | B11: Tulang / carcass frame | C11: Byproduct | D11: 2 | E11: Y | F11: 90 | G11: 8000 | H11: 0.95 | I11: Defensive | J11: Stok / pakan

Sheet I_Live_Bird
A1: I_Live_Bird — Biaya Ayam Hidup, Constraint & Model Controls
A2: Kuning = isi/ubah. Putih hitam = otomatis.
A3: Avg bobot ayam hidup (kg/ekor) | B3: 2
A4: Harga beli ayam hidup (IDR/kg) | B4: 19000
A5: Harga beli per ekor (IDR/ekor) | B5: =B3*B4 -> 38000 | C5: Otomatis: bobot × harga/kg
A6: Biaya potong RPA (IDR/ekor) | B6: 3000
A7: Total biaya per ekor (IDR/ekor) | B7: =B5+B6 -> 41000
A8: Kapasitas freezer (kg) | B8: 5000
A9: Biaya handling beku (IDR/kg) | B9: 500
A10: Nilai salvage unsold non-beku (IDR/kg) | B10: 1000
A11: Kapasitas potong harian (ekor/hari) | B11: 1500
A13: MODEL CONTROLS
A14: Planning window (hari) | B14: 7
A15: Trend mode (Flat / Clamped) | B15: Flat | C15: Flat = aman untuk data pendek
A16: Trend clamp (+/-) | B16: 0.1 | C16: Batas trend bila mode=Clamped
A17: MEV overlay (Off / On) | B17: Off | C17: Off sampai Granger-validated

Sheet I_Yield
A1: I_Yield — Yield Matrix
A2: Ganti % dengan rendemen aktual RPA. kg/ekor = % × bobot hidup. Total % harus = 100%.
A3: Bobot hidup acuan (kg/ekor) | B3: =I_Live_Bird!$B$3 -> 2
A5: Part Code | B5: Part Name | C5: Sellable | D5: Yield % Live Wt | E5: kg per Ekor | F5: Notes
A6: BLD | B6: Boneless Dada (fillet) | C6: Y | D6: 0.18 | E6: =D6*$B$3 -> 0.36 | F6: Binding cut — demand tertinggi
A7: BLP | B7: Boneless Paha (fillet) | C7: Y | D7: 0.13 | E7: =D7*$B$3 -> 0.26
A8: SYP | B8: Sayap | C8: Y | D8: 0.09 | E8: =D8*$B$3 -> 0.18
A9: CKR | B9: Ceker | C9: Y | D9: 0.04 | E9: =D9*$B$3 -> 0.08 | F9: Demand ekspor-sensitif
A10: KPL | B10: Kepala | C10: Y | D10: 0.03 | E10: =D10*$B$3 -> 0.06
A11: KLT | B11: Kulit | C11: Y | D11: 0.06 | E11: =D11*$B$3 -> 0.12
A12: JRN | B12: Jeroan (ati ampela) | C12: Y | D12: 0.05 | E12: =D12*$B$3 -> 0.1
A13: TLG | B13: Tulang / carcass frame | C13: Y | D13: 0.28 | E13: =D13*$B$3 -> 0.56 | F13: Stok / pakan
A14: SUSUT | B14: Susut (darah, bulu, drip, loss proses) | C14: N | D14: =1-SUM(D6:D13) -> 0.14 | E14: =D14*$B$3 -> 0.28 | F14: Penyeimbang ke 100%
A15: TOTAL | D15: =SUM(D6:D14) -> 1 | E15: =SUM(E6:E14) -> 2 | F15: Cek: % = 100%, kg = bobot hidup

Sheet I_Sales_History
A1: I_Sales_History — Penjualan Harian per SKU (kg)
A2: Data aktual (dummy pada skeleton). Flag "Stockout" = hari kehabisan stok → DIKECUALIKAN dari demand rate (censored).
A3: Tanggal | B3: SKU Code | C3: SKU Name | D3: Qty Sold (kg) | E3: Stockout Flag | F3: Notes
A4: 46174 | B4: BLD | C4: Boneless Dada (fillet) | D4: 319.3 | E4: Normal
A5: 46174 | B5: BLP | C5: Boneless Paha (fillet) | D5: 215.5 | E5: Normal
A6: 46174 | B6: SYP | C6: Sayap | D6: 141.2 | E6: Normal
A7: 46174 | B7: CKR | C7: Ceker | D7: 60.2 | E7: Normal
A8: 46174 | B8: KPL | C8: Kepala | D8: 28.2 | E8: Normal
A9: 46174 | B9: KLT | C9: Kulit | D9: 58.5 | E9: Normal
A10: 46174 | B10: JRN | C10: Jeroan (ati ampela) | D10: 53.6 | E10: Normal
A11: 46174 | B11: TLG | C11: Tulang / carcass frame | D11: 185.9 | E11: Normal
A12: 46175 | B12: BLD | C12: Boneless Dada (fillet) | D12: 310.7 | E12: Normal
A13: 46175 | B13: BLP | C13: Boneless Paha (fillet) | D13: 215.9 | E13: Normal
A14: 46175 | B14: SYP | C14: Sayap | D14: 142.1 | E14: Normal
A15: 46175 | B15: CKR | C15: Ceker | D15: 61 | E15: Normal
... A43: 46178 | B43: TLG | C43: Tulang / carcass frame | D43: 202.4 | E43: Normal
A44: 46179 | B44: BLD | C44: Boneless Dada (fillet) | D44: 187 | E44: Stockout | F44: Habis stok siang
A45: 46179 | B45: BLP | C45: Boneless Paha (fillet) | D45: 269.5 | E45: Normal
A46: 46179 | B46: SYP | C46: Sayap | D46: 181.6 | E46: Normal
A47: 46179 | B47: CKR | C47: Ceker | D47: 76.7 | E47: Normal
A48: 46179 | B48: KPL | C48: Kepala | D48: 37.8 | E48: Normal
A49: 46179 | B49: KLT | C49: Kulit | D49: 86.4 | E49: Normal
A50: 46179 | B50: JRN | C50: Jeroan (ati ampela) | D50: 69.4 | E50: Normal
A51: 46179 | B51: TLG | C51: Tulang / carcass frame | D51: 249.2 | E51: Normal
A52: 46180 | B52: BLD | C52: Boneless Dada (fillet) | D52: 371.4 | E52: Normal
A53: 46180 | B53: BLP | C53: Boneless Paha (fillet) | D53: 249.3 | E53: Normal
A54: 46180 | B54: SYP | C54: Sayap | D54: 166 | E54: Normal
A55: 46180 | B55: CKR | C55: Ceker | D55: 71.8 | E55: Normal
A56: 46180 | B56: KPL | C56: Kepala | D56: 33.8 | E56: Normal
... A99: 46185 | B99: TLG | C99: Tulang / carcass frame | D99: 226.7 | E99: Normal
A100: 46186 | B100: BLD | C100: Boneless Dada (fillet) | D100: 187 | E100: Stockout | F100: Habis stok siang
A101: 46186 | B101: BLP | C101: Boneless Paha (fillet) | D101: 275.3 | E101: Normal
A102: 46186 | B102: SYP | C102: Sayap | D102: 208.1 | E102: Normal
A103: 46186 | B103: CKR | C103: Ceker | D103: 69.9 | E103: Normal
A104: 46186 | B104: KPL | C104: Kepala | D104: 40.6 | E104: Normal
A105: 46186 | B105: KLT | C105: Kulit | D105: 84.8 | E105: Normal
A106: 46186 | B106: JRN | C106: Jeroan (ati ampela) | D106: 63.3 | E106: Normal
A107: 46186 | B107: TLG | C107: Tulang / carcass frame | D107: 218.3 | E107: Normal
A108: 46187 | B108: BLD | C108: Boneless Dada (fillet) | D108: 386.3 | E108: Normal
A109: 46187 | B109: BLP | C109: Boneless Paha (fillet) | D109: 294.6 | E109: Normal
...

Sheet I_Market_Intelligence
A1: I_Market_Intelligence — Judgment Interface (seasonality & event)
A2: Sheet yang diisi Head of Sales. Semua angka kuning = override pengetahuan pasar.
A3: SECTION 1 — SEASONALITY HARI (berlaku semua potongan)
A4: Index: 1.00 = rata-rata. 1.15 = 15% di atas, 0.85 = 15% di bawah.
A5: Hari | B5: Seasonality Index
A6: Monday | B6: 0.95
A7: Tuesday | B7: 0.93
A8: Wednesday | B8: 0.95
A9: Thursday | B9: 1
A10: Friday | B10: 1.1
A11: Saturday | B11: 1.2
A12: Sunday | B12: 1.15
A14: SECTION 2 — OVERRIDE HARI LIBUR / RAMADAN / LEBARAN
A15: Lebaran ikut kalender Hijriah (geser ~11 hari/thn) → harus disuntik manual, model tak bisa pelajari dari data pendek.
A16: Tanggal | B16: Uplift Factor | C16: Catatan
A17: 46466 | B17: 1.35 | C17: Contoh: H-2 Lebaran (di luar window skeleton)

Sheet I_MEV
A1: I_MEV — Driver Makro (overlay OFF sampai Granger-validated)
A2: Variabel relevan untuk ayam. Proyeksi = TBC.
A3: Variabel | B3: Unit | C3: Nilai Terbaru | D3: Sumber | E3: Proj Bear | F3: Proj Base | G3: Proj Bull
A4: Harga jagung (pakan) | B4: IDR/kg | C4: TBC | D4: BPS / BI / pasar | E4: TBC | F4: TBC | G4: TBC
A5: Harga DOC | B5: IDR/ekor | C5: TBC | D5: BPS / BI / pasar | E5: TBC | F5: TBC | G5: TBC
A6: Harga ayam hidup | B6: IDR/kg | C6: TBC | D6: BPS / BI / pasar | E6: TBC | F6: TBC | G6: TBC
A7: CPI Pangan | B7: index | C7: TBC | D7: BPS / BI / pasar | E7: TBC | F7: TBC | G7: TBC
A8: BI Rate | B8: % | C8: TBC | D8: BPS / BI / pasar | E8: TBC | F8: TBC | G8: TBC

Sheet O_Demand_Rate
A1: O_Demand_Rate — Demand Rate Historis per SKU (censored)
A2: Avg harian DIHITUNG HANYA dari hari "Normal" → koreksi censored demand (stockout tak menyeret rata-rata turun).
A3: SKU Code | B3: SKU Name | C3: Avg Daily Demand (kg, hari Normal) | D3: Hari Tercatat | E3: Hari Stockout | F3: Manual WoW Trend % | G3: Notes
A4: BLD | B4: Boneless Dada (fillet) | C4: =IFERROR(AVERAGEIFS(I_Sales_History!$D:$D,I_Sales_History!$B:$B,A4,I_Sales_History!$E:$E,"Normal"),0) -> 348.65263 | D4: =COUNTIFS(I_Sales_History!$B:$B,A4) -> 21 | E4: =COUNTIFS(I_Sales_History!$B:$B,A4,I_Sales_History!$E:$E,"Stockout") -> 2 | F4: 0 | G4: Stockout dikecualikan
A5: BLP | B5: Boneless Paha (fillet) | C5: =IFERROR(AVERAGEIFS(I_Sales_History!$D:$D,I_Sales_History!$B:$B,A5,I_Sales_History!$E:$E,"Normal"),0) -> 239.15238 | D5: =COUNTIFS(I_Sales_History!$B:$B,A5) -> 21 | E5: =COUNTIFS(I_Sales_History!$B:$B,A5,I_Sales_History!$E:$E,"Stockout") -> 0 | F5: 0
A6: SYP | B6: Sayap | C6: =IFERROR(AVERAGEIFS(I_Sales_History!$D:$D,I_Sales_History!$B:$B,A6,I_Sales_History!$E:$E,"Normal"),0) -> 157.5619 | D6: =COUNTIFS(I_Sales_History!$B:$B,A6) -> 21 | E6: =COUNTIFS(I_Sales_History!$B:$B,A6,I_Sales_History!$E:$E,"Stockout") -> 0 | F6: 0
A7: CKR | B7: Ceker | C7: =IFERROR(AVERAGEIFS(I_Sales_History!$D:$D,I_Sales_History!$B:$B,A7,I_Sales_History!$E:$E,"Normal"),0) -> 63.585714 | D7: =COUNTIFS(I_Sales_History!$B:$B,A7) -> 21 | E7: =COUNTIFS(I_Sales_History!$B:$B,A7,I_Sales_History!$E:$E,"Stockout") -> 0 | F7: 0
A8: KPL | B8: Kepala | C8: =IFERROR(AVERAGEIFS(I_Sales_History!$D:$D,I_Sales_History!$B:$B,A8,I_Sales_History!$E:$E,"Normal"),0) -> 31.709524 | D8: =COUNTIFS(I_Sales_History!$B:$B,A8) -> 21 | E8: =COUNTIFS(I_Sales_History!$B:$B,A8,I_Sales_History!$E:$E,"Stockout") -> 0 | F8: 0
A9: KLT | B9: Kulit | C9: =IFERROR(AVERAGEIFS(I_Sales_History!$D:$D,I_Sales_History!$B:$B,A9,I_Sales_History!$E:$E,"Normal"),0) -> 72.828571 | D9: =COUNTIFS(I_Sales_History!$B:$B,A9) -> 21 | E9: =COUNTIFS(I_Sales_History!$B:$B,A9,I_Sales_History!$E:$E,"Stockout") -> 0 | F9: 0
A10: JRN | B10: Jeroan (ati ampela) | C10: =IFERROR(AVERAGEIFS(I_Sales_History!$D:$D,I_Sales_History!$B:$B,A10,I_Sales_History!$E:$E,"Normal"),0) -> 58.519048 | D10: =COUNTIFS(I_Sales_History!$B:$B,A10) -> 21 | E10: =COUNTIFS(I_Sales_History!$B:$B,A10,I_Sales_History!$E:$E,"Stockout") -> 0 | F10: 0
A11: TLG | B11: Tulang / carcass frame | C11: =IFERROR(AVERAGEIFS(I_Sales_History!$D:$D,I_Sales_History!$B:$B,A11,I_Sales_History!$E:$E,"Normal"),0) -> 209.32381 | D11: =COUNTIFS(I_Sales_History!$B:$B,A11) -> 21 | E11: =COUNTIFS(I_Sales_History!$B:$B,A11,I_Sales_History!$E:$E,"Stockout") -> 0 | F11: 0

Sheet O_Scenario_Multipliers
A1: O_Scenario_Multipliers — Multiplier Skenario per SKU
A3: SECTION 1 — ELASTISITAS TIER (spread skenario)
A4: Tier | B4: Bear Factor | C4: Bull Factor | D4: Makna
A5: Defensive | B5: 0.97 | C5: 1.03 | D5: Inelastis (tulang/stok)
A6: Neutral | B6: 0.93 | C6: 1.07 | D6: Default
A7: Cyclical | B7: 0.85 | C7: 1.15 | D7: Diskresioner (byproduct/ekspor)
A9: SECTION 1b — MULTIPLIER MEV GABUNGAN (Off = 1.000)
A10: Bear MEV | B10: =IF(I_Live_Bird!$B$17="On",1,1) -> 1
A11: Base MEV | B11: 1
A12: Bull MEV | B12: =IF(I_Live_Bird!$B$17="On",1,1) -> 1
A14: SECTION 2 — MULTIPLIER PER SKU
A15: SKU Code | B15: SKU Name | C15: Tier | D15: Bear | E15: Base | F15: Bull
A16: BLD | B16: Boneless Dada (fillet) | C16: =I_Products!$I$4 -> Neutral | D16: =IFERROR(VLOOKUP(C16,O_Scenario_Multipliers!$A$5:$C$7,2,FALSE()),1) -> 0.93 | E16: 1 | F16: =IFERROR(VLOOKUP(C16,O_Scenario_Multipliers!$A$5:$C$7,3,FALSE()),1) -> 1.07
A17: BLP | B17: Boneless Paha (fillet) | C17: =I_Products!$I$5 -> Neutral | D17: =IFERROR(VLOOKUP(C17,O_Scenario_Multipliers!$A$5:$C$7,2,FALSE()),1) -> 0.93 | E17: 1 | F17: =IFERROR(VLOOKUP(C17,O_Scenario_Multipliers!$A$5:$C$7,3,FALSE()),1) -> 1.07
A18: SYP | B18: Sayap | C18: =I_Products!$I$6 -> Neutral | D18: =IFERROR(VLOOKUP(C18,O_Scenario_Multipliers!$A$5:$C$7,2,FALSE()),1) -> 0.93 | E18: 1 | F18: =IFERROR(VLOOKUP(C18,O_Scenario_Multipliers!$A$5:$C$7,3,FALSE()),1) -> 1.07
A19: CKR | B19: Ceker | C19: =I_Products!$I$7 -> Cyclical | D19: =IFERROR(VLOOKUP(C19,O_Scenario_Multipliers!$A$5:$C$7,2,FALSE()),1) -> 0.85 | E19: 1 | F19: =IFERROR(VLOOKUP(C19,O_Scenario_Multipliers!$A$5:$C$7,3,FALSE()),1) -> 1.15
A20: KPL | B20: Kepala | C20: =I_Products!$I$8 -> Cyclical | D20: =IFERROR(VLOOKUP(C20,O_Scenario_Multipliers!$A$5:$C$7,2,FALSE()),1) -> 0.85 | E20: 1 | F20: =IFERROR(VLOOKUP(C20,O_Scenario_Multipliers!$A$5:$C$7,3,FALSE()),1) -> 1.15
A21: KLT | B21: Kulit | C21: =I_Products!$I$9 -> Cyclical | D21: =IFERROR(VLOOKUP(C21,O_Scenario_Multipliers!$A$5:$C$7,2,FALSE()),1) -> 0.85 | E21: 1 | F21: =IFERROR(VLOOKUP(C21,O_Scenario_Multipliers!$A$5:$C$7,3,FALSE()),1) -> 1.15
A22: JRN | B22: Jeroan (ati ampela) | C22: =I_Products!$I$10 -> Cyclical | D22: =IFERROR(VLOOKUP(C22,O_Scenario_Multipliers!$A$5:$C$7,2,FALSE()),1) -> 0.85 | E22: 1 | F22: =IFERROR(VLOOKUP(C22,O_Scenario_Multipliers!$A$5:$C$7,3,FALSE()),1) -> 1.15
A23: TLG | B23: Tulang / carcass frame | C23: =I_Products!$I$11 -> Defensive | D23: =IFERROR(VLOOKUP(C23,O_Scenario_Multipliers!$A$5:$C$7,2,FALSE()),1) -> 0.97 | E23: 1 | F23: =IFERROR(VLOOKUP(C23,O_Scenario_Multipliers!$A$5:$C$7,3,FALSE()),1) -> 1.03

Sheet O_Monte_Carlo
A1: O_Monte_Carlo — Band Probabilistik per SKU
A2: P10/P50/P90 deterministik via NORMINV (stabil, tak volatile). Untuk simulasi penuh jalankan di Python (scipy).
A3: SKU Code | B3: SKU Name | C3: Avg Daily (kg) | D3: CV % | E3: Std Dev | F3: P10 (kg) | G3: P90 (kg)
A4: BLD | B4: Boneless Dada (fillet) | C4: =O_Demand_Rate!$C$4 -> 348.65263 | D4: 0.12 | E4: =C4*D4 -> 41.838316 | F4: =IFERROR(NORMINV(0.1,C4,E4),0) -> 295.03467 | G4: =IFERROR(NORMINV(0.9,C4,E4),0) -> 402.27059
A5: BLP | B5: Boneless Paha (fillet) | C5: =O_Demand_Rate!$C$5 -> 239.15238 | D5: 0.12 | E5: =C5*D5 -> 28.698286 | F5: =IFERROR(NORMINV(0.1,C5,E5),0) -> 202.37405 | G5: =IFERROR(NORMINV(0.9,C5,E5),0) -> 275.93071
A6: SYP | B6: Sayap | C6: =O_Demand_Rate!$C$6 -> 157.5619 | D6: 0.12 | E6: =C6*D6 -> 18.907429 | F6: =IFERROR(NORMINV(0.1,C6,E6),0) -> 133.33106 | G6: =IFERROR(NORMINV(0.9,C6,E6),0) -> 181.79275
A7: CKR | B7: Ceker | C7: =O_Demand_Rate!$C$7 -> 63.585714 | D7: 0.12 | E7: =C7*D7 -> 7.6302857 | F7: =IFERROR(NORMINV(0.1,C7,E7),0) -> 53.80711 | G7: =IFERROR(NORMINV(0.9,C7,E7),0) -> 73.364319
A8: KPL | B8: Kepala | C8: =O_Demand_Rate!$C$8 -> 31.709524 | D8: 0.12 | E8: =C8*D8 -> 3.8051429 | F8: =IFERROR(NORMINV(0.1,C8,E8),0) -> 26.833037 | G8: =IFERROR(NORMINV(0.9,C8,E8),0) -> 36.586011
A9: KLT | B9: Kulit | C9: =O_Demand_Rate!$C$9 -> 72.828571 | D9: 0.12 | E9: =C9*D9 -> 8.7394286 | F9: =IFERROR(NORMINV(0.1,C9,E9),0) -> 61.628543 | G9: =IFERROR(NORMINV(0.9,C9,E9),0) -> 84.0286
A10: JRN | B10: Jeroan (ati ampela) | C10: =O_Demand_Rate!$C$10 -> 58.519048 | D10: 0.12 | E10: =C10*D10 -> 7.0222857 | F10: =IFERROR(NORMINV(0.1,C10,E10),0) -> 49.519626 | G10: =IFERROR(NORMINV(0.9,C10,E10),0) -> 67.518469
A11: TLG | B11: Tulang / carcass frame | C11: =O_Demand_Rate!$C$11 -> 209.32381 | D11: 0.12 | E11: =C11*D11 -> 25.118857 | F11: =IFERROR(NORMINV(0.1,C11,E11),0) -> 177.1327 | G11: =IFERROR(NORMINV(0.9,C11,E11),0) -> 241.51492

Sheet O_Granger_Test
A1: O_Granger_Test — Validasi MEV (PLACEHOLDER)
A2: Butuh ≥60 observasi bulanan seri eksternal (mis. indeks harga ayam/pakan). Jalankan grangercausalitytests, paste F/p di sini.
A3: MEV Variable | B3: Lag (bln) | C3: F-Stat | D3: P-Value | E3: Significant? | F3: Arah Kausal | G3: Notes
A4: Harga jagung | B4: 1 | C4: TBC | D4: TBC | E4: TBC
A5: Harga jagung | B5: 2 | C5: TBC | D5: TBC | E5: TBC
A6: Harga jagung | B6: 3 | C6: TBC | D6: TBC | E6: TBC
A7: Harga DOC | B7: 1 | C7: TBC | D7: TBC | E7: TBC
A8: Harga DOC | B8: 2 | C8: TBC | D8: TBC | E8: TBC
A9: Harga DOC | B9: 3 | C9: TBC | D9: TBC | E9: TBC
A10: Harga ayam hidup | B10: 1 | C10: TBC | D10: TBC | E10: TBC
A11: Harga ayam hidup | B11: 2 | C11: TBC | D11: TBC | E11: TBC
A12: Harga ayam hidup | B12: 3 | C12: TBC | D12: TBC | E12: TBC
A13: CPI Pangan | B13: 1 | C13: TBC | D13: TBC | E13: TBC
A14: CPI Pangan | B14: 2 | C14: TBC | D14: TBC | E14: TBC
A15: CPI Pangan | B15: 3 | C15: TBC | D15: TBC | E15: TBC
... A18: BI Rate | B18: 3 | C18: TBC | D18: TBC | E18: TBC

Sheet O_Demand_Forecast
A1: O_Demand_Forecast — LAYER 1: Forecast kg per SKU × Skenario (7 hari)
A2: Cell = base rate × seasonality(hari) × multiplier skenario × MEV × trend.
A4: Seasonality (×) | D4: =IFERROR(VLOOKUP(TEXT(D6,"dddd"),I_Market_Intelligence!$A$6:$B$12,2,FALSE()),1)*IFERROR(VLOOKUP(D6,I_Market_Intelligence!$A$17:$B$19,2,FALSE()),1) -> 0.93 | E4: =IFERROR(VLOOKUP(TEXT(E6,"dddd"),I_Market_Intelligence!$A$6:$B$12,2,FALSE()),1)*IFERROR(VLOOKUP(E6,I_Market_Intelligence!$A$17:$B$19,2,FALSE()),1) -> 0.95 | F4: =IFERROR(VLOOKUP(TEXT(F6,"dddd"),I_Market_Intelligence!$A$6:$B$12,2,FALSE()),1)*IFERROR(VLOOKUP(F6,I_Market_Intelligence!$A$17:$B$19,2,FALSE()),1) -> 1 | G4: =IFERROR(VLOOKUP(TEXT(G6,"dddd"),I_Market_Intelligence!$A$6:$B$12,2,FALSE()),1)*IFERROR(VLOOKUP(G6,I_Market_Intelligence!$A$17:$B$19,2,FALSE()),1) -> 1.1 | H4: =IFERROR(VLOOKUP(TEXT(H6,"dddd"),I_Market_Intelligence!$A$6:$B$12,2,FALSE()),1)*IFERROR(VLOOKUP(H6,I_Market_Intelligence!$A$17:$B$19,2,FALSE()),1) -> 1.2 | I4: =IFERROR(VLOOKUP(TEXT(I6,"dddd"),I_Market_Intelligence!$A$6:$B$12,2,FALSE()),1)*IFERROR(VLOOKUP(I6,I_Market_Intelligence!$A$17:$B$19,2,FALSE()),1) -> 1.15 | J4: =IFERROR(VLOOKUP(TEXT(J6,"dddd"),I_Market_Intelligence!$A$6:$B$12,2,FALSE()),1)*IFERROR(VLOOKUP(J6,I_Market_Intelligence!$A$17:$B$19,2,FALSE()),1) -> 0.95
A5: Hari | D5: =TEXT(D6,"dddd") -> Tuesday | E5: =TEXT(E6,"dddd") -> Wednesday | F5: =TEXT(F6,"dddd") -> Thursday | G5: =TEXT(G6,"dddd") -> Friday | H5: =TEXT(H6,"dddd") -> Saturday | I5: =TEXT(I6,"dddd") -> Sunday | J5: =TEXT(J6,"dddd") -> Monday
A6: SKU Code | B6: SKU Name | C6: Scenario | D6: 46196 | E6: 46197 | F6: 46198 | G6: 46199 | H6: 46200 | I6: 46201 | J6: 46202 | K6: 7-Hari Total (kg)
A7: BLD | B7: Boneless Dada (fillet) | C7: Bear | D7: =ROUND(O_Demand_Rate!$C$4*D$4*O_Scenario_Multipliers!$D$16*O_Scenario_Multipliers!$B$10*(IF(I_Live_Bird!$B$15="Flat",1,1+MAX(MIN(O_Demand_Rate!$F$4,I_Live_Bird!$B$16),-I_Live_Bird!$B$16))),1) -> 301.5 | E7: =ROUND(O_Demand_Rate!$C$4*E$4*O_Scenario_Multipliers!$D$16*O_Scenario_Multipliers!$B$10*(IF(I_Live_Bird!$B$15="Flat",1,1+MAX(MIN(O_Demand_Rate!$F$4,I_Live_Bird!$B$16),-I_Live_Bird!$B$16))),1) -> 308 | F7: =ROUND(O_Demand_Rate!$C$4*F$4*O_Scenario_Multipliers!$D$16*O_Scenario_Multipliers!$B$10*(IF(I_Live_Bird!$B$15="Flat",1,1+MAX(MIN(O_Demand_Rate!$F$4,I_Live_Bird!$B$16),-I_Live_Bird!$B$16))),1) -> 324.2 | G7: =ROUND(O_Demand_Rate!$C$4*G$4*O_Scenario_Multipliers!$D$16*O_Scenario_Multipliers!$B$10*(IF(I_Live_Bird!$B$15="Flat",1,1+MAX(MIN(O_Demand_Rate!$F$4,I_Live_Bird!$B$16),-I_Live_Bird!$B$16))),1) -> 356.7 | H7: =ROUND(O_Demand_Rate!$C$4*H$4*O_Scenario_Multipliers!$D$16*O_Scenario_Multipliers!$B$10*(IF(I_Live_Bird!$B$15="Flat",1,1+MAX(MIN(O_Demand_Rate!$F$4,I_Live_Bird!$B$16),-I_Live_Bird!$B$16))),1) -> 389.1 | I7: =ROUND(O_Demand_Rate!$C$4*I$4*O_Scenario_Multipliers!$D$16*O_Scenario_Multipliers!$B$10*(IF(I_Live_Bird!$B$15="Flat",1,1+MAX(MIN(O_Demand_Rate!$F$4,I_Live_Bird!$B$16),-I_Live_Bird!$B$16))),1) -> 372.9 | J7: =ROUND(O_Demand_Rate!$C$4*J$4*O_Scenario_Multipliers!$D$16*O_Scenario_Multipliers!$B$10*(IF(I_Live_Bird!$B$15="Flat",1,1+MAX(MIN(O_Demand_Rate!$F$4,I_Live_Bird!$B$16),-I_Live_Bird!$B$16))),1) -> 308 | K7: =SUM(D7:J7) -> 2360.4
A8: BLD | B8: Boneless Dada (fillet) | C8: Base | D8: =ROUND(O_Demand_Rate!$C$4*D$4*O_Scenario_Multipliers!$E$16*O_Scenario_Multipliers!$B$11*(IF(I_Live_Bird!$B$15="Flat",1,1+MAX(MIN(O_Demand_Rate!$F$4,I_Live_Bird!$B$16),-I_Live_Bird!$B$16))),1) -> 324.2 | E8: =ROUND(O_Demand_Rate!$C$4*E$4*O_Scenario_Multipliers!$E$16*O_Scenario_Multipliers!$B$11*(IF(I_Live_Bird!$B$15="Flat",1,1+MAX(MIN(O_Demand_Rate!$F$4,I_Live_Bird!$B$16),-I_Live_Bird!$B$16))),1) -> 331.2 | F8: =ROUND(O_Demand_Rate!$C$4*F$4*O_Scenario_Multipliers!$E$16*O_Scenario_Multipliers!$B$11*(IF(I_Live_Bird!$B$15="Flat",1,1+MAX(MIN(O_Demand_Rate!$F$4,I_Live_Bird!$B$16),-I_Live_Bird!$B$16))),1) -> 348.7 | G8: =ROUND(O_Demand_Rate!$C$4*G$4*O_Scenario_Multipliers!$E$16*O_Scenario_Multipliers!$B$11*(IF(I_Live_Bird!$B$15="Flat",1,1+MAX(MIN(O_Demand_Rate!$F$4,I_Live_Bird!$B$16),-I_Live_Bird!$B$16))),1) -> 383.5 | H8: =ROUND(O_Demand_Rate!$C$4*H$4*O_Scenario_Multipliers!$E$16*O_Scenario_Multipliers!$B$11*(IF(I_Live_Bird!$B$15="Flat",1,1+MAX(MIN(O_Demand_Rate!$F$4,I_Live_Bird!$B$16),-I_Live_Bird!$B$16))),1) -> 418.4 | I8: =ROUND(O_Demand_Rate!$C$4*I$4*O_Scenario_Multipliers!$E$16*O_Scenario_Multipliers!$B$11*(IF(I_Live_Bird!$B$15="Flat",1,1+MAX(MIN(O_Demand_Rate!$F$4,I_Live_Bird!$B$16),-I_Live_Bird!$B$16))),1) -> 401 | J8: =ROUND(O_Demand_Rate!$C$4*J$4*O_Scenario_Multipliers!$E$16*O_Scenario_Multipliers!$B$11*(IF(I_Live_Bird!$B$15="Flat",1,1+MAX(MIN(O_Demand_Rate!$F$4,I_Live_Bird!$B$16),-I_Live_Bird!$B$16))),1) -> 331.2 | K8: =SUM(D8:J8) -> 2538.2
A9: BLD | B9: Boneless Dada (fillet) | C9: Bull | D9: =ROUND(O_Demand_Rate!$C$4*D$4*O_Scenario_Multipliers!$F$16*O_Scenario_Multipliers!$B$12*(IF(I_Live_Bird!$B$15="Flat",1,1+MAX(MIN(O_Demand_Rate!$F$4,I_Live_Bird!$B$16),-I_Live_Bird!$B$16))),1) -> 346.9 | E9: =ROUND(O_Demand_Rate!$C$4*E$4*O_Scenario_Multipliers!$F$16*O_Scenario_Multipliers!$B$12*(IF(I_Live_Bird!$B$15="Flat",1,1+MAX(MIN(O_Demand_Rate!$F$4,I_Live_Bird!$B$16),-I_Live_Bird!$B$16))),1) -> 354.4 | F9: =ROUND(O_Demand_Rate!$C$4*F$4*O_Scenario_Multipliers!$F$16*O_Scenario_Multipliers!$B$12*(IF(I_Live_Bird!$B$15="Flat",1,1+MAX(MIN(O_Demand_Rate!$F$4,I_Live_Bird!$B$16),-I_Live_Bird!$B$16))),1) -> 373.1 | G9: =ROUND(O_Demand_Rate!$C$4*G$4*O_Scenario_Multipliers!$F$16*O_Scenario_Multipliers!$B$12*(IF(I_Live_Bird!$B$15="Flat",1,1+MAX(MIN(O_Demand_Rate!$F$4,I_Live_Bird!$B$16),-I_Live_Bird!$B$16))),1) -> 410.4 | H9: =ROUND(O_Demand_Rate!$C$4*H$4*O_Scenario_Multipliers!$F$16*O_Scenario_Multipliers!$B$12*(IF(I_Live_Bird!$B$15="Flat",1,1+MAX(MIN(O_Demand_Rate!$F$4,I_Live_Bird!$B$16),-I_Live_Bird!$B$16))),1) -> 447.7 | I9: =ROUND(O_Demand_Rate!$C$4*I$4*O_Scenario_Multipliers!$F$16*O_Scenario_Multipliers!$B$12*(IF(I_Live_Bird!$B$15="Flat",1,1+MAX(MIN(O_Demand_Rate!$F$4,I_Live_Bird!$B$16),-I_Live_Bird!$B$16))),1) -> 429 | J9: =ROUND(O_Demand_Rate!$C$4*J$4*O_Scenario_Multipliers!$F$16*O_Scenario_Multipliers!$B$12*(IF(I_Live_Bird!$B$15="Flat",1,1+MAX(MIN(O_Demand_Rate!$F$4,I_Live_Bird!$B$16),-I_Live_Bird!$B$16))),1) -> 354.4 | K9: =SUM(D9:J9) -> 2715.9
A10: BLP | B10: Boneless Paha (fillet) | C10: Bear | D10: =ROUND(O_Demand_Rate!$C$5*D$4*O_Scenario_Multipliers!$D$17*O_Scenario_Multipliers!$B$10*(IF(I_Live_Bird!$B$15="Flat",1,1+MAX(MIN(O_Demand_Rate!$F$5,I_Live_Bird!$B$16),-I_Live_Bird!$B$16))),1) -> 206.8 | E10: =ROUND(O_Demand_Rate!$C$5*E$4*O_Scenario_Multipliers!$D$17*O_Scenario_Multipliers!$B$10*(IF(I_Live_Bird!$B$15="Flat",1,1+MAX(MIN(O_Demand_Rate!$F$5,I_Live_Bird!$B$16),-I_Live_Bird!$B$16))),1) -> 211.3 | F10: =ROUND(O_Demand_Rate!$C$5*F$4*O_Scenario_Multipliers!$D$17*O_Scenario_Multipliers!$B$10*(IF(I_Live_Bird!$B$15="Flat",1,1+MAX(MIN(O_Demand_Rate!$F$5,I_Live_Bird!$B$16),-I_Live_Bird!$B$16))),1) -> 222.4 | G10: =ROUND(O_Demand_Rate!$C$5*G$4*O_Scenario_Multipliers!$D$17*O_Scenario_Multipliers!$B$10*(IF(I_Live_Bird!$B$15="Flat",1,1+MAX(MIN(O_Demand_Rate!$F$5,I_Live_Bird!$B$16),-I_Live_Bird!$B$16))),1) -> 244.7 | H10: =ROUND(O_Demand_Rate!$C$5*H$4*O_Scenario_Multipliers!$D$17*O_Scenario_Multipliers!$B$10*(IF(I_Live_Bird!$B$15="Flat",1,1+MAX(MIN(O_Demand_Rate!$F$5,I_Live_Bird!$B$16),-I_Live_Bird!$B$16))),1) -> 266.9 | I10: =ROUND(O_Demand_Rate!$C$5*I$4*O_Scenario_Multipliers!$D$17*O_Scenario_Multipliers!$B$10*(IF(I_Live_Bird!$B$15="Flat",1,1+MAX(MIN(O_Demand_Rate!$F$5,I_Live_Bird!$B$16),-I_Live_Bird!$B$16))),1) -> 255.8 | J10: =ROUND(O_Demand_Rate!$C$5*J$4*O_Scenario_Multipliers!$D$17*O_Scenario_Multipliers!$B$10*(IF(I_Live_Bird!$B$15="Flat",1,1+MAX(MIN(O_Demand_Rate!$F$5,I_Live_Bird!$B$16),-I_Live_Bird!$B$16))),1) -> 211.3 | K10: =SUM(D10:J10) -> 1619.2
A11: BLP | B11: Boneless Paha (fillet) | C11: Base | D11: =ROUND(O_Demand_Rate!$C$5*D$4*O_Scenario_Multipliers!$E$17*O_Scenario_Multipliers!$B$11*(IF(I_Live_Bird!$B$15="Flat",1,1+MAX(MIN(O_Demand_Rate!$F$5,I_Live_Bird!$B$16),-I_Live_Bird!$B$16))),1) -> 222.4 | E11: =ROUND(O_Demand_Rate!$C$5*E$4*O_Scenario_Multipliers!$E$17*O_Scenario_Multipliers!$B$11*(IF(I_Live_Bird!$B$15="Flat",1,1+MAX(MIN(O_Demand_Rate!$F$5,I_Live_Bird!$B$16),-I_Live_Bird!$B$16))),1) -> 227.2 | F11: =ROUND(O_Demand_Rate!$C$5*F$4*O_Scenario_Multipliers!$E$17*O_Scenario_Multipliers!$B$11*(IF(I_Live_Bird!$B$15="Flat",1,1+MAX(MIN(O_Demand_Rate!$F$5,I_Live_Bird!$B$16),-I_Live_Bird!$B$16))),1) -> 239.2 | G11: =ROUND(O_Demand_Rate!$C$5*G$4*O_Scenario_Multipliers!$E$17*O_Scenario_Multipliers!$B$11*(IF(I_Live_Bird!$B$15="Flat",1,1+MAX(MIN(O_Demand_Rate!$F$5,I_Live_Bird!$B$16),-I_Live_Bird!$B$16))),1) -> 263.1 | H11: =ROUND(O_Demand_Rate!$C$5*H$4*O_Scenario_Multipliers!$E$17*O_Scenario_Multipliers!$B$11*(IF(I_Live_Bird!$B$15="Flat",1,1+MAX(MIN(O_Demand_Rate!$F$5,I_Live_Bird!$B$16),-I_Live_Bird!$B$16))),1) -> 287 | I11: =ROUND(O_Demand_Rate!$C$5*I$4*O_Scenario_Multipliers!$E$17*O_Scenario_Multipliers!$B$11*(IF(I_Live_Bird!$B$15="Flat",1,1+MAX(MIN(O_Demand_Rate!$F$5,I_Live_Bird!$B$16),-I_Live_Bird!$B$16))),1) -> 275 | J11: =ROUND(O_Demand_Rate!$C$5*J$4*O_Scenario_Multipliers!$E$17*O_Scenario_Multipliers!$B$11*(IF(I_Live_Bird!$B$15="Flat",1,1+MAX(MIN(O_Demand_Rate!$F$5,I_Live_Bird!$B$16),-I_Live_Bird!$B$16))),1) -> 227.2 | K11: =SUM(D11:J11) -> 1741.1
A12: BLP | B12: Boneless Paha (fillet) | C12: Bull | D12: =ROUND(O_Demand_Rate!$C$5*D$4*O_Scenario_Multipliers!$F$17*O_Scenario_Multipliers!$B$12*(IF(I_Live_Bird!$B$15="Flat",1,1+MAX(MIN(O_Demand_Rate!$F$5,I_Live_Bird!$B$16),-I_Live_Bird!$B$16))),1) -> 238 | E12: =ROUND(O_Demand_Rate!$C$5*E$4*O_Scenario_Multipliers!$F$17*O_Scenario_Multipliers!$B$12*(IF(I_Live_Bird!$B$15="Flat",1,1+MAX(MIN(O_Demand_Rate!$F$5,I_Live_Bird!$B$16),-I_Live_Bird!$B$16))),1) -> 243.1 | F12: =ROUND(O_Demand_Rate!$C$5*F$4*O_Scenario_Multipliers!$F$17*O_Scenario_Multipliers!$B$12*(IF(I_Live_Bird!$B$15="Flat",1,1+MAX(MIN(O_Demand_Rate!$F$5,I_Live_Bird!$B$16),-I_Live_Bird!$B$16))),1) -> 255.9 | G12: =ROUND(O_Demand_Rate!$C$5*G$4*O_Scenario_Multipliers!$F$17*O_Scenario_Multipliers!$B$12*(IF(I_Live_Bird!$B$15="Flat",1,1+MAX(MIN(O_Demand_Rate!$F$5,I_Live_Bird!$B$16),-I_Live_Bird!$B$16))),1) -> 281.5 | H12: =ROUND(O_Demand_Rate!$C$5*H$4*O_Scenario_Multipliers!$F$17*O_Scenario_Multipliers!$B$12*(IF(I_Live_Bird!$B$15="Flat",1,1+MAX(MIN(O_Demand_Rate!$F$5,I_Live_Bird!$B$16),-I_Live_Bird!$B$16))),1) -> 307.1 | I12: =ROUND(O_Demand_Rate!$C$5*I$4*O_Scenario_Multipliers!$F$17*O_Scenario_Multipliers!$B$12*(IF(I_Live_Bird!$B$15="Flat",1,1+MAX(MIN(O_Demand_Rate!$F$5,I_Live_Bird!$B$16),-I_Live_Bird!$B$16))),1) -> 294.3 | J12: =ROUND(O_Demand_Rate!$C$5*J$4*O_Scenario_Multipliers!$F$17*O_Scenario_Multipliers!$B$12*(IF(I_Live_Bird!$B$15="Flat",1,1+MAX(MIN(O_Demand_Rate!$F$5,I_Live_Bird!$B$16),-I_Live_Bird!$B$16))),1) -> 243.1 | K12: =SUM(D12:J12) -> 1863
A13: SYP | B13: Sayap | C13: Bear | D13: =ROUND(O_Demand_Rate!$C$6*D$4*O_Scenario_Multipliers!$D$18*O_Scenario_Multipliers!$B$10*(IF(I_Live_Bird!$B$15="Flat",1,1+MAX(MIN(O_Demand_Rate!$F$6,I_Live_Bird!$B$16),-I_Live_Bird!$B$16))),1) -> 136.3 | E13: =ROUND(O_Demand_Rate!$C$6*E$4*O_Scenario_Multipliers!$D$18*O_Scenario_Multipliers!$B$10*(IF(I_Live_Bird!$B$15="Flat",1,1+MAX(MIN(O_Demand_Rate!$F$6,I_Live_Bird!$B$16),-I_Live_Bird!$B$16))),1) -> 139.2 | F13: =ROUND(O_Demand_Rate!$C$6*F$4*O_Scenario_Multipliers!$D$18*O_Scenario_Multipliers!$B$10*(IF(I_Live_Bird!$B$15="Flat",1,1+MAX(MIN(O_Demand_Rate!$F$6,I_Live_Bird!$B$16),-I_Live_Bird!$B$16))),1) -> 146.5 | G13: =ROUND(O_Demand_Rate!$C$6*G$4*O_Scenario_Multipliers!$D$18*O_Scenario_Multipliers!$B$10*(IF(I_Live_Bird!$B$15="Flat",1,1+MAX(MIN(O_Demand_Rate!$F$6,I_Live_Bird!$B$16),-I_Live_Bird!$B$16))),1) -> 161.2 | H13: =ROUND(O_Demand_Rate!$C$6*H$4*O_Scenario_Multipliers!$D$18*O_Scenario_Multipliers!$B$10*(IF(I_Live_Bird!$B$15="Flat",1,1+MAX(MIN(O_Demand_Rate!$F$6,I_Live_Bird!$B$16),-I_Live_Bird!$B$16))),1) -> 175.8 | I13: =ROUND(O_Demand_Rate!$C$6*I$4*O_Scenario_Multipliers!$D$18*O_Scenario_Multipliers!$B$10*(IF(I_Live_Bird!$B$15="Flat",1,1+MAX(MIN(O_Demand_Rate!$F$6,I_Live_Bird!$B$16),-I_Live_Bird!$B$16))),1) -> 168.5 | J13: =ROUND(O_Demand_Rate!$C$6*J$4*O_Scenario_Multipliers!$D$18*O_Scenario_Multipliers!$B$10*(IF(I_Live_Bird!$B$15="Flat",1,1+MAX(MIN(O_Demand_Rate!$F$6,I_Live_Bird!$B$16),-I_Live_Bird!$B$16))),1) -> 139.2 | K13: =SUM(D13:J13) -> 1066.7
A14: SYP | B14: Sayap | C14: Base | D14: =ROUND(O_Demand_Rate!$C$6*D$4*O_Scenario_Multipliers!$E$18*O_Scenario_Multipliers!$B$11*(IF(I_Live_Bird!$B$15="Flat",1,1+MAX(MIN(O_Demand_Rate!$F$6,I_Live_Bird!$B$16),-I_Live_Bird!$B$16))),1) -> 146.5 | E14: =ROUND(O_Demand_Rate!$C$6*E$4*O_Scenario_Multipliers!$E$18*O_Scenario_Multipliers!$B$11*(IF(I_Live_Bird!$B$15="Flat",1,1+MAX(MIN(O_Demand_Rate!$F$6,I_Live_Bird!$B$16),-I_Live_Bird!$B$16))),1) -> 149.7 | F14: =ROUND(O_Demand_Rate!$C$6*F$4*O_Scenario_Multipliers!$E$18*O_Scenario_Multipliers!$B$11*(IF(I_Live_Bird!$B$15="Flat",1,1+MAX(MIN(O_Demand_Rate!$F$6,I_Live_Bird!$B$16),-I_Live_Bird!$B$16))),1) -> 157.6 | G14: =ROUND(O_Demand_Rate!$C$6*G$4*O_Scenario_Multipliers!$E$18*O_Scenario_Multipliers!$B$11*(IF(I_Live_Bird!$B$15="Flat",1,1+MAX(MIN(O_Demand_Rate!$F$6,I_Live_Bird!$B$16),-I_Live_Bird!$B$16))),1) -> 173.3 | H14: =ROUND(O_Demand_Rate!$C$6*H$4*O_Scenario_Multipliers!$E$18*O_Scenario_Multipliers!$B$11*(IF(I_Live_Bird!$B$15="Flat",1,1+MAX(MIN(O_Demand_Rate!$F$6,I_Live_Bird!$B$16),-I_Live_Bird!$B$16))),1) -> 189.1 | I14: =ROUND(O_Demand_Rate!$C$6*I$4*O_Scenario_Multipliers!$E$18*O_Scenario_Multipliers!$B$11*(IF(I_Live_Bird!$B$15="Flat",1,1+MAX(MIN(O_Demand_Rate!$F$6,I_Live_Bird!$B$16),-I_Live_Bird!$B$16))),1) -> 181.2 | J14: =ROUND(O_Demand_Rate!$C$6*J$4*O_Scenario_Multipliers!$E$18*O_Scenario_Multipliers!$B$11*(IF(I_Live_Bird!$B$15="Flat",1,1+MAX(MIN(O_Demand_Rate!$F$6,I_Live_Bird!$B$16),-I_Live_Bird!$B$16))),1) -> 149.7 | K14: =SUM(D14:J14) -> 1147.1
A15: SYP | B15: Sayap | C15: Bull | D15: =ROUND(O_Demand_Rate!$C$6*D$4*O_Scenario_Multipliers!$F$18*O_Scenario_Multipliers!$B$12*(IF(I_Live_Bird!$B$15="Flat",1,1+MAX(MIN(O_Demand_Rate!$F$6,I_Live_Bird!$B$16),-I_Live_Bird!$B$16))),1) -> 156.8 | E15: =ROUND(O_Demand_Rate!$C$6*E$4*O_Scenario_Multipliers!$F$18*O_Scenario_Multipliers!$B$12*(IF(I_Live_Bird!$B$15="Flat",1,1+MAX(MIN(O_Demand_Rate!$F$6,I_Live_Bird!$B$16),-I_Live_Bird!$B$16))),1) -> 160.2 | F15: =ROUND(O_Demand_Rate!$C$6*F$4*O_Scenario_Multipliers!$F$18*O_Scenario_Multipliers!$B$12*(IF(I_Live_Bird!$B$15="Flat",1,1+MAX(MIN(O_Demand_Rate!$F$6,I_Live_Bird!$B$16),-I_Live_Bird!$B$16))),1) -> 168.6 | G15: =ROUND(O_Demand_Rate!$C$6*G$4*O_Scenario_Multipliers!$F$18*O_Scenario_Multipliers!$B$12*(IF(I_Live_Bird!$B$15="Flat",1,1+MAX(MIN(O_Demand_Rate!$F$6,I_Live_Bird!$B$16),-I_Live_Bird!$B$16))),1) -> 185.5 | H15: =ROUND(O_Demand_Rate!$C$6*H$4*O_Scenario_Multipliers!$F$18*O_Scenario_Multipliers!$B$12*(IF(I_Live_Bird!$B$15="Flat",1,1+MAX(MIN(O_Demand_Rate!$F$6,I_Live_Bird!$B$16),-I_Live_Bird!$B$16))),1) -> 202.3 | I15: =ROUND(O_Demand_Rate!$C$6*I$4*O_Scenario_Multipliers!$F$18*O_Scenario_Multipliers!$B$12*(IF(I_Live_Bird!$B$15="Flat",1,1+MAX(MIN(O_Demand_Rate!$F$6,I_Live_Bird!$B$16),-I_Live_Bird!$B$16))),1) -> 193.9 | J15: =ROUND(O_Demand_Rate!$C$6*J$4*O_Scenario_Multipliers!$F$18*O_Scenario_Multipliers!$B$12*(IF(I_Live_Bird!$B$15="Flat",1,1+MAX(MIN(O_Demand_Rate!$F$6,I_Live_Bird!$B$16),-I_Live_Bird!$B$16))),1) -> 160.2 | K15: =SUM(D15:J15) -> 1227.5
A16: CKR | B16: Ceker | C16: Bear | D16: =ROUND(O_Demand_Rate!$C$7*D$4*O_Scenario_Multipliers!$D$19*O_Scenario_Multipliers!$B$10*(IF(I_Live_Bird!$B$15="Flat",1,1+MAX(MIN(O_Demand_Rate!$F$7,I_Live_Bird!$B$16),-I_Live_Bird!$B$16))),1) -> 50.3 | E16: =ROUND(O_Demand_Rate!$C$7*E$4*O_Scenario_Multipliers!$D$19*O_Scenario_Multipliers!$B$10*(IF(I_Live_Bird!$B$15="Flat",1,1+MAX(MIN(O_Demand_Rate!$F$7,I_Live_Bird!$B$16),-I_Live_Bird!$B$16))),1) -> 51.3 | F16: =ROUND(O_Demand_Rate!$C$7*F$4*O_Scenario_Multipliers!$D$19*O_Scenario_Multipliers!$B$10*(IF(I_Live_Bird!$B$15="Flat",1,1+MAX(MIN(O_Demand_Rate!$F$7,I_Live_Bird!$B$16),-I_Live_Bird!$B$16))),1) -> 54 | G16: =ROUND(O_Demand_Rate!$C$7*G$4*O_Scenario_Multipliers!$D$19*O_Scenario_Multipliers!$B$10*(IF(I_Live_Bird!$B$15="Flat",1,1+MAX(MIN(O_Demand_Rate!$F$7,I_Live_Bird!$B$16),-I_Live_Bird!$B$16))),1) -> 59.5 | H16: =ROUND(O_Demand_Rate!$C$7*H$4*O_Scenario_Multipliers!$D$19*O_Scenario_Multipliers!$B$10*(IF(I_Live_Bird!$B$15="Flat",1,1+MAX(MIN(O_Demand_Rate!$F$7,I_Live_Bird!$B$16),-I_Live_Bird!$B$16))),1) -> 64.9 | I16: =ROUND(O_Demand_Rate!$C$7*I$4*O_Scenario_Multipliers!$D$19*O_Scenario_Multipliers!$B$10*(IF(I_Live_Bird!$B$15="Flat",1,1+MAX(MIN(O_Demand_Rate!$F$7,I_Live_Bird!$B$16),-I_Live_Bird!$B$16))),1) -> 62.2 | J16: =ROUND(O_Demand_Rate!$C$7*J$4*O_Scenario_Multipliers!$D$19*O_Scenario_Multipliers!$B$10*(IF(I_Live_Bird!$B$15="Flat",1,1+MAX(MIN(O_Demand_Rate!$F$7,I_Live_Bird!$B$16),-I_Live_Bird!$B$16))),1) -> 51.3 | K16: =SUM(D16:J16) -> 393.5
A17: CKR | B17: Ceker | C17: Base | D17: =ROUND(O_Demand_Rate!$C$7*D$4*O_Scenario_Multipliers!$E$19*O_Scenario_Multipliers!$B$11*(IF(I_Live_Bird!$B$15="Flat",1,1+MAX(MIN(O_Demand_Rate!$F$7,I_Live_Bird!$B$16),-I_Live_Bird!$B$16))),1) -> 59.1 | E17: =ROUND(O_Demand_Rate!$C$7*E$4*O_Scenario_Multipliers!$E$19*O_Scenario_Multipliers!$B$11*(IF(I_Live_Bird!$B$15="Flat",1,1+MAX(MIN(O_Demand_Rate!$F$7,I_Live_Bird!$B$16),-I_Live_Bird!$B$16))),1) -> 60.4 | F17: =ROUND(O_Demand_Rate!$C$7*F$4*O_Scenario_Multipliers!$E$19*O_Scenario_Multipliers!$B$11*(IF(I_Live_Bird!$B$15="Flat",1,1+MAX(MIN(O_Demand_Rate!$F$7,I_Live_Bird!$B$16),-I_Live_Bird!$B$16))),1) -> 63.6 | G17: =ROUND(O_Demand_Rate!$C$7*G$4*O_Scenario_Multipliers!$E$19*O_Scenario_Multipliers!$B$11*(IF(I_Live_Bird!$B$15="Flat",1,1+MAX(MIN(O_Demand_Rate!$F$7,I_Live_Bird!$B$16),-I_Live_Bird!$B$16))),1) -> 69.9 | H17: =ROUND(O_Demand_Rate!$C$7*H$4*O_Scenario_Multipliers!$E$19*O_Scenario_Multipliers!$B$11*(IF(I_Live_Bird!$B$15="Flat",1,1+MAX(MIN(O_Demand_Rate!$F$7,I_Live_Bird!$B$16),-I_Live_Bird!$B$16))),1) -> 76.3 | I17: =ROUND(O_Demand_Rate!$C$7*I$4*O_Scenario_Multipliers!$E$19*O_Scenario_Multipliers!$B$11*(IF(I_Live_Bird!$B$15="Flat",1,1+MAX(MIN(O_Demand_Rate!$F$7,I_Live_Bird!$B$16),-I_Live_Bird!$B$16))),1) -> 73.1 | J17: =ROUND(O_Demand_Rate!$C$7*J$4*O_Scenario_Multipliers!$E$19*O_Scenario_Multipliers!$B$11*(IF(I_Live_Bird!$B$15="Flat",1,1+MAX(MIN(O_Demand_Rate!$F$7,I_Live_Bird!$B$16),-I_Live_Bird!$B$16))),1) -> 60.4 | K17: =SUM(D17:J17) -> 462.8
A18: CKR | B18: Ceker | C18: Bull | D18: =ROUND(O_Demand_Rate!$C$7*D$4*O_Scenario_Multipliers!$F$19*O_Scenario_Multipliers!$B$12*(IF(I_Live_Bird!$B$15="Flat",1,1+MAX(MIN(O_Demand_Rate!$F$7,I_Live_Bird!$B$16),-I_Live_Bird!$B$16))),1) -> 68 | E18: =ROUND(O_Demand_Rate!$C$7*E$4*O_Scenario_Multipliers!$F$19*O_Scenario_Multipliers!$B$12*(IF(I_Live_Bird!$B$15="Flat",1,1+MAX(MIN(O_Demand_Rate!$F$7,I_Live_Bird!$B$16),-I_Live_Bird!$B$16))),1) -> 69.5 | F18: =ROUND(O_Demand_Rate!$C$7*F$4*O_Scenario_Multipliers!$F$19*O_Scenario_Multipliers!$B$12*(IF(I_Live_Bird!$B$15="Flat",1,1+MAX(MIN(O_Demand_Rate!$F$7,I_Live_Bird!$B$16),-I_Live_Bird!$B$16))),1) -> 73.1 | G18: =ROUND(O_Demand_Rate!$C$7*G$4*O_Scenario_Multipliers!$F$19*O_Scenario_Multipliers!$B$12*(IF(I_Live_Bird!$B$15="Flat",1,1+MAX(MIN(O_Demand_Rate!$F$7,I_Live_Bird!$B$16),-I_Live_Bird!$B$16))),1) -> 80.4 | H18: =ROUND(O_Demand_Rate!$C$7*H$4*O_Scenario_Multipliers!$F$19*O_Scenario_Multipliers!$B$12*(IF(I_Live_Bird!$B$15="Flat",1,1+MAX(MIN(O_Demand_Rate!$F$7,I_Live_Bird!$B$16),-I_Live_Bird!$B$16))),1) -> 87.7 | I18: =ROUND(O_Demand_Rate!$C$7*I$4*O_Scenario_Multipliers!$F$19*O_Scenario_Multipliers!$B$12*(IF(I_Live_Bird!$B$15="Flat",1,1+MAX(MIN(O_Demand_Rate!$F$7,I_Live_Bird!$B$16),-I_Live_Bird!$B$16))),1) -> 84.1 | J18: =ROUND(O_Demand_Rate!$C$7*J$4*O_Scenario_Multipliers!$F$19*O_Scenario_Multipliers!$B$12*(IF(I_Live_Bird!$B$15="Flat",1,1+MAX(MIN(O_Demand_Rate!$F$7,I_Live_Bird!$B$16),-I_Live_Bird!$B$16))),1) -> 69.5 | K18: =SUM(D18:J18) -> 532.3
A19: KPL | B19: Kepala | C19: Bear | D19: =ROUND(O_Demand_Rate!$C$8*D$4*O_Scenario_Multipliers!$D$20*O_Scenario_Multipliers!$B$10*(IF(I_Live_Bird!$B$15="Flat",1,1+MAX(MIN(O_Demand_Rate!$F$8,I_Live_Bird!$B$16),-I_Live_Bird!$B$16))),1) -> 25.1 | E19: =ROUND(O_Demand_Rate!$C$8*E$4*O_Scenario_Multipliers!$D$20*O_Scenario_Multipliers!$B$10*(IF(I_Live_Bird!$B$15="Flat",1,1+MAX(MIN(O_Demand_Rate!$F$8,I_Live_Bird!$B$16),-I_Live_Bird!$B$16))),1) -> 25.6 | F19: =ROUND(O_Demand_Rate!$C$8*F$4*O_Scenario_Multipliers!$D$20*O_Scenario_Multipliers!$B$10*(IF(I_Live_Bird!$B$15="Flat",1,1+MAX(MIN(O_Demand_Rate!$F$8,I_Live_Bird!$B$16),-I_Live_Bird!$B$16))),1) -> 27 | G19: =ROUND(O_Demand_Rate!$C$8*G$4*O_Scenario_Multipliers!$D$20*O_Scenario_Multipliers!$B$10*(IF(I_Live_Bird!$B$15="Flat",1,1+MAX(MIN(O_Demand_Rate!$F$8,I_Live_Bird!$B$16),-I_Live_Bird!$B$16))),1) -> 29.6 | H19: =ROUND(O_Demand_Rate!$C$8*H$4*O_Scenario_Multipliers!$D$20*O_Scenario_Multipliers!$B$10*(IF(I_Live_Bird!$B$15="Flat",1,1+MAX(MIN(O_Demand_Rate!$F$8,I_Live_Bird!$B$16),-I_Live_Bird!$B$16))),1) -> 32.3 | I19: =ROUND(O_Demand_Rate!$C$8*I$4*O_Scenario_Multipliers!$D$20*O_Scenario_Multipliers!$B$10*(IF(I_Live_Bird!$B$15="Flat",1,1+MAX(MIN(O_Demand_Rate!$F$8,I_Live_Bird!$B$16),-I_Live_Bird!$B$16))),1) -> 31 | J19: =ROUND(O_Demand_Rate!$C$8*J$4*O_Scenario_Multipliers!$D$20*O_Scenario_Multipliers!$B$10*(IF(I_Live_Bird!$B$15="Flat",1,1+MAX(MIN(O_Demand_Rate!$F$8,I_Live_Bird!$B$16),-I_Live_Bird!$B$16))),1) -> 25.6 | K19: =SUM(D19:J19) -> 196.2
A20: KPL | B20: Kepala | C20: Base | D20: =ROUND(O_Demand_Rate!$C$8*D$4*O_Scenario_Multipliers!$E$20*O_Scenario_Multipliers!$B$11*(IF(I_Live_Bird!$B$15="Flat",1,1+MAX(MIN(O_Demand_Rate!$F$8,I_Live_Bird!$B$16),-I_Live_Bird!$B$16))),1) -> 29.5 | E20: =ROUND(O_Demand_Rate!$C$8*E$4*O_Scenario_Multipliers!$E$20*O_Scenario_Multipliers!$B$11*(IF(I_Live_Bird!$B$15="Flat",1,1+MAX(MIN(O_Demand_Rate!$F$8,I_Live_Bird!$B$16),-I_Live_Bird!$B$16))),1) -> 30.1 | F20: =ROUND(O_Demand_Rate!$C$8*F$4*O_Scenario_Multipliers!$E$20*O_Scenario_Multipliers!$B$11*(IF(I_Live_Bird!$B$15="Flat",1,1+MAX(MIN(O_Demand_Rate!$F$8,I_Live_Bird!$B$16),-I_Live_Bird!$B$16))),1) -> 31.7 | G20: =ROUND(O_Demand_Rate!$C$8*G$4*O_Scenario_Multipliers!$E$20*O_Scenario_Multipliers!$B$11*(IF(I_Live_Bird!$B$15="Flat",1,1+MAX(MIN(O_Demand_Rate!$F$8,I_Live_Bird!$B$16),-I_Live_Bird!$B$16))),1) -> 34.9 | H20: =ROUND(O_Demand_Rate!$C$8*H$4*O_Scenario_Multipliers!$E$20*O_Scenario_Multipliers!$B$11*(IF(I_Live_Bird!$B$15="Flat",1,1+MAX(MIN(O_Demand_Rate!$F$8,I_Live_Bird!$B$16),-I_Live_Bird!$B$16))),1) -> 38.1 | I20: =ROUND(O_Demand_Rate!$C$8*I$4*O_Scenario_Multipliers!$E$20*O_Scenario_Multipliers!$B$11*(IF(I_Live_Bird!$B$15="Flat",1,1+MAX(MIN(O_Demand_Rate!$F$8,I_Live_Bird!$B$16),-I_Live_Bird!$B$16))),1) -> 36.5 | J20: =ROUND(O_Demand_Rate!$C$8*J$4*O_Scenario_Multipliers!$E$20*O_Scenario_Multipliers!$B$11*(IF(I_Live_Bird!$B$15="Flat",1,1+MAX(MIN(O_Demand_Rate!$F$8,I_Live_Bird!$B$16),-I_Live_Bird!$B$16))),1) -> 30.1 | K20: =SUM(D20:J20) -> 230.9
A21: KPL | B21: Kepala | C21: Bull | D21: =ROUND(O_Demand_Rate!$C$8*D$4*O_Scenario_Multipliers!$F$20*O_Scenario_Multipliers!$B$12*(IF(I_Live_Bird!$B$15="Flat",1,1+MAX(MIN(O_Demand_Rate!$F$8,I_Live_Bird!$B$16),-I_Live_Bird!$B$16))),1) -> 33.9 | E21: =ROUND(O_Demand_Rate!$C$8*E$4*O_Scenario_Multipliers!$F$20*O_Scenario_Multipliers!$B$12*(IF(I_Live_Bird!$B$15="Flat",1,1+MAX(MIN(O_Demand_Rate!$F$8,I_Live_Bird!$B$16),-I_Live_Bird!$B$16))),1) -> 34.6 | F21: =ROUND(O_Demand_Rate!$C$8*F$4*O_Scenario_Multipliers!$F$20*O_Scenario_Multipliers!$B$12*(IF(I_Live_Bird!$B$15="Flat",1,1+MAX(MIN(O_Demand_Rate!$F$8,I_Live_Bird!$B$16),-I_Live_Bird!$B$16))),1) -> 36.5 | G21: =ROUND(O_Demand_Rate!$C$8*G$4*O_Scenario_Multipliers!$F$20*O_Scenario_Multipliers!$B$12*(IF(I_Live_Bird!$B$15="Flat",1,1+MAX(MIN(O_Demand_Rate!$F$8,I_Live_Bird!$B$16),-I_Live_Bird!$B$16))),1) -> 40.1 | H21: =ROUND(O_Demand_Rate!$C$8*H$4*O_Scenario_Multipliers!$F$20*O_Scenario_Multipliers!$B$12*(IF(I_Live_Bird!$B$15="Flat",1,1+MAX(MIN(O_Demand_Rate!$F$8,I_Live_Bird!$B$16),-I_Live_Bird!$B$16))),1) -> 43.8 | I21: =ROUND(O_Demand_Rate!$C$8*I$4*O_Scenario_Multipliers!$F$20*O_Scenario_Multipliers!$B$12*(IF(I_Live_Bird!$B$15="Flat",1,1+MAX(MIN(O_Demand_Rate!$F$8,I_Live_Bird!$B$16),-I_Live_Bird!$B$16))),1) -> 41.9 | J21: =ROUND(O_Demand_Rate!$C$8*J$4*O_Scenario_Multipliers!$F$20*O_Scenario_Multipliers!$B$12*(IF(I_Live_Bird!$B$15="Flat",1,1+MAX(MIN(O_Demand_Rate!$F$8,I_Live_Bird!$B$16),-I_Live_Bird!$B$16))),1) -> 34.6 | K21: =SUM(D21:J21) -> 265.4
A22: KLT | B22: Kulit | C22: Bear | D22: =ROUND(O_Demand_Rate!$C$9*D$4*O_Scenario_Multipliers!$D$21*O_Scenario_Multipliers!$B$10*(IF(I_Live_Bird!$B$15="Flat",1,1+MAX(MIN(O_Demand_Rate!$F$9,I_Live_Bird!$B$16),-I_Live_Bird!$B$16))),1) -> 57.6 | E22: =ROUND(O_Demand_Rate!$C$9*E$4*O_Scenario_Multipliers!$D$21*O_Scenario_Multipliers!$B$10*(IF(I_Live_Bird!$B$15="Flat",1,1+MAX(MIN(O_Demand_Rate!$F$9,I_Live_Bird!$B$16),-I_Live_Bird!$B$16))),1) -> 58.8 | F22: =ROUND(O_Demand_Rate!$C$9*F$4*O_Scenario_Multipliers!$D$21*O_Scenario_Multipliers!$B$10*(IF(I_Live_Bird!$B$15="Flat",1,1+MAX(MIN(O_Demand_Rate!$F$9,I_Live_Bird!$B$16),-I_Live_Bird!$B$16))),1) -> 61.9 | G22: =ROUND(O_Demand_Rate!$C$9*G$4*O_Scenario_Multipliers!$D$21*O_Scenario_Multipliers!$B$10*(IF(I_Live_Bird!$B$15="Flat",1,1+MAX(MIN(O_Demand_Rate!$F$9,I_Live_Bird!$B$16),-I_Live_Bird!$B$16))),1) -> 68.1 | H22: =ROUND(O_Demand_Rate!$C$9*H$4*O_Scenario_Multipliers!$D$21*O_Scenario_Multipliers!$B$10*(IF(I_Live_Bird!$B$15="Flat",1,1+MAX(MIN(O_Demand_Rate!$F$9,I_Live_Bird!$B$16),-I_Live_Bird!$B$16))),1) -> 74.3 | I22: =ROUND(O_Demand_Rate!$C$9*I$4*O_Scenario_Multipliers!$D$21*O_Scenario_Multipliers!$B$10*(IF(I_Live_Bird!$B$15="Flat",1,1+MAX(MIN(O_Demand_Rate!$F$9,I_Live_Bird!$B$16),-I_Live_Bird!$B$16))),1) -> 71.2 | J22: =ROUND(O_Demand_Rate!$C$9*J$4*O_Scenario_Multipliers!$D$21*O_Scenario_Multipliers!$B$10*(IF(I_Live_Bird!$B$15="Flat",1,1+MAX(MIN(O_Demand_Rate!$F$9,I_Live_Bird!$B$16),-I_Live_Bird!$B$16))),1) -> 58.8 | K22: =SUM(D22:J22) -> 450.7
A23: KLT | B23: Kulit | C23: Base | D23: =ROUND(O_Demand_Rate!$C$9*D$4*O_Scenario_Multipliers!$E$21*O_Scenario_Multipliers!$B$11*(IF(I_Live_Bird!$B$15="Flat",1,1+MAX(MIN(O_Demand_Rate!$F$9,I_Live_Bird!$B$16),-I_Live_Bird!$B$16))),1) -> 67.7 | E23: =ROUND(O_Demand_Rate!$C$9*E$4*O_Scenario_Multipliers!$E$21*O_Scenario_Multipliers!$B$11*(IF(I_Live_Bird!$B$15="Flat",1,1+MAX(MIN(O_Demand_Rate!$F$9,I_Live_Bird!$B$16),-I_Live_Bird!$B$16))),1) -> 69.2 | F23: =ROUND(O_Demand_Rate!$C$9*F$4*O_Scenario_Multipliers!$E$21*O_Scenario_Multipliers!$B$11*(IF(I_Live_Bird!$B$15="Flat",1,1+MAX(MIN(O_Demand_Rate!$F$9,I_Live_Bird!$B$16),-I_Live_Bird!$B$16))),1) -> 72.8 | G23: =ROUND(O_Demand_Rate!$C$9*G$4*O_Scenario_Multipliers!$E$21*O_Scenario_Multipliers!$B$11*(IF(I_Live_Bird!$B$15="Flat",1,1+MAX(MIN(O_Demand_Rate!$F$9,I_Live_Bird!$B$16),-I_Live_Bird!$B$16))),1) -> 80.1 | H23: =ROUND(O_Demand_Rate!$C$9*H$4*O_Scenario_Multipliers!$E$21*O_Scenario_Multipliers!$B$11*(IF(I_Live_Bird!$B$15="Flat",1,1+MAX(MIN(O_Demand_Rate!$F$9,I_Live_Bird!$B$16),-I_Live_Bird!$B$16))),1) -> 87.4 | I23: =ROUND(O_Demand_Rate!$C$9*I$4*O_Scenario_Multipliers!$E$21*O_Scenario_Multipliers!$B$11*(IF(I_Live_Bird!$B$15="Flat",1,1+MAX(MIN(O_Demand_Rate!$F$9,I_Live_Bird!$B$16),-I_Live_Bird!$B$16))),1) -> 83.8 | J23: =ROUND(O_Demand_Rate!$C$9*J$4*O_Scenario_Multipliers!$E$21*O_Scenario_Multipliers!$B$11*(IF(I_Live_Bird!$B$15="Flat",1,1+MAX(MIN(O_Demand_Rate!$F$9,I_Live_Bird!$B$16),-I_Live_Bird!$B$16))),1) -> 69.2 | K23: =SUM(D23:J23) -> 530.2
A24: KLT | B24: Kulit | C24: Bull | D24: =ROUND(O_Demand_Rate!$C$9*D$4*O_Scenario_Multipliers!$F$21*O_Scenario_Multipliers!$B$12*(IF(I_Live_Bird!$B$15="Flat",1,1+MAX(MIN(O_Demand_Rate!$F$9,I_Live_Bird!$B$16),-I_Live_Bird!$B$16))),1) -> 77.9 | E24: =ROUND(O_Demand_Rate!$C$9*E$4*O_Scenario_Multipliers!$F$21*O_Scenario_Multipliers!$B$12*(IF(I_Live_Bird!$B$15="Flat",1,1+MAX(MIN(O_Demand_Rate!$F$9,I_Live_Bird!$B$16),-I_Live_Bird!$B$16))),1) -> 79.6 | F24: =ROUND(O_Demand_Rate!$C$9*F$4*O_Scenario_Multipliers!$F$21*O_Scenario_Multipliers!$B$12*(IF(I_Live_Bird!$B$15="Flat",1,1+MAX(MIN(O_Demand_Rate!$F$9,I_Live_Bird!$B$16),-I_Live_Bird!$B$16))),1) -> 83.8 | G24: =ROUND(O_Demand_Rate!$C$9*G$4*O_Scenario_Multipliers!$F$21*O_Scenario_Multipliers!$B$12*(IF(I_Live_Bird!$B$15="Flat",1,1+MAX(MIN(O_Demand_Rate!$F$9,I_Live_Bird!$B$16),-I_Live_Bird!$B$16))),1) -> 92.1 | H24: =ROUND(O_Demand_Rate!$C$9*H$4*O_Scenario_Multipliers!$F$21*O_Scenario_Multipliers!$B$12*(IF(I_Live_Bird!$B$15="Flat",1,1+MAX(MIN(O_Demand_Rate!$F$9,I_Live_Bird!$B$16),-I_Live_Bird!$B$16))),1) -> 100.5 | I24: =ROUND(O_Demand_Rate!$C$9*I$4*O_Scenario_Multipliers!$F$21*O_Scenario_Multipliers!$B$12*(IF(I_Live_Bird!$B$15="Flat",1,1+MAX(MIN(O_Demand_Rate!$F$9,I_Live_Bird!$B$16),-I_Live_Bird!$B$16))),1) -> 96.3 | J24: =ROUND(O_Demand_Rate!$C$9*J$4*O_Scenario_Multipliers!$F$21*O_Scenario_Multipliers!$B$12*(IF(I_Live_Bird!$B$15="Flat",1,1+MAX(MIN(O_Demand_Rate!$F$9,I_Live_Bird!$B$16),-I_Live_Bird!$B$16))),1) -> 79.6 | K24: =SUM(D24:J24) -> 609.8
A25: JRN | B25: Jeroan (ati ampela) | C25: Bear | D25: =ROUND(O_Demand_Rate!$C$10*D$4*O_Scenario_Multipliers!$D$22*O_Scenario_Multipliers!$B$10*(IF(I_Live_Bird!$B$15="Flat",1,1+MAX(MIN(O_Demand_Rate!$F$10,I_Live_Bird!$B$16),-I_Live_Bird!$B$16))),1) -> 46.3 | E25: =ROUND(O_Demand_Rate!$C$10*E$4*O_Scenario_Multipliers!$D$22*O_Scenario_Multipliers!$B$10*(IF(I_Live_Bird!$B$15="Flat",1,1+MAX(MIN(O_Demand_Rate!$F$10,I_Live_Bird!$B$16),-I_Live_Bird!$B$16))),1) -> 47.3 | F25: =ROUND(O_Demand_Rate!$C$10*F$4*O_Scenario_Multipliers!$D$22*O_Scenario_Multipliers!$B$10*(IF(I_Live_Bird!$B$15="Flat",1,1+MAX(MIN(O_Demand_Rate!$F$10,I_Live_Bird!$B$16),-I_Live_Bird!$B$16))),1) -> 49.7 | G25: =ROUND(O_Demand_Rate!$C$10*G$4*O_Scenario_Multipliers!$D$22*O_Scenario_Multipliers!$B$10*(IF(I_Live_Bird!$B$15="Flat",1,1+MAX(MIN(O_Demand_Rate!$F$10,I_Live_Bird!$B$16),-I_Live_Bird!$B$16))),1) -> 54.7 | H25: =ROUND(O_Demand_Rate!$C$10*H$4*O_Scenario_Multipliers!$D$22*O_Scenario_Multipliers!$B$10*(IF(I_Live_Bird!$B$15="Flat",1,1+MAX(MIN(O_Demand_Rate!$F$10,I_Live_Bird!$B$16),-I_Live_Bird!$B$16))),1) -> 59.7 | I25: =ROUND(O_Demand_Rate!$C$10*I$4*O_Scenario_Multipliers!$D$22*O_Scenario_Multipliers!$B$10*(IF(I_Live_Bird!$B$15="Flat",1,1+MAX(MIN(O_Demand_Rate!$F$10,I_Live_Bird!$B$16),-I_Live_Bird!$B$16))),1) -> 57.2 | J25: =ROUND(O_Demand_Rate!$C$10*J$4*O_Scenario_Multipliers!$D$22*O_Scenario_Multipliers!$B$10*(IF(I_Live_Bird!$B$15="Flat",1,1+MAX(MIN(O_Demand_Rate!$F$10,I_Live_Bird!$B$16),-I_Live_Bird!$B$16))),1) -> 47.3 | K25: =SUM(D25:J25) -> 362.2
A26: JRN | B26: Jeroan (ati ampela) | C26: Base | D26: =ROUND(O_Demand_Rate!$C$10*D$4*O_Scenario_Multipliers!$E$22*O_Scenario_Multipliers!$B$11*(IF(I_Live_Bird!$B$15="Flat",1,1+MAX(MIN(O_Demand_Rate!$F$10,I_Live_Bird!$B$16),-I_Live_Bird!$B$16))),1) -> 54.4 | E26: =ROUND(O_Demand_Rate!$C$10*E$4*O_Scenario_Multipliers!$E$22*O_Scenario_Multipliers!$B$11*(IF(I_Live_Bird!$B$15="Flat",1,1+MAX(MIN(O_Demand_Rate!$F$10,I_Live_Bird!$B$16),-I_Live_Bird!$B$16))),1) -> 55.6 | F26: =ROUND(O_Demand_Rate!$C$10*F$4*O_Scenario_Multipliers!$E$22*O_Scenario_Multipliers!$B$11*(IF(I_Live_Bird!$B$15="Flat",1,1+MAX(MIN(O_Demand_Rate!$F$10,I_Live_Bird!$B$16),-I_Live_Bird!$B$16))),1) -> 58.5 | G26: =ROUND(O_Demand_Rate!$C$10*G$4*O_Scenario_Multipliers!$E$22*O_Scenario_Multipliers!$B$11*(IF(I_Live_Bird!$B$15="Flat",1,1+MAX(MIN(O_Demand_Rate!$F$10,I_Live_Bird!$B$16),-I_Live_Bird!$B$16))),1) -> 64.4 | H26: =ROUND(O_Demand_Rate!$C$10*H$4*O_Scenario_Multipliers!$E$22*O_Scenario_Multipliers!$B$11*(IF(I_Live_Bird!$B$15="Flat",1,1+MAX(MIN(O_Demand_Rate!$F$10,I_Live_Bird!$B$16),-I_Live_Bird!$B$16))),1) -> 70.2 | I26: =ROUND(O_Demand_Rate!$C$10*I$4*O_Scenario_Multipliers!$E$22*O_Scenario_Multipliers!$B$11*(IF(I_Live_Bird!$B$15="Flat",1,1+MAX(MIN(O_Demand_Rate!$F$10,I_Live_Bird!$B$16),-I_Live_Bird!$B$16))),1) -> 67.3 | J26: =ROUND(O_Demand_Rate!$C$10*J$4*O_Scenario_Multipliers!$E$22*O_Scenario_Multipliers!$B$11*(IF(I_Live_Bird!$B$15="Flat",1,1+MAX(MIN(O_Demand_Rate!$F$10,I_Live_Bird!$B$16),-I_Live_Bird!$B$16))),1) -> 55.6 | K26: =SUM(D26:J26) -> 426
A27: JRN | B27: Jeroan (ati ampela) | C27: Bull | D27: =ROUND(O_Demand_Rate!$C$10*D$4*O_Scenario_Multipliers!$F$22*O_Scenario_Multipliers!$B$12*(IF(I_Live_Bird!$B$15="Flat",1,1+MAX(MIN(O_Demand_Rate!$F$10,I_Live_Bird!$B$16),-I_Live_Bird!$B$16))),1) -> 62.6 | E27: =ROUND(O_Demand_Rate!$C$10*E$4*O_Scenario_Multipliers!$F$22*O_Scenario_Multipliers!$B$12*(IF(I_Live_Bird!$B$15="Flat",1,1+MAX(MIN(O_Demand_Rate!$F$10,I_Live_Bird!$B$16),-I_Live_Bird!$B$16))),1) -> 63.9 | F27: =ROUND(O_Demand_Rate!$C$10*F$4*O_Scenario_Multipliers!$F$22*O_Scenario_Multipliers!$B$12*(IF(I_Live_Bird!$B$15="Flat",1,1+MAX(MIN(O_Demand_Rate!$F$10,I_Live_Bird!$B$16),-I_Live_Bird!$B$16))),1) -> 67.3 | G27: =ROUND(O_Demand_Rate!$C$10*G$4*O_Scenario_Multipliers!$F$22*O_Scenario_Multipliers!$B$12*(IF(I_Live_Bird!$B$15="Flat",1,1+MAX(MIN(O_Demand_Rate!$F$10,I_Live_Bird!$B$16),-I_Live_Bird!$B$16))),1) -> 74 | H27: =ROUND(O_Demand_Rate!$C$10*H$4*O_Scenario_Multipliers!$F$22*O_Scenario_Multipliers!$B$12*(IF(I_Live_Bird!$B$15="Flat",1,1+MAX(MIN(O_Demand_Rate!$F$10,I_Live_Bird!$B$16),-I_Live_Bird!$B$16))),1) -> 80.8 | I27: =ROUND(O_Demand_Rate!$C$10*I$4*O_Scenario_Multipliers!$F$22*O_Scenario_Multipliers!$B$12*(IF(I_Live_Bird!$B$15="Flat",1,1+MAX(MIN(O_Demand_Rate!$F$10,I_Live_Bird!$B$16),-I_Live_Bird!$B$16))),1) -> 77.4 | J27: =ROUND(O_Demand_Rate!$C$10*J$4*O_Scenario_Multipliers!$F$22*O_Scenario_Multipliers!$B$12*(IF(I_Live_Bird!$B$15="Flat",1,1+MAX(MIN(O_Demand_Rate!$F$10,I_Live_Bird!$B$16),-I_Live_Bird!$B$16))),1) -> 63.9 | K27: =SUM(D27:J27) -> 489.9
A28: TLG | B28: Tulang / carcass frame | C28: Bear | D28: =ROUND(O_Demand_Rate!$C$11*D$4*O_Scenario_Multipliers!$D$23*O_Scenario_Multipliers!$B$10*(IF(I_Live_Bird!$B$15="Flat",1,1+MAX(MIN(O_Demand_Rate!$F$11,I_Live_Bird!$B$16),-I_Live_Bird!$B$16))),1) -> 188.8 | E28: =ROUND(O_Demand_Rate!$C$11*E$4*O_Scenario_Multipliers!$D$23*O_Scenario_Multipliers!$B$10*(IF(I_Live_Bird!$B$15="Flat",1,1+MAX(MIN(O_Demand_Rate!$F$11,I_Live_Bird!$B$16),-I_Live_Bird!$B$16))),1) -> 192.9 | F28: =ROUND(O_Demand_Rate!$C$11*F$4*O_Scenario_Multipliers!$D$23*O_Scenario_Multipliers!$B$10*(IF(I_Live_Bird!$B$15="Flat",1,1+MAX(MIN(O_Demand_Rate!$F$11,I_Live_Bird!$B$16),-I_Live_Bird!$B$16))),1) -> 203 | G28: =ROUND(O_Demand_Rate!$C$11*G$4*O_Scenario_Multipliers!$D$23*O_Scenario_Multipliers!$B$10*(IF(I_Live_Bird!$B$15="Flat",1,1+MAX(MIN(O_Demand_Rate!$F$11,I_Live_Bird!$B$16),-I_Live_Bird!$B$16))),1) -> 223.3 | H28: =ROUND(O_Demand_Rate!$C$11*H$4*O_Scenario_Multipliers!$D$23*O_Scenario_Multipliers!$B$10*(IF(I_Live_Bird!$B$15="Flat",1,1+MAX(MIN(O_Demand_Rate!$F$11,I_Live_Bird!$B$16),-I_Live_Bird!$B$16))),1) -> 243.7 | I28: =ROUND(O_Demand_Rate!$C$11*I$4*O_Scenario_Multipliers!$D$23*O_Scenario_Multipliers!$B$10*(IF(I_Live_Bird!$B$15="Flat",1,1+MAX(MIN(O_Demand_Rate!$F$11,I_Live_Bird!$B$16),-I_Live_Bird!$B$16))),1) -> 233.5 | J28: =ROUND(O_Demand_Rate!$C$11*J$4*O_Scenario_Multipliers!$D$23*O_Scenario_Multipliers!$B$10*(IF(I_Live_Bird!$B$15="Flat",1,1+MAX(MIN(O_Demand_Rate!$F$11,I_Live_Bird!$B$16),-I_Live_Bird!$B$16))),1) -> 192.9 | K28: =SUM(D28:J28) -> 1478.1
A29: TLG | B29: Tulang / carcass frame | C29: Base | D29: =ROUND(O_Demand_Rate!$C$11*D$4*O_Scenario_Multipliers!$E$23*O_Scenario_Multipliers!$B$11*(IF(I_Live_Bird!$B$15="Flat",1,1+MAX(MIN(O_Demand_Rate!$F$11,I_Live_Bird!$B$16),-I_Live_Bird!$B$16))),1) -> 194.7 | E29: =ROUND(O_Demand_Rate!$C$11*E$4*O_Scenario_Multipliers!$E$23*O_Scenario_Multipliers!$B$11*(IF(I_Live_Bird!$B$15="Flat",1,1+MAX(MIN(O_Demand_Rate!$F$11,I_Live_Bird!$B$16),-I_Live_Bird!$B$16))),1) -> 198.9 | F29: =ROUND(O_Demand_Rate!$C$11*F$4*O_Scenario_Multipliers!$E$23*O_Scenario_Multipliers!$B$11*(IF(I_Live_Bird!$B$15="Flat",1,1+MAX(MIN(O_Demand_Rate!$F$11,I_Live_Bird!$B$16),-I_Live_Bird!$B$16))),1) -> 209.3 | G29: =ROUND(O_Demand_Rate!$C$11*G$4*O_Scenario_Multipliers!$E$23*O_Scenario_Multipliers!$B$11*(IF(I_Live_Bird!$B$15="Flat",1,1+MAX(MIN(O_Demand_Rate!$F$11,I_Live_Bird!$B$16),-I_Live_Bird!$B$16))),1) -> 230.3 | H29: =ROUND(O_Demand_Rate!$C$11*H$4*O_Scenario_Multipliers!$E$23*O_Scenario_Multipliers!$B$11*(IF(I_Live_Bird!$B$15="Flat",1,1+MAX(MIN(O_Demand_Rate!$F$11,I_Live_Bird!$B$16),-I_Live_Bird!$B$16))),1) -> 251.2 | I29: =ROUND(O_Demand_Rate!$C$11*I$4*O_Scenario_Multipliers!$E$23*O_Scenario_Multipliers!$B$11*(IF(I_Live_Bird!$B$15="Flat",1,1+MAX(MIN(O_Demand_Rate!$F$11,I_Live_Bird!$B$16),-I_Live_Bird!$B$16))),1) -> 240.7 | J29: =ROUND(O_Demand_Rate!$C$11*J$4*O_Scenario_Multipliers!$E$23*O_Scenario_Multipliers!$B$11*(IF(I_Live_Bird!$B$15="Flat",1,1+MAX(MIN(O_Demand_Rate!$F$11,I_Live_Bird!$B$16),-I_Live_Bird!$B$16))),1) -> 198.9 | K29: =SUM(D29:J29) -> 1524
A30: TLG | B30: Tulang / carcass frame | C30: Bull | D30: =ROUND(O_Demand_Rate!$C$11*D$4*O_Scenario_Multipliers!$F$23*O_Scenario_Multipliers!$B$12*(IF(I_Live_Bird!$B$15="Flat",1,1+MAX(MIN(O_Demand_Rate!$F$11,I_Live_Bird!$B$16),-I_Live_Bird!$B$16))),1) -> 200.5 | E30: =ROUND(O_Demand_Rate!$C$11*E$4*O_Scenario_Multipliers!$F$23*O_Scenario_Multipliers!$B$12*(IF(I_Live_Bird!$B$15="Flat",1,1+MAX(MIN(O_Demand_Rate!$F$11,I_Live_Bird!$B$16),-I_Live_Bird!$B$16))),1) -> 204.8 | F30: =ROUND(O_Demand_Rate!$C$11*F$4*O_Scenario_Multipliers!$F$23*O_Scenario_Multipliers!$B$12*(IF(I_Live_Bird!$B$15="Flat",1,1+MAX(MIN(O_Demand_Rate!$F$11,I_Live_Bird!$B$16),-I_Live_Bird!$B$16))),1) -> 215.6 | G30: =ROUND(O_Demand_Rate!$C$11*G$4*O_Scenario_Multipliers!$F$23*O_Scenario_Multipliers!$B$12*(IF(I_Live_Bird!$B$15="Flat",1,1+MAX(MIN(O_Demand_Rate!$F$11,I_Live_Bird!$B$16),-I_Live_Bird!$B$16))),1) -> 237.2 | H30: =ROUND(O_Demand_Rate!$C$11*H$4*O_Scenario_Multipliers!$F$23*O_Scenario_Multipliers!$B$12*(IF(I_Live_Bird!$B$15="Flat",1,1+MAX(MIN(O_Demand_Rate!$F$11,I_Live_Bird!$B$16),-I_Live_Bird!$B$16))),1) -> 258.7 | I30: =ROUND(O_Demand_Rate!$C$11*I$4*O_Scenario_Multipliers!$F$23*O_Scenario_Multipliers!$B$12*(IF(I_Live_Bird!$B$15="Flat",1,1+MAX(MIN(O_Demand_Rate!$F$11,I_Live_Bird!$B$16),-I_Live_Bird!$B$16))),1) -> 247.9 | J30: =ROUND(O_Demand_Rate!$C$11*J$4*O_Scenario_Multipliers!$F$23*O_Scenario_Multipliers!$B$12*(IF(I_Live_Bird!$B$15="Flat",1,1+MAX(MIN(O_Demand_Rate!$F$11,I_Live_Bird!$B$16),-I_Live_Bird!$B$16))),1) -> 204.8 | K30: =SUM(D30:J30) -> 1569.5

Sheet O_Optimizer
A1: O_Optimizer — LAYER 2: Keputusan Beli Ayam (Joint Production)
A2: Window 7 hari. Implied ekor per potongan = demand / (kg per ekor). Binding cut = ekor terbanyak.
A4: BAGIAN A — DEMAND 7-HARI & IMPLIED EKOR
A5: SKU Code | B5: SKU Name | C5: kg/Ekor | D5: Demand Bear | E5: Demand Base | F5: Demand Bull | G5: Ekor Bear | H5: Ekor Base | I5: Ekor Bull
A6: BLD | B6: Boneless Dada (fillet) | C6: =I_Yield!$E$6 -> 0.36 | D6: =O_Demand_Forecast!$K$7 -> 2360.4 | E6: =O_Demand_Forecast!$K$8 -> 2538.2 | F6: =O_Demand_Forecast!$K$9 -> 2715.9 | G6: =IFERROR(D6/C6,0) -> 6556.6667 | H6: =IFERROR(E6/C6,0) -> 7050.5556 | I6: =IFERROR(F6/C6,0) -> 7544.1667
A7: BLP | B7: Boneless Paha (fillet) | C7: =I_Yield!$E$7 -> 0.26 | D7: =O_Demand_Forecast!$K$10 -> 1619.2 | E7: =O_Demand_Forecast!$K$11 -> 1741.1 | F7: =O_Demand_Forecast!$K$12 -> 1863 | G7: =IFERROR(D7/C7,0) -> 6227.6923 | H7: =IFERROR(E7/C7,0) -> 6696.5385 | I7: =IFERROR(F7/C7,0) -> 7165.3846
A8: SYP | B8: Sayap | C8: =I_Yield!$E$8 -> 0.18 | D8: =O_Demand_Forecast!$K$13 -> 1066.7 | E8: =O_Demand_Forecast!$K$14 -> 1147.1 | F8: =O_Demand_Forecast!$K$15 -> 1227.5 | G8: =IFERROR(D8/C8,0) -> 5926.1111 | H8: =IFERROR(E8/C8,0) -> 6372.7778 | I8: =IFERROR(F8/C8,0) -> 6819.4444
A9: CKR | B9: Ceker | C9: =I_Yield!$E$9 -> 0.08 | D9: =O_Demand_Forecast!$K$16 -> 393.5 | E9: =O_Demand_Forecast!$K$17 -> 462.8 | F9: =O_Demand_Forecast!$K$18 -> 532.3 | G9: =IFERROR(D9/C9,0) -> 4918.75 | H9: =IFERROR(E9/C9,0) -> 5785 | I9: =IFERROR(F9/C9,0) -> 6653.75
A10: KPL | B10: Kepala | C10: =I_Yield!$E$10 -> 0.06 | D10: =O_Demand_Forecast!$K$19 -> 196.2 | E10: =O_Demand_Forecast!$K$20 -> 230.9 | F10: =O_Demand_Forecast!$K$21 -> 265.4 | G10: =IFERROR(D10/C10,0) -> 3270 | H10: =IFERROR(E10/C10,0) -> 3848.3333 | I10: =IFERROR(F10/C10,0) -> 4423.3333
A11: KLT | B11: Kulit | C11: =I_Yield!$E$11 -> 0.12 | D11: =O_Demand_Forecast!$K$22 -> 450.7 | E11: =O_Demand_Forecast!$K$23 -> 530.2 | F11: =O_Demand_Forecast!$K$24 -> 609.8 | G11: =IFERROR(D11/C11,0) -> 3755.8333 | H11: =IFERROR(E11/C11,0) -> 4418.3333 | I11: =IFERROR(F11/C11,0) -> 5081.6667
