Workbook

Sheet Notes
A1: KGR — WORKING PAPER SALES, SKU AND SEGMENT GROSS PROFIT — August 2026 (v7, rebuilt)
A3: Purpose | B3: Gross profit per segment (RPA, Trading) March–August 2026, with the 10 August invoices that have no SI moved to the segment of their items and re-costed; a GP-margin waterfall July→August per segment (NMG method); August sales split by vintage; SKU, form, karkas-size, by-product and batch economics; why the RPA loses money.
A4: FS basis | B4: Accounting team's FS_KGR_Aug_2026.xlsx (Agt 26 GL incl. the undated adjustment rows at the bottom; PL - Performance; TB Accurate). "Aug as booked" in Segment GP ties to PL - Performance to the rupiah.
A5: Sources | B5: inventory_valuation_terbaru.xls (1 Jul–31 Aug, printed 23 Sep 23.25; 95 items, 993 lines) + 25 dormant items from WP v6 · sales_details.xls via WP v6 (invoiced kg/revenue; invoices unchanged) · Dika's schedule of the 4 MJ invoices (item, kg, cost 31/8) · FS_KGR_Aug_2026.xlsx sheet Sheet1 (10 invoices) · GL live-bird PIs for batch cost.
A6: Colour code | B6: Blue = input from a source file. Black = formula. Green = link to another sheet. Yellow fill = assumption you may edit (segment of the 6 invoices, line prices, cost-of-sales overrides, kg-share override, benchmarks, lemak price).
A7: How the unbilled invoices are treated | B7: As booked, all 10 sit in RPA (4101013 in "Revenue - LB", all HPP in 5100004 and credited to 1104003). Adj-1 moves each line to the segment of its item code at the HPP booked; Adj-2 re-costs the 4 MJ invoices at the moving average on the SJ date (MA Engine replay B); Adj-3 is the knock-on on later DOs once those kg leave stock. The 6 invoices without item detail keep the HPP booked in Agt 26 (FS version of 24 Sep: 226 and 311 re-estimated) and follow Dika's segment tag in Agt 26 (201, 232 RPA; 226 Trading); untagged 243, 257, 311 sit in RPA — change per invoice in Unbilled column N.
A8: MA Engine | B8: Replays Accurate's moving average row by row. Replay A (as posted) reproduces Accurate's DO cost to Rp7 in total — proof the engine is Accurate's own method. Adjustments (IA) and job rows keep booked value. DO KGR26.00231 (JLB0822) left more than the stock on hand; Accurate's cost is kept. Changing a kg in Unbilled recalculates B. Changing an item code or SJ date needs the engine regenerated (row position).
A9: Vintage method | B9: Accurate keeps no lots. Point estimate = FIFO row by row in MA Engine (cols AE–AM): each outflow takes the stock on hand at 1 Jul first, then July receipts, then August receipts, and carries the HPP Accurate booked on that DO split by kg. Buckets therefore add up to booked HPP — no moving-average bar (NMG style, Dika 24 Sep). Lower bound = new stock first at the item's average booked HPP/kg. Revenue per item = its kg share of the invoiced revenue of its SKU-form (karkas: size-form) + its unbilled lines.
A10: Batch data | B10: Ops costing file 202608_Data_COGS_LB.xlsx (12 Pot_ISA sheets, Pot_ISA20 REV for 20 Aug) in I_Batch_Ops: output per item ties to Accurate receipts per batch; cost ties to GRN. Batch Economics shows output, yields on live-bird kg (ops definition) and on processed kg, value at the ops price list and at August realised prices, karkas size mix and cost/kg by product (ops allocation vs Accurate). 8 Aug: 323.8 kg usus discarded (limbah), not in stock.
A11: Waterfall method | B11: Bar = August revenue share of the bucket × (bucket product margin − July GP margin). Moving-average effect, cost of sales others and items outside the split (revenue with no SI, invoices without item) are separate bars. Consolidated: rate effect per segment + segment mix + unknown-segment invoices. Bars add exactly (Tally).
A12: Cost of sales others | B12: Expedition (5100002/07/10) and blasting (5100009) are inside Gross Profit in the accounting mapping. Segment GP shows them SEPARATELY at KGR level (Dika, 24 Sep): segment gross profit = revenue − product COGS. Sheet COS Others still attributes every journal line by vendor/narrative (shared lines by kg) as information; switch COS Others B3 to Yes to push that attribution into the segments. Storage, handling and packaging stay below GP as in the FS.
A13: What changed vs WP v6 | B13: (1) FS basis = accounting FS. (2) Accurate re-costed August: JLB DO −Rp31.7m, karkas/by-product split at GRN, TRD −Rp6.7m. (3) GR26080012 now has 5,641.6 kg karkas (1,577.7 kg Karkas 1.0 Fresh Premium posted) — its yield is normal; the old −Rp61m "short batch" driver is gone. (4) 10 unbilled invoices added (6 new by Dika). (5) Segment GP, vintage and waterfall added. (6) Stock Carry-over replaced by Vintage. (7) Months now tie to GL at SKU level: three GL-only rows in Data SKU — Apr RPA Rp22.1m SI COGS not matched to a DO (v6), Jul Trading Rp9.2m PI26070074 kulit posted straight to COGS (no GRN, no sale — for accounting), Jul RPA −Rp81k MJ26070009. Stock ties to GL at 30 Jun, 31 Jul and 31 Aug.
A14: KPI vs budget | B14: Sheet RPA KPI vs Budget: 19 driver KPIs (volume, live bird, process, output mix, prices, conversion, result per kg) with the budget value copied from KGR_-_Budget_Manufacturing_v3.xlsx (sheet!cell shown, blue) and August actual linked to this WP. Budget models the own plant from Sep-26; August was still maklon at ISA — conversion and utilisation are shown for direction only.
... A16: Sheet map | B16: MTM Bridge (KPI matrix, revenue bridge, customers, margin drivers, spread, opex/NIBT) → Segment GP → GP Waterfall → Vintage → Unbilled → RPA Loss Bridge → Batch Economics → SKU Summary → Karkas Detail → By-product → Fresh vs Frozen → Monthly by SKU → COS Others → Recon to FS → Deck Feed → Data SKU → MA Engine → I_Sales_Inv (invoice × customer) → I_Items → I_GL.

Sheet Tally
A1: TALLY — every total checked against its source
A2: Status OK = within tolerance. "OK (known)" = the difference equals a documented item (Expected column). BREAK = investigate.
A4: # | B4: Area | C4: Check | D4: WP value | E4: Reference | F4: Difference | G4: Expected (known item) | H4: Tol. | I4: Status | J4: Note
A5: 1 | B5: MA Engine | C5: Replay A reproduces Accurate DO cost (sum A − booked) | D5: ='MA Engine'!AB1111 -> -6.6701382 | E5: 0 | F5: =D5-E5 -> -6.6701382 | G5: 0 | H5: 10 | I5: =IF(ABS(F5-G5)<=H5,IF(G5=0,"OK","OK (known)"),"BREAK") -> OK | J5: Moving average replayed row by row; DO KGR26.00231 (JLB0822, stock negative in Accurate) kept at booked cost
A6: 2 | B6: MA Engine | C6: Closing kg per engine A = Accurate closing kg (sum of abs diff) | D6: =SUMPRODUCT(ABS(I_Items!$M$5:$M$133-I_Items!$K$5:$K$133)) -> 1.779768e-11 | E6: 0 | F6: =D6-E6 -> 1.779768e-11 | G6: 0 | H6: 0.05 | I6: =IF(ABS(F6-G6)<=H6,IF(G6=0,"OK","OK (known)"),"BREAK") -> OK
A7: 3 | B7: MA Engine | C7: Closing Rp per engine A = Accurate closing Rp (sum of abs diff) | D7: =SUMPRODUCT(ABS(I_Items!$N$5:$N$133-I_Items!$L$5:$L$133)) -> 12.561372 | E7: 0 | F7: =D7-E7 -> 12.561372 | G7: 0 | H7: 20 | I7: =IF(ABS(F7-G7)<=H7,IF(G7=0,"OK","OK (known)"),"BREAK") -> OK
A8: 4 | B8: MA Engine | C8: Aug DO cost RPA excl. DO 257 (engine A) = GL 5100004+05 less unbilled HPP | D8: =SUMIFS('MA Engine'!$S$6:$S$1110,'MA Engine'!$C$6:$C$1110,"RPA",'MA Engine'!$H$6:$H$1110,8,'MA Engine'!$I$6:$I$1110,"DO",'MA Engine'!$P$6:$P$1110,"<>Y") -> 2.1713713e+09 | E8: =I_GL!I19+I_GL!I20-Unbilled!L17 -> 2.1713713e+09 | F8: =D8-E8 -> 0.78266716 | G8: 0 | H8: 10 | I8: =IF(ABS(F8-G8)<=H8,IF(G8=0,"OK","OK (known)"),"BREAK") -> OK
A9: 5 | B9: MA Engine | C9: Aug DO cost Trading (engine A) = GL 5100011 | D9: =SUMIFS('MA Engine'!$S$6:$S$1110,'MA Engine'!$C$6:$C$1110,"Trading",'MA Engine'!$H$6:$H$1110,8,'MA Engine'!$I$6:$I$1110,"DO") -> 4.835721e+09 | E9: =I_GL!I26 -> 4.835721e+09 | F9: =D9-E9 -> -5.5488672 | G9: 0 | H9: 10 | I9: =IF(ABS(F9-G9)<=H9,IF(G9=0,"OK","OK (known)"),"BREAK") -> OK
A10: 6 | B10: MA Engine | C10: DO KGR26.00257 cost = GL 1104002 In Transit 31 Aug | D10: =SUMIFS('MA Engine'!$S$6:$S$1110,'MA Engine'!$P$6:$P$1110,"Y") -> 91185802 | E10: =I_GL!M6 -> 91185802 | F10: =D10-E10 -> -0.15293424 | G10: 0 | H10: 1 | I10: =IF(ABS(F10-G10)<=H10,IF(G10=0,"OK","OK (known)"),"BREAK") -> OK
A11: 7 | B11: MA Engine | C11: Aug receipts RPA (engine) = live-bird GRN value in GL (2103011) | D11: =SUMIFS('MA Engine'!$L$6:$L$1110,'MA Engine'!$C$6:$C$1110,"RPA",'MA Engine'!$H$6:$H$1110,8,'MA Engine'!$I$6:$I$1110,"Receipt") -> 3.8401048e+09 | E11: ='Batch Economics'!H18 -> 3.8401048e+09 | F11: =D11-E11 -> -0.009999752 | G11: 0 | H11: 1 | I11: =IF(ABS(F11-G11)<=H11,IF(G11=0,"OK","OK (known)"),"BREAK") -> OK
A12: 8 | B12: MA Engine | C12: Unbilled lines: stock goes negative after posting (count) | D12: =COUNTIF(Unbilled!$S$22:$S$38,"STOCK MINUS") -> 4 | E12: 0 | F12: =D12-E12 -> 4 | G12: 4 | H12: 0 | I12: =IF(ABS(F12-G12)<=H12,IF(G12=0,"OK","OK (known)"),"BREAK") -> OK (known) | J12: TRD0021, JLB1857, TRD0027, TRD0024 — item code to be confirmed (Unbilled open item 2)
A13: 9 | B13: Data SKU | C13: Aug invoiced kg = engine DO kg excl. DO 257 | D13: =SUMIFS('Data SKU'!$F$5:$F$116,'Data SKU'!$D$5:$D$116,8,'Data SKU'!$N$5:$N$116,"Invoiced") -> 236674.21 | E13: =SUMIFS('MA Engine'!$W$6:$W$1110,'MA Engine'!$H$6:$H$1110,8,'MA Engine'!$I$6:$I$1110,"DO",'MA Engine'!$P$6:$P$1110,"<>Y",'MA Engine'!$C$6:$C$1110,"<>Other") -> 236674.21 | F13: =D13-E13 -> 0 | G13: 0 | H13: 0.5 | I13: =IF(ABS(F13-G13)<=H13,IF(G13=0,"OK","OK (known)"),"BREAK") -> OK
A14: 10 | B14: Data SKU | C14: Aug invoiced revenue RPA = GL revenue RPA | D14: =SUMIFS('Data SKU'!$G$5:$G$116,'Data SKU'!$A$5:$A$116,"RPA",'Data SKU'!$D$5:$D$116,8,'Data SKU'!$N$5:$N$116,"Invoiced") -> 2104033270 | E14: =-SUMIFS(I_GL!$I$5:$I$29,I_GL!$C$5:$C$29,"Rev RPA") -> 2104662870 | F14: =D14-E14 -> -629600 | G14: -629600 | H14: 1 | I14: =IF(ABS(F14-G14)<=H14,IF(G14=0,"OK","OK (known)"),"BREAK") -> OK (known) | J14: Sampel usus/limbah April Rp629,600 reclassed from DP to 4101007 in Aug — no SI, so not in sales_details
A15: 11 | B15: Data SKU | C15: Aug invoiced revenue Trading = GL revenue Trading | D15: =SUMIFS('Data SKU'!$G$5:$G$116,'Data SKU'!$A$5:$A$116,"Trading",'Data SKU'!$D$5:$D$116,8,'Data SKU'!$N$5:$N$116,"Invoiced") -> 5.3173228e+09 | E15: =-SUMIFS(I_GL!$I$5:$I$29,I_GL!$C$5:$C$29,"Rev Trading") -> 5317322794 | F15: =D15-E15 -> -0.19999981 | G15: 0 | H15: 1 | I15: =IF(ABS(F15-G15)<=H15,IF(G15=0,"OK","OK (known)"),"BREAK") -> OK
A16: 12 | B16: Data SKU | C16: Mar-26 RPA: SKU revenue = Segment GP revenue | D16: =SUMIFS('Data SKU'!$G$5:$G$116,'Data SKU'!$A$5:$A$116,"RPA",'Data SKU'!$D$5:$D$116,3) -> 190035900 | E16: ='Segment GP'!D6 -> 190035900 | F16: =D16-E16 -> 0 | G16: 0 | H16: 1 | I16: =IF(ABS(F16-G16)<=H16,IF(G16=0,"OK","OK (known)"),"BREAK") -> OK
A17: 13 | B17: Data SKU | C17: Mar-26 RPA: SKU product cost = Segment GP COGS | D17: =SUMIFS('Data SKU'!$H$5:$H$116,'Data SKU'!$A$5:$A$116,"RPA",'Data SKU'!$D$5:$D$116,3) -> 1.7515188e+08 | E17: =-'Segment GP'!D13 -> 1.7515188e+08 | F17: =D17-E17 -> 0 | G17: 0 | H17: 10 | I17: =IF(ABS(F17-G17)<=H17,IF(G17=0,"OK","OK (known)"),"BREAK") -> OK
A18: 14 | B18: Data SKU | C18: Mar-26 Trading: SKU revenue = Segment GP revenue | D18: =SUMIFS('Data SKU'!$G$5:$G$116,'Data SKU'!$A$5:$A$116,"Trading",'Data SKU'!$D$5:$D$116,3) -> 0 | E18: ='Segment GP'!D7 -> 0 | F18: =D18-E18 -> 0 | G18: 0 | H18: 1 | I18: =IF(ABS(F18-G18)<=H18,IF(G18=0,"OK","OK (known)"),"BREAK") -> OK
A19: 15 | B19: Data SKU | C19: Mar-26 Trading: SKU product cost = Segment GP COGS | D19: =SUMIFS('Data SKU'!$H$5:$H$116,'Data SKU'!$A$5:$A$116,"Trading",'Data SKU'!$D$5:$D$116,3) -> 0 | E19: =-'Segment GP'!D14 -> 0 | F19: =D19-E19 -> 0 | G19: 0 | H19: 10 | I19: =IF(ABS(F19-G19)<=H19,IF(G19=0,"OK","OK (known)"),"BREAK") -> OK
A20: 16 | B20: Data SKU | C20: Apr-26 RPA: SKU revenue = Segment GP revenue | D20: =SUMIFS('Data SKU'!$G$5:$G$116,'Data SKU'!$A$5:$A$116,"RPA",'Data SKU'!$D$5:$D$116,4) -> 646041120 | E20: ='Segment GP'!E6 -> 646041120 | F20: =D20-E20 -> 0 | G20: 0 | H20: 1 | I20: =IF(ABS(F20-G20)<=H20,IF(G20=0,"OK","OK (known)"),"BREAK") -> OK
A21: 17 | B21: Data SKU | C21: Apr-26 RPA: SKU product cost = Segment GP COGS | D21: =SUMIFS('Data SKU'!$H$5:$H$116,'Data SKU'!$A$5:$A$116,"RPA",'Data SKU'!$D$5:$D$116,4) -> 5.6053189e+08 | E21: =-'Segment GP'!E13 -> 5.6053189e+08 | F21: =D21-E21 -> 0 | G21: 0 | H21: 10 | I21: =IF(ABS(F21-G21)<=H21,IF(G21=0,"OK","OK (known)"),"BREAK") -> OK
A22: 18 | B22: Data SKU | C22: Apr-26 Trading: SKU revenue = Segment GP revenue | D22: =SUMIFS('Data SKU'!$G$5:$G$116,'Data SKU'!$A$5:$A$116,"Trading",'Data SKU'!$D$5:$D$116,4) -> 149939860 | E22: ='Segment GP'!E7 -> 149939860 | F22: =D22-E22 -> 0 | G22: 0 | H22: 1 | I22: =IF(ABS(F22-G22)<=H22,IF(G22=0,"OK","OK (known)"),"BREAK") -> OK
A23: 19 | B23: Data SKU | C23: Apr-26 Trading: SKU product cost = Segment GP COGS | D23: =SUMIFS('Data SKU'!$H$5:$H$116,'Data SKU'!$A$5:$A$116,"Trading",'Data SKU'!$D$5:$D$116,4) -> 141127370 | E23: =-'Segment GP'!E14 -> 141127370 | F23: =D23-E23 -> 0 | G23: 0 | H23: 10 | I23: =IF(ABS(F23-G23)<=H23,IF(G23=0,"OK","OK (known)"),"BREAK") -> OK
A24: 20 | B24: Data SKU | C24: May-26 RPA: SKU revenue = Segment GP revenue | D24: =SUMIFS('Data SKU'!$G$5:$G$116,'Data SKU'!$A$5:$A$116,"RPA",'Data SKU'!$D$5:$D$116,5) -> 1402180774 | E24: ='Segment GP'!F6 -> 1402180774 | F24: =D24-E24 -> 0 | G24: 0 | H24: 1 | I24: =IF(ABS(F24-G24)<=H24,IF(G24=0,"OK","OK (known)"),"BREAK") -> OK
A25: 21 | B25: Data SKU | C25: May-26 RPA: SKU product cost = Segment GP COGS | D25: =SUMIFS('Data SKU'!$H$5:$H$116,'Data SKU'!$A$5:$A$116,"RPA",'Data SKU'!$D$5:$D$116,5) -> 1.5619249e+09 | E25: =-'Segment GP'!F13 -> 1.5619249e+09 | F25: =D25-E25 -> 0.65999985 | G25: 0 | H25: 10 | I25: =IF(ABS(F25-G25)<=H25,IF(G25=0,"OK","OK (known)"),"BREAK") -> OK
A26: 22 | B26: Data SKU | C26: May-26 Trading: SKU revenue = Segment GP revenue | D26: =SUMIFS('Data SKU'!$G$5:$G$116,'Data SKU'!$A$5:$A$116,"Trading",'Data SKU'!$D$5:$D$116,5) -> 44220195 | E26: ='Segment GP'!F7 -> 44220195 | F26: =D26-E26 -> 0 | G26: 0 | H26: 1 | I26: =IF(ABS(F26-G26)<=H26,IF(G26=0,"OK","OK (known)"),"BREAK") -> OK
A27: 23 | B27: Data SKU | C27: May-26 Trading: SKU product cost = Segment GP COGS | D27: =SUMIFS('Data SKU'!$H$5:$H$116,'Data SKU'!$A$5:$A$116,"Trading",'Data SKU'!$D$5:$D$116,5) -> 40506060 | E27: =-'Segment GP'!F14 -> 40506060 | F27: =D27-E27 -> 0 | G27: 0 | H27: 10 | I27: =IF(ABS(F27-G27)<=H27,IF(G27=0,"OK","OK (known)"),"BREAK") -> OK
A28: 24 | B28: Data SKU | C28: Jun-26 RPA: SKU revenue = Segment GP revenue | D28: =SUMIFS('Data SKU'!$G$5:$G$116,'Data SKU'!$A$5:$A$116,"RPA",'Data SKU'!$D$5:$D$116,6) -> 5.0030944e+08 | E28: ='Segment GP'!G6 -> 5.0030944e+08 | F28: =D28-E28 -> 0 | G28: 0 | H28: 1 | I28: =IF(ABS(F28-G28)<=H28,IF(G28=0,"OK","OK (known)"),"BREAK") -> OK
A29: 25 | B29: Data SKU | C29: Jun-26 RPA: SKU product cost = Segment GP COGS | D29: =SUMIFS('Data SKU'!$H$5:$H$116,'Data SKU'!$A$5:$A$116,"RPA",'Data SKU'!$D$5:$D$116,6) -> 4.8423077e+08 | E29: =-'Segment GP'!G13 -> 4.8423077e+08 | F29: =D29-E29 -> 0.0099999905 | G29: 0 | H29: 10 | I29: =IF(ABS(F29-G29)<=H29,IF(G29=0,"OK","OK (known)"),"BREAK") -> OK
A30: 26 | B30: Data SKU | C30: Jun-26 Trading: SKU revenue = Segment GP revenue | D30: =SUMIFS('Data SKU'!$G$5:$G$116,'Data SKU'!$A$5:$A$116,"Trading",'Data SKU'!$D$5:$D$116,6) -> 922384240 | E30: ='Segment GP'!G7 -> 922384240 | F30: =D30-E30 -> 0 | G30: 0 | H30: 1 | I30: =IF(ABS(F30-G30)<=H30,IF(G30=0,"OK","OK (known)"),"BREAK") -> OK
A31: 27 | B31: Data SKU | C31: Jun-26 Trading: SKU product cost = Segment GP COGS | D31: =SUMIFS('Data SKU'!$H$5:$H$116,'Data SKU'!$A$5:$A$116,"Trading",'Data SKU'!$D$5:$D$116,6) -> 8.077824e+08 | E31: =-'Segment GP'!G14 -> 8.077824e+08 | F31: =D31-E31 -> -0.19000006 | G31: 0 | H31: 10 | I31: =IF(ABS(F31-G31)<=H31,IF(G31=0,"OK","OK (known)"),"BREAK") -> OK
A32: 28 | B32: Data SKU | C32: Jul-26 RPA: SKU revenue = Segment GP revenue | D32: =SUMIFS('Data SKU'!$G$5:$G$116,'Data SKU'!$A$5:$A$116,"RPA",'Data SKU'!$D$5:$D$116,7) -> 246532160 | E32: ='Segment GP'!H6 -> 246532160 | F32: =D32-E32 -> 0 | G32: 0 | H32: 1 | I32: =IF(ABS(F32-G32)<=H32,IF(G32=0,"OK","OK (known)"),"BREAK") -> OK
A33: 29 | B33: Data SKU | C33: Jul-26 RPA: SKU product cost = Segment GP COGS | D33: =SUMIFS('Data SKU'!$H$5:$H$116,'Data SKU'!$A$5:$A$116,"RPA",'Data SKU'!$D$5:$D$116,7) -> 2.4804879e+08 | E33: =-'Segment GP'!H13 -> 2.4804879e+08 | F33: =D33-E33 -> 0.079999954 | G33: 0 | H33: 10 | I33: =IF(ABS(F33-G33)<=H33,IF(G33=0,"OK","OK (known)"),"BREAK") -> OK
A34: 30 | B34: Data SKU | C34: Jul-26 Trading: SKU revenue = Segment GP revenue | D34: =SUMIFS('Data SKU'!$G$5:$G$116,'Data SKU'!$A$5:$A$116,"Trading",'Data SKU'!$D$5:$D$116,7) -> 2.8764258e+09 | E34: ='Segment GP'!H7 -> 2.8764258e+09 | F34: =D34-E34 -> 0 | G34: 0 | H34: 1 | I34: =IF(ABS(F34-G34)<=H34,IF(G34=0,"OK","OK (known)"),"BREAK") -> OK
A35: 31 | B35: Data SKU | C35: Jul-26 Trading: SKU product cost = Segment GP COGS | D35: =SUMIFS('Data SKU'!$H$5:$H$116,'Data SKU'!$A$5:$A$116,"Trading",'Data SKU'!$D$5:$D$116,7) -> 2.3922533e+09 | E35: =-'Segment GP'!H14 -> 2.3922533e+09 | F35: =D35-E35 -> -0.61000013 | G35: 0 | H35: 10 | I35: =IF(ABS(F35-G35)<=H35,IF(G35=0,"OK","OK (known)"),"BREAK") -> OK
A36: 32 | B36: Data SKU | C36: Aug-26 RPA: SKU revenue = Segment GP revenue (corrected) | D36: =SUMIFS('Data SKU'!$G$5:$G$116,'Data SKU'!$A$5:$A$116,"RPA",'Data SKU'!$D$5:$D$116,8) -> 2.691687e+09 | E36: ='Segment GP'!M6 -> 2.691687e+09 | F36: =D36-E36 -> 0 | G36: 0 | H36: 1 | I36: =IF(ABS(F36-G36)<=H36,IF(G36=0,"OK","OK (known)"),"BREAK") -> OK
A37: 33 | B37: Data SKU | C37: Aug-26 RPA: SKU product cost = Segment GP COGS (corrected) | D37: =SUMIFS('Data SKU'!$H$5:$H$116,'Data SKU'!$A$5:$A$116,"RPA",'Data SKU'!$D$5:$D$116,8) -> 2.7551492e+09 | E37: =-'Segment GP'!M13 -> 2.7551492e+09 | F37: =D37-E37 -> 0.78266764 | G37: 0 | H37: 10 | I37: =IF(ABS(F37-G37)<=H37,IF(G37=0,"OK","OK (known)"),"BREAK") -> OK | J37: Aug: MA replay reproduces Accurate within Rp7
A38: 34 | B38: Data SKU | C38: Aug-26 Trading: SKU revenue = Segment GP revenue (corrected) | D38: =SUMIFS('Data SKU'!$G$5:$G$116,'Data SKU'!$A$5:$A$116,"Trading",'Data SKU'!$D$5:$D$116,8) -> 5.6700739e+09 | E38: ='Segment GP'!M7 -> 5.6700739e+09 | F38: =D38-E38 -> -0.19999981 | G38: 0 | H38: 1 | I38: =IF(ABS(F38-G38)<=H38,IF(G38=0,"OK","OK (known)"),"BREAK") -> OK
A39: 35 | B39: Data SKU | C39: Aug-26 Trading: SKU product cost = Segment GP COGS (corrected) | D39: =SUMIFS('Data SKU'!$H$5:$H$116,'Data SKU'!$A$5:$A$116,"Trading",'Data SKU'!$D$5:$D$116,8) -> 5.2001277e+09 | E39: =-'Segment GP'!M14 -> 5.2001277e+09 | F39: =D39-E39 -> -5.5488672 | G39: 0 | H39: 10 | I39: =IF(ABS(F39-G39)<=H39,IF(G39=0,"OK","OK (known)"),"BREAK") -> OK | J39: Aug: MA replay reproduces Accurate within Rp7
A40: 36 | B40: Recon to FS | C40: Inventory 30 Jun: GL − subledger, RPA | D40: ='Recon to FS'!C43 -> 1 | E40: 0 | F40: =D40-E40 -> 1 | G40: 0 | H40: 1 | I40: =IF(ABS(F40-G40)<=H40,IF(G40=0,"OK","OK (known)"),"BREAK") -> OK
A41: 37 | B41: Recon to FS | C41: Inventory 30 Jun: GL − subledger, Trading + packaging | D41: ='Recon to FS'!D43+'Recon to FS'!E43 -> 0 | E41: 0 | F41: =D41-E41 -> 0 | G41: 0 | H41: 5 | I41: =IF(ABS(F41-G41)<=H41,IF(G41=0,"OK","OK (known)"),"BREAK") -> OK | J41: Rupiah rounding of the moving average
...

Sheet MTM Bridge
A1: KGR — JULY vs AUGUST 2026 (MTM): KPI matrix, revenue bridge, customers, GP-margin drivers, opex and NIBT — the numbers behind the script
A2: Aug = corrected (unbilled at item segment, moving average on SJ date; 6 invoices without item detail in RPA). Opex/NIBT = accounting PL - Performance.
B4: A. KEY FINANCIAL AND PERFORMANCE MATRIX
B5: Description | C5: Unit | D5: Jul-26 | E5: Aug-26 | F5: Variance | G5: Var % | H5: YTD Mar–Aug | N5: Note
B6: Revenue — RPA | C6: IDR mn | D6: ='Segment GP'!H6/1000000 -> 246.53216 | E6: ='Segment GP'!M6/1000000 -> 2691.687 | F6: =IFERROR(E6-D6,0) -> 2445.1548 | G6: =IFERROR(F6/ABS(D6),0) -> 9.9181982 | H6: ='Segment GP'!N6/1000000 -> 5676.7864
B7: Revenue — Trading | C7: IDR mn | D7: ='Segment GP'!H7/1000000 -> 2876.4258 | E7: ='Segment GP'!M7/1000000 -> 5670.0739 | F7: =IFERROR(E7-D7,0) -> 2793.6481 | G7: =IFERROR(F7/ABS(D7),0) -> 0.97122204 | H7: ='Segment GP'!N7/1000000 -> 9663.044
B8: Revenue — total | C8: IDR mn | D8: ='Segment GP'!H9/1000000 -> 3122.9579 | E8: ='Segment GP'!M9/1000000 -> 8361.7609 | F8: =IFERROR(E8-D8,0) -> 5238.803 | G8: =IFERROR(F8/ABS(D8),0) -> 1.6775131 | H8: ='Segment GP'!N9/1000000 -> 15339.83
B9: Gross profit — total | C9: IDR mn | D9: ='Segment GP'!H34/1000000 -> 363.05137 | E9: ='Segment GP'!M34/1000000 -> 306.13814 | F9: =IFERROR(E9-D9,0) -> -56.913236 | G9: =IFERROR(F9/ABS(D9),0) -> -0.15676359 | H9: ='Segment GP'!N34/1000000 -> 389.84162
B10: GP margin — RPA | C10: % | D10: ='Segment GP'!H35 -> -0.0061518649 | E10: ='Segment GP'!M35 -> -0.023577126 | F10: =IFERROR(E10-D10,0) -> -0.017425261 | H10: ='Segment GP'!N35 -> -0.019069074
B11: GP margin — Trading | C11: % | D11: ='Segment GP'!H36 -> 0.16832434 | E11: ='Segment GP'!M36 -> 0.082881853 | F11: =IFERROR(E11-D11,0) -> -0.085442491 | H11: ='Segment GP'!N36 -> 0.11189509
B12: GP margin — total | C12: % | D12: ='Segment GP'!H38 -> 0.11625241 | E12: ='Segment GP'!M38 -> 0.036611683 | F12: =IFERROR(E12-D12,0) -> -0.079640723 | H12: ='Segment GP'!N38 -> 0.025413685
B13: Volume sold — RPA | C13: ton | D13: ='Segment GP'!H40/1000 -> 12.57601 | E13: ='Segment GP'!M40/1000 -> 95.54572 | F13: =IFERROR(E13-D13,0) -> 82.96971 | G13: =IFERROR(F13/ABS(D13),0) -> 6.597459 | H13: ='Segment GP'!N40/1000 -> 239.68339
B14: Volume sold — Trading | C14: ton | D14: ='Segment GP'!H41/1000 -> 86.9467 | E14: ='Segment GP'!M41/1000 -> 168.92498 | F14: =IFERROR(E14-D14,0) -> 81.97828 | G14: =IFERROR(F14/ABS(D14),0) -> 0.94285672 | H14: ='Segment GP'!N41/1000 -> 288.43437
B15: ASP — RPA | C15: Rp/kg | D15: ='Segment GP'!H44 -> 19603.369 | E15: ='Segment GP'!M44 -> 28171.717 | F15: =IFERROR(E15-D15,0) -> 8568.3484 | G15: =IFERROR(F15/ABS(D15),0) -> 0.43708551 | H15: ='Segment GP'!N44 -> 23684.521
B16: ASP — Trading | C16: Rp/kg | D16: ='Segment GP'!H48 -> 33082.633 | E16: ='Segment GP'!M48 -> 33565.633 | F16: =IFERROR(E16-D16,0) -> 482.99993 | G16: =IFERROR(F16/ABS(D16),0) -> 0.014599803 | H16: ='Segment GP'!N48 -> 33501.708
B17: Product cost — Trading | C17: Rp/kg | D17: =-'Segment GP'!H49 -> 27514.021 | E17: =-'Segment GP'!M49 -> 30783.651 | F17: =IFERROR(E17-D17,0) -> 3269.6306 | G17: =IFERROR(F17/ABS(D17),0) -> 0.11883507
B18: Revenue share — RPA | C18: % | D18: ='Segment GP'!H6/'Segment GP'!H9 -> 0.078941876 | E18: ='Segment GP'!M6/'Segment GP'!M9 -> 0.32190432 | F18: =IFERROR(E18-D18,0) -> 0.24296245
B19: RPA: live bird bought | C19: ton | D19: 4.1017 | E19: ='Batch Economics'!G18/1000 -> 140.71904 | F19: =IFERROR(E19-D19,0) -> 136.61734 | G19: =IFERROR(F19/ABS(D19),0) -> 33.307492 | N19: Jul: 1 batch, PI26070053 Deni Jakaria (boneless run)
B20: RPA: live bird price | C20: Rp/kg | D20: 12350 | E20: ='Batch Economics'!L18 -> 24472.12 | F20: =IFERROR(E20-D20,0) -> 12122.12 | G20: =IFERROR(F20/ABS(D20),0) -> 0.98154821 | N20: Jul batch Rp12,350/kg — not a normal broiler price; July GRN output 4,492 kg > 4,102 kg bought (incl. HJA 1,300 kg at Rp0): not usable as a base
B21: RPA: batches slaughtered | C21: # | D21: 1 | E21: 12 | F21: =IFERROR(E21-D21,0) -> 11
B22: RPA: shrink bought → slaughtered | C22: % | D22: n/m | E22: ='Batch Economics'!O18 -> 0.062797756
B23: RPA: karkas yield on slaughter weight | C23: % | D23: n/m | E23: ='Batch Economics'!AD18 -> 0.73670973
B24: RPA: karkas received fresh | C24: % | D24: n/m | E24: ='Batch Economics'!AF18 -> 0.59320762
B25: RPA: inbound freight | C25: Rp/kg LB | D25: n/m | E25: ='Batch Economics'!AK18 -> 1289.0935
B26: RPA: live bird share of batch cost | C26: % | D26: n/m | E26: ='Batch Economics'!K18/'Batch Economics'!H18 -> 0.89677065
B27: Trading: purchases | C27: ton | D27: =SUMIFS('MA Engine'!$K$6:$K$1110,'MA Engine'!$C$6:$C$1110,"Trading",'MA Engine'!$H$6:$H$1110,7,'MA Engine'!$I$6:$I$1110,"Receipt")/1000 -> 106.94875 | E27: =SUMIFS('MA Engine'!$K$6:$K$1110,'MA Engine'!$C$6:$C$1110,"Trading",'MA Engine'!$H$6:$H$1110,8,'MA Engine'!$I$6:$I$1110,"Receipt")/1000 -> 159.27977 | F27: =IFERROR(E27-D27,0) -> 52.33102 | G27: =IFERROR(F27/ABS(D27),0) -> 0.48930932 | N27: Goods receipts into TRD items (MA Engine)
B28: Trading: average purchase price | C28: Rp/kg | D28: =SUMIFS('MA Engine'!$L$6:$L$1110,'MA Engine'!$C$6:$C$1110,"Trading",'MA Engine'!$H$6:$H$1110,7,'MA Engine'!$I$6:$I$1110,"Receipt")/SUMIFS('MA Engine'!$K$6:$K$1110,'MA Engine'!$C$6:$C$1110,"Trading",'MA Engine'!$H$6:$H$1110,7,'MA Engine'!$I$6:$I$1110,"Receipt") -> 26671.872 | E28: =SUMIFS('MA Engine'!$L$6:$L$1110,'MA Engine'!$C$6:$C$1110,"Trading",'MA Engine'!$H$6:$H$1110,8,'MA Engine'!$I$6:$I$1110,"Receipt")/SUMIFS('MA Engine'!$K$6:$K$1110,'MA Engine'!$C$6:$C$1110,"Trading",'MA Engine'!$H$6:$H$1110,8,'MA Engine'!$I$6:$I$1110,"Receipt") -> 29711.405 | F28: =IFERROR(E28-D28,0) -> 3039.5329 | G28: =IFERROR(F28/ABS(D28),0) -> 0.11396024
B29: Trading: karkas share of kg sold | C29: % | D29: =SUMIFS('Data SKU'!$F$5:$F$116,'Data SKU'!$A$5:$A$116,"Trading",'Data SKU'!$B$5:$B$116,"Karkas",'Data SKU'!$D$5:$D$116,7)/'Segment GP'!H41 -> 0.16089696 | E29: =SUMIFS('Data SKU'!$F$5:$F$116,'Data SKU'!$A$5:$A$116,"Trading",'Data SKU'!$B$5:$B$116,"Karkas",'Data SKU'!$D$5:$D$116,8)/'Segment GP'!M41 -> 0.54989268 | F29: =IFERROR(E29-D29,0) -> 0.38899572
B30: Active customers (with SI / unbilled) | C30: # | D30: =SUMPRODUCT((I_Sales_Inv!$A$5:$A$228=7)/COUNTIFS(I_Sales_Inv!$D$5:$D$228,I_Sales_Inv!$D$5:$D$228,I_Sales_Inv!$A$5:$A$228,I_Sales_Inv!$A$5:$A$228)) -> 22 | E30: =SUMPRODUCT((I_Sales_Inv!$A$5:$A$228=8)/COUNTIFS(I_Sales_Inv!$D$5:$D$228,I_Sales_Inv!$D$5:$D$228,I_Sales_Inv!$A$5:$A$228,I_Sales_Inv!$A$5:$A$228)) -> 26 | F30: =IFERROR(E30-D30,0) -> 4
B32: B. REVENUE BRIDGE Jul → Aug by segment and SKU (IDR)
B33: SKU | C33: Form | D33: Jul revenue | E33: Volume effect | F33: Price effect | G33: New / dropped | H33: Other (no kg) | I33: Aug revenue | J33: Jul kg | K33: Aug kg | L33: Jul ASP | M33: Aug ASP | N33: Note
B34: BLD | C34: Fresh | D34: ='SKU Summary'!F6 -> 0 | E34: =IF(AND(J34>0,K34>0),(K34-J34)*L34,0) -> 0 | F34: =IF(AND(J34>0,K34>0),(M34-L34)*K34,0) -> 0 | G34: =IF(AND(J34>0,K34>0),0,IF(J34>0,-D34,0)+IF(K34>0,I34,0)) -> 9281170 | H34: =I34-D34-E34-F34-G34 -> 0 | I34: ='SKU Summary'!L6 -> 9281170 | J34: ='SKU Summary'!E6 -> 0 | K34: ='SKU Summary'!K6 -> 226.37 | L34: ='SKU Summary'!G6 -> 0 | M34: ='SKU Summary'!M6 -> 41000
B35: BLD | C35: Frozen | D35: ='SKU Summary'!F7 -> 46002000 | E35: =IF(AND(J35>0,K35>0),(K35-J35)*L35,0) -> 18343400 | F35: =IF(AND(J35>0,K35>0),(M35-L35)*K35,0) -> 0 | G35: =IF(AND(J35>0,K35>0),0,IF(J35>0,-D35,0)+IF(K35>0,I35,0)) -> 0 | H35: =I35-D35-E35-F35-G35 -> 0 | I35: ='SKU Summary'!L7 -> 64345400 | J35: ='SKU Summary'!E7 -> 1122 | K35: ='SKU Summary'!K7 -> 1569.4 | L35: ='SKU Summary'!G7 -> 41000 | M35: ='SKU Summary'!M7 -> 41000
B36: BLP | C36: Fresh | D36: ='SKU Summary'!F8 -> 0 | E36: =IF(AND(J36>0,K36>0),(K36-J36)*L36,0) -> 0 | F36: =IF(AND(J36>0,K36>0),(M36-L36)*K36,0) -> 0 | G36: =IF(AND(J36>0,K36>0),0,IF(J36>0,-D36,0)+IF(K36>0,I36,0)) -> 10982800 | H36: =I36-D36-E36-F36-G36 -> 0 | I36: ='SKU Summary'!L8 -> 10982800 | J36: ='SKU Summary'!E8 -> 0 | K36: ='SKU Summary'!K8 -> 274.57 | L36: ='SKU Summary'!G8 -> 0 | M36: ='SKU Summary'!M8 -> 40000
B37: BLP | C37: Frozen | D37: ='SKU Summary'!F9 -> 0 | E37: =IF(AND(J37>0,K37>0),(K37-J37)*L37,0) -> 0 | F37: =IF(AND(J37>0,K37>0),(M37-L37)*K37,0) -> 0 | G37: =IF(AND(J37>0,K37>0),0,IF(J37>0,-D37,0)+IF(K37>0,I37,0)) -> 96460400 | H37: =I37-D37-E37-F37-G37 -> 0 | I37: ='SKU Summary'!L9 -> 96460400 | J37: ='SKU Summary'!E9 -> 0 | K37: ='SKU Summary'!K9 -> 2411.51 | L37: ='SKU Summary'!G9 -> 0 | M37: ='SKU Summary'!M9 -> 40000
B38: Belum ada detail item | C38: n/a | D38: ='SKU Summary'!F10 -> 0 | E38: =IF(AND(J38>0,K38>0),(K38-J38)*L38,0) -> 0 | F38: =IF(AND(J38>0,K38>0),(M38-L38)*K38,0) -> 0 | G38: =IF(AND(J38>0,K38>0),0,IF(J38>0,-D38,0)+IF(K38>0,I38,0)) -> 317493234 | H38: =I38-D38-E38-F38-G38 -> 0 | I38: ='SKU Summary'!L10 -> 317493234 | J38: ='SKU Summary'!E10 -> 0 | K38: ='SKU Summary'!K10 -> 9061.48 | L38: ='SKU Summary'!G10 -> 0 | M38: ='SKU Summary'!M10 -> 35037.68
B39: Ceker | C39: Fresh | D39: ='SKU Summary'!F11 -> 0 | E39: =IF(AND(J39>0,K39>0),(K39-J39)*L39,0) -> 0 | F39: =IF(AND(J39>0,K39>0),(M39-L39)*K39,0) -> 0 | G39: =IF(AND(J39>0,K39>0),0,IF(J39>0,-D39,0)+IF(K39>0,I39,0)) -> 11370200 | H39: =I39-D39-E39-F39-G39 -> 0 | I39: ='SKU Summary'!L11 -> 11370200 | J39: ='SKU Summary'!E11 -> 0 | K39: ='SKU Summary'!K11 -> 3666.8 | L39: ='SKU Summary'!G11 -> 0 | M39: ='SKU Summary'!M11 -> 3100.8509
B40: Ceker | C40: Frozen | D40: ='SKU Summary'!F12 -> 2311000 | E40: =IF(AND(J40>0,K40>0),(K40-J40)*L40,0) -> 0 | F40: =IF(AND(J40>0,K40>0),(M40-L40)*K40,0) -> 0 | G40: =IF(AND(J40>0,K40>0),0,IF(J40>0,-D40,0)+IF(K40>0,I40,0)) -> -2311000 | H40: =I40-D40-E40-F40-G40 -> 0 | I40: ='SKU Summary'!L12 -> 0 | J40: ='SKU Summary'!E12 -> 462.2 | K40: ='SKU Summary'!K12 -> 0 | L40: ='SKU Summary'!G12 -> 5000 | M40: ='SKU Summary'!M12 -> 0
B41: GL adjustment | C41: n/a | D41: ='SKU Summary'!F13 -> 0 | E41: =IF(AND(J41>0,K41>0),(K41-J41)*L41,0) -> 0 | F41: =IF(AND(J41>0,K41>0),(M41-L41)*K41,0) -> 0 | G41: =IF(AND(J41>0,K41>0),0,IF(J41>0,-D41,0)+IF(K41>0,I41,0)) -> 0 | H41: =I41-D41-E41-F41-G41 -> 0 | I41: ='SKU Summary'!L13 -> 0 | J41: ='SKU Summary'!E13 -> 0 | K41: ='SKU Summary'!K13 -> 0 | L41: ='SKU Summary'!G13 -> 0 | M41: ='SKU Summary'!M13 -> 0
B42: HJA (Hati/Jantung/Ampela) | C42: Fresh | D42: ='SKU Summary'!F14 -> 1837500 | E42: =IF(AND(J42>0,K42>0),(K42-J42)*L42,0) -> 31734500 | F42: =IF(AND(J42>0,K42>0),(M42-L42)*K42,0) -> -3254350 | G42: =IF(AND(J42>0,K42>0),0,IF(J42>0,-D42,0)+IF(K42>0,I42,0)) -> 0 | H42: =I42-D42-E42-F42-G42 -> 0 | I42: ='SKU Summary'!L14 -> 30317650 | J42: ='SKU Summary'!E14 -> 367.5 | K42: ='SKU Summary'!K14 -> 6714.4 | L42: ='SKU Summary'!G14 -> 5000 | M42: ='SKU Summary'!M14 -> 4515.3178
...

Sheet Batch Ops KPI
A1: RPA — BATCH OPS KPI, AUGUST 2026
A2: Source: Batch Economics (Accurate goods receipts = ops Pot_ISA sheets; cost = GRN). Value at the price RPA realised in August per form. All cells link to the WP.
B4: A. RPA OPS KPI — AUGUST 2026: input → process → output → sales → stock
B5: # | C5: Data | D5: Agustus | E5: Satuan | F5: Pembanding | G5: Keterangan pembanding | H5: Selisih | I5: Porsi dari rugi produksi Agustus | J5: Kenapa perlu
B6: 1 | C6: Live bird — harga beli | D6: ='Batch Economics'!L18 -> 24472.12 | E6: Rp/kg | F6: ='Batch Economics'!AL18 -> 21705.123 | G6: Harga breakeven (di harga jual Agustus) | H6: =D6-F6 -> 2766.9971 | J6: Ayam dibeli di atas titik impas
C7: Live bird — volume | D7: ='Batch Economics'!G18/1000 -> 140.71904 | E7: ="ton, "&COUNT('Batch Economics'!B6:B17)&" batch" -> ton, 12 batch
B8: 2 | C8: Shrink (dibeli vs diproses) — rata-rata | D8: ='Batch Economics'!O18 -> 0.062797756 | E8: % dari kg dibeli | F8: ='RPA Loss Bridge'!C22 -> 0.02 | G8: Normal | H8: =D8-F8 -> 0.042797756 | I8: ='RPA Loss Bridge'!E32 -> 0.37478745 | J8: Driver #2 rugi produksi
C9: Shrink — batch tertinggi | D9: =MAX('Batch Economics'!O6:O17) -> 0.097179102 | E9: % (terendah di kolom Pembanding) | F9: =MIN('Batch Economics'!O6:O17) -> 0.043254441 | G9: Batch terendah | J9: Variasi antar batch besar
B10: 3 | C10: Freight per kg live bird | D10: ='Batch Economics'!AK18 -> 1289.0935 | E10: Rp/kg LB | F10: ='RPA Loss Bridge'!C23 -> 1000 | G10: Benchmark (batch terbaik) | H10: =D10-F10 -> 289.0935 | I10: ='RPA Loss Bridge'!E34 -> 0.10447915 | J10: Driver #4 rugi produksi
B11: 4 | C11: Yield — karkas ÷ kg diproses | D11: ='Batch Economics'!AD18 -> 0.73670973 | E11: % | F11: ='RPA Loss Bridge'!C24 -> 0.737 | G11: Benchmark | H11: =D11-F11 -> -0.00029026965 | I11: ='RPA Loss Bridge'!E33 -> 0.003617476 | J11: Membuktikan masalahnya bukan yield
C12: Yield — output ÷ kg live bird | D12: ='Batch Economics'!AP18 -> 0.8606497 | E12: % (ops, incl. usus limbah)
C13: Yield — karkas ÷ kg live bird | D13: ='Batch Economics'!AQ18 -> 0.69044601 | E13: %
B14: 5 | C14: Karkas diproduksi fresh | D14: ='Batch Economics'!AF18 -> 0.59320762 | E14: % dari karkas diproduksi | J14: Sisanya keluar frozen
C15: Karkas dari produksi Agustus yang terjual — porsi fresh | D15: =IFERROR(SUMIFS(Vintage!$AC$36:$AC$127,Vintage!$C$36:$C$127,"RPA",Vintage!$BB$36:$BB$127,"Karkas fresh")/(SUMIFS(Vintage!$AC$36:$AC$127,Vintage!$C$36:$C$127,"RPA",Vintage!$BB$36:$BB$127,"Karkas fresh")+SUMIFS(Vintage!$AC$36:$AC$127,Vintage!$C$36:$C$127,"RPA",Vintage!$BB$36:$BB$127,"Karkas frozen")+SUMIFS(Vintage!$AC$36:$AC$127,Vintage!$C$36:$C$127,"RPA",Vintage!$BB$36:$BB$127,"Karkas mix")),0) -> 0.87659448 | E15: % dari karkas terjual | J15: Yang laku terutama fresh
C16: Harga laku karkas fresh | D16: ='Batch Economics'!D23 -> 36794.205 | E16: Rp/kg | F16: ='Batch Economics'!D24 -> 31657.785 | G16: Harga laku karkas frozen | H16: =D16-F16 -> 5136.4193 | I16: ='RPA Loss Bridge'!E31 -> 0.52137991 | J16: Driver #1 rugi produksi (karkas keluar frozen)
B17: 6 | C17: Cost per kg output | D17: ='Batch Economics'!AI18 -> 31792.632 | E17: Rp/kg | F17: ='Batch Economics'!AJ18 -> 28569.003 | G17: Nilai output per kg (harga laku Agustus) | H17: =D17-F17 -> 3223.6284 | J17: Biaya per kg di atas nilai per kg
C18: Cost karkas per kg — as booked | D18: ='Batch Economics'!C58 -> 37149.487 | E18: Rp/kg | F18: ='Batch Economics'!D23 -> 36794.205 | G18: Harga laku karkas fresh | H18: =D18-F18 -> 355.28218 | J18: Karkas fresh pun belum menutup biaya
C19: Cost karkas per kg — kredit by-product | D19: ='Batch Economics'!C59 -> 38712.299 | E19: Rp/kg | F19: ='Batch Economics'!D23 -> 36794.205 | G19: Harga laku karkas fresh | H19: =D19-F19 -> 1918.0941 | J19: By-product dinilai di harga lakunya
B20: 7 | C20: Sisa stok karkas frozen produksi Agustus, 31 Agu | D20: =F58/1000 -> 33.72738 | E20: ton | J20: Risiko margin September
C21: Sisa stok karkas fresh produksi Agustus, 31 Agu | D21: =F59/1000 -> 12.11286 | E21: ton | J21: Aging stok fresh
C22: Sisa stok by-product produksi Agustus, 31 Agu | D22: =F61/1000 -> 14.22802 | E22: ton
C23: Driver lain: maklon tanpa kg (Rp4m) dan sisa spread harga LB vs karkas | D23: =('RPA Loss Bridge'!C35+'RPA Loss Bridge'!C36)/1000000 -> 1.6602658 | E23: Rp mn | I23: ='RPA Loss Bridge'!E35+'RPA Loss Bridge'!E36 -> -0.0042639888 | J23: Kecil — bukan penjelas utama
C24: Rugi produksi Agustus (seluruh output, di harga laku) | D24: ='RPA Loss Bridge'!C30/1000000 -> -389.36918 | E24: Rp mn | I24: =SUM(I8,I10,I11,I16)+I23 -> 1 | J24: Total yang dijelaskan driver di atas
B25: Porsi dari rugi = driver ÷ rugi produksi Agustus (RPA Loss Bridge). Pembanding shrink, freight dan yield = benchmark di RPA Loss Bridge (sel kuning). Semua angka link ke Batch Economics / Vintage.
B32: B. PER BATCH
B33: Cut date | C33: Supplier | D33: Live bird kg | E33: Live bird Rp/kg | F33: Shrink % | G33: Freight Rp/kg LB | H33: Output % of LB | I33: Karkas % of LB | J33: Karkas % of processed | K33: Karkas fresh % | L33: Avg size (Uk) | M33: Cost Rp/kg output | N33: Value Rp/kg output | O33: Gap Rp/kg output | P33: Gap Rp mn | Q33: Breakeven LB Rp/kg | R33: LB price − breakeven
B34: =I_Batch_Ops!B5 -> 46242 | C34: =I_Batch_Ops!E5 -> Priyono | D34: ='Batch Economics'!G6 -> 7000 | E34: ='Batch Economics'!L6 -> 24100 | F34: ='Batch Economics'!O6 -> 0.062428571 | G34: ='Batch Economics'!AK6 -> 1285.7143 | H34: ='Batch Economics'!AP6 -> 0.87044286 | I34: ='Batch Economics'!AQ6 -> 0.68865714 | J34: ='Batch Economics'!AD6 -> 0.73451166 | K34: ='Batch Economics'!AF6 -> 0.94467494 | L34: ='Batch Economics'!U65 -> 1.0786583 | M34: ='Batch Economics'!AI6 -> 32621.081 | N34: ='Batch Economics'!AJ6 -> 31167.436 | O34: =N34-M34 -> -1453.6447 | P34: ='Batch Economics'!AH6/1000000 -> -8.3865124 | Q34: ='Batch Economics'!AL6 -> 22901.927 | R34: =E34-Q34 -> 1198.0732
B35: =I_Batch_Ops!B6 -> 46244 | C35: =I_Batch_Ops!E6 -> Alberus | D35: ='Batch Economics'!G7 -> 11241.1 | E35: ='Batch Economics'!L7 -> 21700 | F35: ='Batch Economics'!O7 -> 0.097179102 | G35: ='Batch Economics'!AK7 -> 2135.0224 | H35: ='Batch Economics'!AP7 -> 0.84487283 | I35: ='Batch Economics'!AQ7 -> 0.67005008 | J35: ='Batch Economics'!AD7 -> 0.74217387 | K35: ='Batch Economics'!AF7 -> 0.83080416 | L35: ='Batch Economics'!U66 -> 1.0634126 | M35: ='Batch Economics'!AI7 -> 29921.113 | N35: ='Batch Economics'!AJ7 -> 29178.046 | O35: =N35-M35 -> -743.06688 | P35: ='Batch Economics'!AH7/1000000 -> -7.0571291 | Q35: ='Batch Economics'!AL7 -> 21072.203 | R35: =E35-Q35 -> 627.79702
B36: =I_Batch_Ops!B7 -> 46245 | C36: =I_Batch_Ops!E7 -> PT Bounty Segar Distribution | D36: ='Batch Economics'!G8 -> 7000 | E36: ='Batch Economics'!L8 -> 24000 | F36: ='Batch Economics'!O8 -> 0.057757143 | G36: ='Batch Economics'!AK8 -> 1000 | H36: ='Batch Economics'!AP8 -> 0.84498571 | I36: ='Batch Economics'!AQ8 -> 0.65964286 | J36: ='Batch Economics'!AD8 -> 0.70007732 | K36: ='Batch Economics'!AF8 -> 0.56591229 | L36: ='Batch Economics'!U67 -> 1.5516665 | M36: ='Batch Economics'!AI8 -> 31370.458 | N36: ='Batch Economics'!AJ8 -> 27716.417 | O36: =N36-M36 -> -3654.0402 | P36: ='Batch Economics'!AH8/1000000 -> -21.613282 | Q36: ='Batch Economics'!AL8 -> 20912.388 | R36: =E36-Q36 -> 3087.6117
B37: =I_Batch_Ops!B8 -> 46248 | C37: =I_Batch_Ops!E8 -> Alberus & Priyono | D37: ='Batch Economics'!G9 -> 15388.94 | E37: ='Batch Economics'!L9 -> 25377.978 | F37: ='Batch Economics'!O9 -> 0.043254441 | G37: ='Batch Economics'!AK9 -> 1169.6712 | H37: ='Batch Economics'!AP9 -> 0.87391334 | I37: ='Batch Economics'!AQ9 -> 0.69555148 | J37: ='Batch Economics'!AD9 -> 0.72699734 | K37: ='Batch Economics'!AF9 -> 0.70315215 | L37: ='Batch Economics'!U68 -> 1.2832181 | M37: ='Batch Economics'!AI9 -> 32129.55 | N37: ='Batch Economics'!AJ9 -> 28743.151 | O37: =N37-M37 -> -3386.3984 | P37: ='Batch Economics'!AH9/1000000 -> -45.542318 | Q37: ='Batch Economics'!AL9 -> 22418.559 | R37: =E37-Q37 -> 2959.4188
B38: =I_Batch_Ops!B9 -> 46253 | C38: =I_Batch_Ops!E9 -> Alberus | D38: ='Batch Economics'!G10 -> 16862.7 | E38: ='Batch Economics'!L10 -> 24435.713 | F38: ='Batch Economics'!O10 -> 0.076025785 | G38: ='Batch Economics'!AK10 -> 1482.5621 | H38: ='Batch Economics'!AP10 -> 0.84772308 | I38: ='Batch Economics'!AQ10 -> 0.6842202 | J38: ='Batch Economics'!AD10 -> 0.74051872 | K38: ='Batch Economics'!AF10 -> 0.7320113 | L38: ='Batch Economics'!U69 -> 1.2523679 | M38: ='Batch Economics'!AI10 -> 32317.904 | N38: ='Batch Economics'!AJ10 -> 29230.453 | O38: =N38-M38 -> -3087.4517 | P38: ='Batch Economics'!AH10/1000000 -> -44.134814 | Q38: ='Batch Economics'!AL10 -> 21818.408 | R38: =E38-Q38 -> 2617.3041
B39: =I_Batch_Ops!B10 -> 46254 | C39: =I_Batch_Ops!E10 -> Alberus | D39: ='Batch Economics'!G11 -> 8177.6 | E39: ='Batch Economics'!L11 -> 25100 | F39: ='Batch Economics'!O11 -> 0.049525533 | G39: ='Batch Economics'!AK11 -> 1100.5674 | H39: ='Batch Economics'!AP11 -> 0.87157601 | I39: ='Batch Economics'!AQ11 -> 0.68988456 | J39: ='Batch Economics'!AD11 -> 0.72583177 | K39: ='Batch Economics'!AF11 -> 0.27965471 | L39: ='Batch Economics'!U70 -> 0.9688794 | M39: ='Batch Economics'!AI11 -> 31805.977 | N39: ='Batch Economics'!AJ11 -> 26881.523 | O39: =N39-M39 -> -4924.4544 | P39: ='Batch Economics'!AH11/1000000 -> -35.098556 | Q39: ='Batch Economics'!AL11 -> 20807.964 | R39: =E39-Q39 -> 4292.0363
B40: =I_Batch_Ops!B11 -> 46255 | C40: =I_Batch_Ops!E11 -> Alberus | D40: ='Batch Economics'!G12 -> 7780.6 | E40: ='Batch Economics'!L12 -> 25100 | F40: ='Batch Economics'!O12 -> 0.061306326 | G40: ='Batch Economics'!AK12 -> 1156.7231 | H40: ='Batch Economics'!AP12 -> 0.85571807 | I40: ='Batch Economics'!AQ12 -> 0.68589826 | J40: ='Batch Economics'!AD12 -> 0.73069445 | K40: ='Batch Economics'!AF12 -> 0.23656942 | L40: ='Batch Economics'!U71 -> 1.0239174 | M40: ='Batch Economics'!AI12 -> 32438.994 | N40: ='Batch Economics'!AJ12 -> 27011.781 | O40: =N40-M40 -> -5427.2123 | P40: ='Batch Economics'!AH12/1000000 -> -36.13438 | Q40: ='Batch Economics'!AL12 -> 20455.836 | R40: =E40-Q40 -> 4644.1636
B41: =I_Batch_Ops!B12 -> 46259 | C41: =I_Batch_Ops!E12 -> Alberus | D41: ='Batch Economics'!G13 -> 12211.6 | E41: ='Batch Economics'!L13 -> 23659.91 | F41: ='Batch Economics'!O13 -> 0.044613318 | G41: ='Batch Economics'!AK13 -> 2088.1785 | H41: ='Batch Economics'!AP13 -> 0.85950244 | I41: ='Batch Economics'!AQ13 -> 0.70221756 | J41: ='Batch Economics'!AD13 -> 0.73500874 | K41: ='Batch Economics'!AF13 -> 0.72141758 | L41: ='Batch Economics'!U72 -> 1.2880539 | M41: ='Batch Economics'!AI13 -> 31735.462 | N41: ='Batch Economics'!AJ13 -> 29491.401 | O41: =N41-M41 -> -2244.0615 | P41: ='Batch Economics'!AH13/1000000 -> -23.553445 | Q41: ='Batch Economics'!AL13 -> 21731.134 | R41: =E41-Q41 -> 1928.7763
B42: =I_Batch_Ops!B13 -> 46260 | C42: =I_Batch_Ops!E13 -> Alberus | D42: ='Batch Economics'!G14 -> 12089.6 | E42: ='Batch Economics'!L14 -> 24148.141 | F42: ='Batch Economics'!O14 -> 0.081747949 | G42: ='Batch Economics'!AK14 -> 1116.6623 | H42: ='Batch Economics'!AP14 -> 0.84611567 | I42: ='Batch Economics'!AQ14 -> 0.67985707 | J42: ='Batch Economics'!AD14 -> 0.74038176 | K42: ='Batch Economics'!AF14 -> 0.60890354 | L42: ='Batch Economics'!U73 -> 1.2514405 | M42: ='Batch Economics'!AI14 -> 31987.197 | N42: ='Batch Economics'!AJ14 -> 28603.238 | O42: =N42-M42 -> -3383.9595 | P42: ='Batch Economics'!AH14/1000000 -> -34.615198 | Q42: ='Batch Economics'!AL14 -> 21284.919 | R42: =E42-Q42 -> 2863.2212
B43: =I_Batch_Ops!B14 -> 46261 | C43: =I_Batch_Ops!E14 -> Alberus | D43: ='Batch Economics'!G15 -> 11681.4 | E43: ='Batch Economics'!L15 -> 24600 | F43: ='Batch Economics'!O15 -> 0.064238875 | G43: ='Batch Economics'!AK15 -> 1232.729 | H43: ='Batch Economics'!AP15 -> 0.86254216 | I43: ='Batch Economics'!AQ15 -> 0.69582413 | J43: ='Batch Economics'!AD15 -> 0.74359162 | K43: ='Batch Economics'!AF15 -> 0.67556162 | L43: ='Batch Economics'!U74 -> 1.2210083 | M43: ='Batch Economics'!AI15 -> 31685.346 | N43: ='Batch Economics'!AJ15 -> 28979.874 | O43: =N43-M43 -> -2705.472 | P43: ='Batch Economics'!AH15/1000000 -> -27.259524 | Q43: ='Batch Economics'!AL15 -> 22266.416 | R43: =E43-Q43 -> 2333.5837
B44: =I_Batch_Ops!B15 -> 46262 | C44: =I_Batch_Ops!E15 -> Alberus | D44: ='Batch Economics'!G16 -> 15537.2 | E44: ='Batch Economics'!L16 -> 25412.043 | F44: ='Batch Economics'!O16 -> 0.055795124 | G44: ='Batch Economics'!AK16 -> 965.42492 | H44: ='Batch Economics'!AP16 -> 0.87102567 | I44: ='Batch Economics'!AQ16 -> 0.70322194 | J44: ='Batch Economics'!AD16 -> 0.74477686 | K44: ='Batch Economics'!AF16 -> 0.42209022 | L44: ='Batch Economics'!U75 -> 1.223356 | M44: ='Batch Economics'!AI16 -> 32017.651 | N44: ='Batch Economics'!AJ16 -> 27945.367 | O44: =N44-M44 -> -4072.2844 | P44: ='Batch Economics'!AH16/1000000 -> -55.111447 | Q44: ='Batch Economics'!AL16 -> 21864.979 | R44: =E44-Q44 -> 3547.0643
B45: =I_Batch_Ops!B16 -> 46265 | C45: =I_Batch_Ops!E16 -> Alberus | D45: ='Batch Economics'!G17 -> 15748.3 | E45: ='Batch Economics'!L17 -> 25200 | F45: ='Batch Economics'!O17 -> 0.058615851 | G45: ='Batch Economics'!AK17 -> 761.98701 | H45: ='Batch Economics'!AP17 -> 0.87257037 | I45: ='Batch Economics'!AQ17 -> 0.70611431 | J45: ='Batch Economics'!AD17 -> 0.75008094 | K45: ='Batch Economics'!AF17 -> 0.3690974 | L45: ='Batch Economics'!U76 -> 1.3639922 | M45: ='Batch Economics'!AI17 -> 31479.641 | N45: ='Batch Economics'!AJ17 -> 27778.256 | O45: =N45-M45 -> -3701.3843 | P45: ='Batch Economics'!AH17/1000000 -> -50.862572 | Q45: ='Batch Economics'!AL17 -> 21970.282 | R45: =E45-Q45 -> 3229.7183
B46: TOTAL | C46: Agustus — total | D46: ='Batch Economics'!G18 -> 140719.04 | E46: ='Batch Economics'!L18 -> 24472.12 | F46: ='Batch Economics'!O18 -> 0.062797756 | G46: ='Batch Economics'!AK18 -> 1289.0935 | H46: ='Batch Economics'!AP18 -> 0.8606497 | I46: ='Batch Economics'!AQ18 -> 0.69044601 | J46: ='Batch Economics'!AD18 -> 0.73670973 | K46: ='Batch Economics'!AF18 -> 0.59320762 | L46: ='Batch Economics'!U77 -> 1.2276753 | M46: ='Batch Economics'!AI18 -> 31792.632 | N46: ='Batch Economics'!AJ18 -> 28569.003 | O46: =N46-M46 -> -3223.6284 | P46: ='Batch Economics'!AH18/1000000 -> -389.36918 | Q46: ='Batch Economics'!AL18 -> 21705.123 | R46: =E46-Q46 -> 2766.9971
B47: Benchmark | F47: ='RPA Loss Bridge'!C22 -> 0.02 | G47: ='RPA Loss Bridge'!C23 -> 1000 | J47: ='RPA Loss Bridge'!C24 -> 0.737 | O47: 0
...

Sheet RPA KPI vs Budget
A1: RPA — KPI PENGGERAK UTAMA: BUDGET vs AKTUAL AGUSTUS 2026
A2: Budget = KGR_-_Budget_Manufacturing_v3.xlsx (bulan pertama Sep-26 atau kartu biaya standar; nilai biru disalin dari sel yang disebut). Aktual = WP ini (Batch Economics, Accurate = ops). Budget memodelkan pabrik sendiri; Agustus masih maklon di ISA.
B5: # | C5: KPI | D5: Definisi | E5: Satuan | F5: Budget | G5: Sumber budget | H5: Target KPI (B_KPI) | I5: Aktual Agustus | J5: Selisih aktual − budget | K5: Status | L5: Dampak vs budget Rp mn (indikatif) | M5: Pemilik | N5: Catatan
B6: A. VOLUME DAN KAPASITAS
B7: 1 | C7: Live bird diterima | D7: kg diterima (PI) per bulan | E7: ton | F7: 432.28664 | G7: O_Produksi!I14 (Sep-26) | H7: — | I7: ='Batch Economics'!G18/1000 -> 140.71904 | J7: =IF(ISNUMBER(I7),I7-F7,"") -> -291.5676 | K7: =IF(ISNUMBER(I7),IF(I7>=F7,"On","Off"),"—") -> Off | M7: Direktur Operasional | N7: Agustus 12 batch; budget mengasumsikan potong setiap hari
B8: 2 | C8: kg masuk lini per hari potong | D8: kg diproses ÷ hari potong | E8: kg/hari | F8: 14265.459 | G8: O_Produksi!I22 (Sep-26) | H8: =20000 -> 20000 | I8: ='Batch Economics'!M18/COUNT('Batch Economics'!B6:B17) -> 10990.183 | J8: =IF(ISNUMBER(I8),I8-F8,"") -> -3275.2756 | K8: =IF(ISNUMBER(I8),IF(I8>=F8,"On","Off"),"—") -> Off | M8: Manajer Operasional | N8: Target volume 20 t/hari (Assumptions!G55)
B9: 3 | C9: Utilisasi vs volume normal | D9: kg masuk lini ÷ volume normal bulanan | E9: % | F9: 0.41084563 | G9: O_Produksi!I25 (Sep-26) | H9: ≥ 95% | I9: ='Batch Economics'!M18/1041665.625 -> 0.12660704 | J9: =IF(ISNUMBER(I9),I9-F9,"") -> -0.28423859 | K9: =IF(ISNUMBER(I9),IF(I9>=F9,"On","Off"),"—") -> Off | M9: Manajer Operasional | N9: Volume normal 1,041,666 kg/bln (Assumptions!G24). Di bawah 95% overhead tak terserap jadi beban periode (PSAK 14)
B10: B. BAHAN BAKU
B11: 4 | C11: Harga live bird | D11: Rp per kg diterima | E11: Rp/kg | F11: 24805.388 | G11: O_Weekly RPA!H15 (rata-rata rencana) | H11: ≤ Rp 20.000 | I11: ='Batch Economics'!L18 -> 24472.12 | J11: =IF(ISNUMBER(I11),I11-F11,"") -> -333.26765 | K11: =IF(ISNUMBER(I11),IF(I11<=F11,"On","Off"),"—") -> On | L11: =(F11-I11)*'Batch Economics'!G18/1000000 -> 46.897103 | M11: Manajer Operasional | N11: B_KPI: di atas Rp22.000 pabrik tidak BEP di volume berapa pun
B12: 5 | C12: Ongkos angkut live bird | D12: freight inbound ÷ kg diterima | E12: Rp/kg LB | F12: 0 | G12: tidak dimodelkan | H12: — | I12: ='Batch Economics'!AK18 -> 1289.0935 | J12: =IF(ISNUMBER(I12),I12-F12,"") -> 1289.0935 | K12: =IF(ISNUMBER(I12),IF(I12<=F12,"On","Off"),"—") -> Off | L12: =(F12-I12)*'Batch Economics'!G18/1000000 -> -181.4 | M12: Manajer Operasional | N12: Budget menganggap harga LB sudah sampai pabrik. Aktual Rp181m di Agustus — perlu masuk budget
B13: C. PROSES
B14: 6 | C14: Susut penerimaan s.d. masuk lini | D14: (kg diterima − kg diproses) ÷ kg diterima | E14: % | F14: 0.01 | G14: I_Model Details!G25:G27 (DOA + mortalitas + susut holding) | H14: ≤ 2% (akurasi terima) | I14: ='Batch Economics'!O18 -> 0.062797756 | J14: =IF(ISNUMBER(I14),I14-F14,"") -> 0.052797756 | K14: =IF(ISNUMBER(I14),IF(I14<=F14,"On","Off"),"—") -> Off | L14: =(F14-I14)*'Batch Economics'!G18*'Batch Economics'!L18/1000000 -> -181.81928 | M14: Supervisor Produksi | N14: Aktual = kg PI vs kg tagihan maklon; belum dipisah DOA / mati / susut timbang
B15: 7 | C15: Yield total | D15: kg output ÷ kg masuk lini | E15: % | F15: 0.8879778 | G15: O_Produksi!I44 (Sep-26) | H15: 89,2% (indikatif) | I15: ='Batch Economics'!AC18/'Batch Economics'!M18 -> 0.91586279 | J15: =IF(ISNUMBER(I15),I15-F15,"") -> 0.027884993 | K15: =IF(ISNUMBER(I15),IF(I15>=F15,"On","Off"),"—") -> On | M15: PPIC | N15: Output di stok Accurate (tanpa usus limbah 8 Agu)
B16: 8 | C16: Yield karkas | D16: kg karkas ÷ kg masuk lini | E16: % | F16: 0.69416 | G16: O_Costing!E35 (kartu standar) | H16: — | I16: ='Batch Economics'!AD18 -> 0.73670973 | J16: =IF(ISNUMBER(I16),I16-F16,"") -> 0.04254973 | K16: =IF(ISNUMBER(I16),IF(I16>=F16,"On","Off"),"—") -> On | L16: =(I16-F16)*'Batch Economics'!M18*(('Batch Economics'!T18*'Batch Economics'!D23+'Batch Economics'!U18*'Batch Economics'!D24)/'Batch Economics'!V18)/1000000 -> 194.7475 | M16: PPIC | N16: Dampak dinilai di harga laku karkas Agustus
B17: 9 | C17: Yield by-product | D17: kg by-product (termasuk limbah) ÷ kg masuk lini | E17: % | F17: =SUM(F42:F47) -> 0.19828 | G17: O_Costing!E36:E41 | H17: ≤ 5% deviasi relatif | I17: =('Batch Economics'!AB18+'Batch Economics'!AN18)/'Batch Economics'!M18 -> 0.18160828 | J17: =IF(ISNUMBER(I17),I17-F17,"") -> -0.016671716 | K17: =IF(ISNUMBER(I17),IF(I17>=F17,"On","Off"),"—") -> Off | L17: =(I17-F17)*'Batch Economics'!M18*(('Batch Economics'!W18*'Batch Economics'!D25+'Batch Economics'!X18*'Batch Economics'!D26+'Batch Economics'!Y18*'Batch Economics'!D27+'Batch Economics'!Z18*'Batch Economics'!D28+'Batch Economics'!AA18*'Batch Economics'!D29)/'Batch Economics'!AB18)/1000000 -> -7.3386361 | M17: PPIC | N17: Budget termasuk kerongkongan 3,9% (tidak ada di Agustus — karkas dijual utuh). Rincian per produk di bawah
B18: 10 | C18: Kondemnasi post-mortem | D18: kg dikondemnasi ÷ kg masuk lini | E18: % | F18: 0.005 | G18: I_Model Details!G28 | H18: ≤ 0,5% | I18: n/a | K18: =IF(ISNUMBER(I18),"info","—") -> — | M18: Dokter Hewan | N18: Belum dicatat — perlu kolom di Yield Report
B19: D. BAURAN OUTPUT
B20: 11 | C20: Karkas dijual utuh | D20: kg karkas utuh ÷ karkas total | E20: % | F20: 0.81328512 | G20: Assumptions!G77 | H20: — | I20: ='Batch Economics'!V18/('Batch Economics'!V18+SUMIFS('MA Engine'!$K$6:$K$1110,'MA Engine'!$C$6:$C$1110,"RPA",'MA Engine'!$H$6:$H$1110,8,'MA Engine'!$I$6:$I$1110,"Receipt",'MA Engine'!$D$6:$D$1110,"BLD")+SUMIFS('MA Engine'!$K$6:$K$1110,'MA Engine'!$C$6:$C$1110,"RPA",'MA Engine'!$H$6:$H$1110,8,'MA Engine'!$I$6:$I$1110,"Receipt",'MA Engine'!$D$6:$D$1110,"BLP")) -> 1 | J20: =IF(ISNUMBER(I20),I20-F20,"") -> 0.18671488 | K20: =IF(ISNUMBER(I20),"info","—") -> info | M20: PPIC | N20: Agustus tanpa cut-up
B21: 12 | C21: Porsi output dibekukan | D21: kg produk beku ÷ total output | E21: % | F21: 0.6 | G21: I_Model Details!G29 | H21: — | I21: =SUMIFS('MA Engine'!$K$6:$K$1110,'MA Engine'!$C$6:$C$1110,"RPA",'MA Engine'!$H$6:$H$1110,8,'MA Engine'!$I$6:$I$1110,"Receipt",'MA Engine'!$E$6:$E$1110,"Frozen")/'Batch Economics'!AC18 -> 0.33036113 | J21: =IF(ISNUMBER(I21),I21-F21,"") -> -0.26963887 | K21: =IF(ISNUMBER(I21),"info","—") -> info | L21: ='RPA Loss Bridge'!C31/1000000 -> -203.00927 | M21: Manajer Sales | N21: Budget butuh premium harga beku +Rp1.122/kg (B_UnitEcon); aktual frozen DISKON Rp5,136/kg. Dampak = driver #1 Loss Bridge
B22: E. HARGA JUAL
B23: 13 | C23: Harga karkas (bauran fresh + frozen) | D23: nilai karkas ÷ kg, di harga laku Agustus | E23: Rp/kg | F23: 37150.028 | G23: I_Model Details!I120 (Sep-26) | H23: — | I23: =(('Batch Economics'!T18*'Batch Economics'!D23+'Batch Economics'!U18*'Batch Economics'!D24)/'Batch Economics'!V18) -> 34704.748 | J23: =IF(ISNUMBER(I23),I23-F23,"") -> -2445.2798 | K23: =IF(ISNUMBER(I23),IF(I23>=F23,"On","Off"),"—") -> Off | L23: =(I23-F23)*'Batch Economics'!V18/1000000 -> -237.58069 | M23: Manajer Sales | N23: Fresh Rp36,794, frozen Rp31,658. Harga pasar acuan budget Rp33.106 (Assumptions!G56)
B24: 14 | C24: Harga by-product (bauran aktual) | D24: nilai by-product ÷ kg | E24: Rp/kg | F24: =('Batch Economics'!W18*F50+'Batch Economics'!X18*F51+'Batch Economics'!Y18*F52+'Batch Economics'!Z18*F53+'Batch Economics'!AA18*F54)/'Batch Economics'!AB18 -> 7429.7511 | G24: I_Model Details!I128:I132 (Sep-26), dibobot bauran aktual | H24: — | I24: =(('Batch Economics'!W18*'Batch Economics'!D25+'Batch Economics'!X18*'Batch Economics'!D26+'Batch Economics'!Y18*'Batch Economics'!D27+'Batch Economics'!Z18*'Batch Economics'!D28+'Batch Economics'!AA18*'Batch Economics'!D29)/'Batch Economics'!AB18) -> 3337.712 | J24: =IF(ISNUMBER(I24),I24-F24,"") -> -4092.0391 | K24: =IF(ISNUMBER(I24),IF(I24>=F24,"On","Off"),"—") -> Off | L24: =(I24-F24)*'Batch Economics'!AB18/1000000 -> -96.683017 | M24: Manajer Sales | N24: Budget kepala/ceker Rp11,6rb, usus Rp7,0rb; laku Agustus Rp4,0rb / Rp3,1rb / Rp1,5rb
B25: F. BIAYA KONVERSI
B26: 15 | C26: Biaya potong per kg masuk lini | D26: maklon ÷ kg diproses (budget: Pool A tenaga + overhead) | E26: Rp/kg | F26: 1232.5107 | G26: I_Model Details!I179 (Sep-26, pabrik sendiri) | H26: — | I26: ='Batch Economics'!J18/'Batch Economics'!M18 -> 1630.3301 | J26: =IF(ISNUMBER(I26),I26-F26,"") -> 397.81941 | K26: =IF(ISNUMBER(I26),IF(I26<=F26,"On","Off"),"—") -> Off | L26: =(F26-I26)*'Batch Economics'!M18/1000000 -> -52.465299 | M26: Manajer Accounting | N26: Di volume Agustus, Pool A pabrik sendiri ≈ Rp4,000/kg — maklon masih lebih murah
B27: G. HASIL PER KG
B28: 16 | C28: Nilai output per kg | D28: nilai output di harga laku ÷ kg output | E28: Rp/kg | F28: 27816.022 | G28: B_RPA_Summary!G89 | H28: — | I28: ='Batch Economics'!AJ18 -> 28569.003 | J28: =IF(ISNUMBER(I28),I28-F28,"") -> 752.98128 | K28: =IF(ISNUMBER(I28),IF(I28>=F28,"On","Off"),"—") -> On | M28: Manajer Sales
B29: 17 | C29: Biaya per kg output | D29: biaya batch ÷ kg output | E29: Rp/kg | F29: 30471.5 | G29: B_RPA_Summary!H52 (20 t/hari) | H29: — | I29: ='Batch Economics'!AI18 -> 31792.632 | J29: =IF(ISNUMBER(I29),I29-F29,"") -> 1321.1317 | K29: =IF(ISNUMBER(I29),IF(I29<=F29,"On","Off"),"—") -> Off | M29: Manajer Accounting | N29: Budget termasuk storage, kemasan, G&A (Rp2.255/kg); aktual hanya LB + angkut + maklon
B30: 18 | C30: Kontribusi per kg live bird | D30: (nilai output − LB − angkut − maklon) ÷ kg LB | E30: Rp/kg | F30: 1835 | G30: B_KPI!F26 (kartu standar) | H30: Rp 1.835 | I30: =('Batch Economics'!AG18-'Batch Economics'!H18)/'Batch Economics'!G18 -> -2766.9971 | J30: =IF(ISNUMBER(I30),I30-F30,"") -> -4601.9971 | K30: =IF(ISNUMBER(I30),IF(I30>=F30,"On","Off"),"—") -> Off | L30: =(I30-F30)*'Batch Economics'!G18/1000000 -> -647.58862 | M30: Manajer Accounting | N30: Selisih total terhadap kartu standar — bukan jumlah dari baris lain
B31: 19 | C31: Harga breakeven live bird | D31: harga LB maksimum agar kontribusi = 0 | E31: Rp/kg | F31: 21912.653 | G31: B_Summary!G362 (ambang own = maklon) | H31: — | I31: ='Batch Economics'!AL18 -> 21705.123 | J31: =IF(ISNUMBER(I31),I31-F31,"") -> -207.53003 | K31: =IF(ISNUMBER(I31),IF(I31>=F31,"On","Off"),"—") -> Off | M31: Manajer Operasional | N31: Aktual: harga beli Rp2.767/kg di atas breakeven
B32: Status: On = aktual sama atau lebih baik dari budget. Dampak = (aktual − budget) × volume Agustus, di harga laku Agustus; indikatif, antar baris tumpang tindih sehingga tidak dijumlah. Kontribusi per kg (#18) adalah selisih totalnya.
B40: H. YIELD DAN HARGA PER BY-PRODUCT — budget (kartu standar / Sep-26) vs aktual Agustus
C41: Produk | E41: Satuan | F41: Yield budget ÷ kg masuk lini | G41: Sumber | I41: Yield aktual ÷ kg masuk lini | J41: Selisih | K41: Status
C42: Kerongkongan | E42: % | F42: 0.03906 | G42: O_Costing!E36 | I42: 0 | J42: =I42-F42 -> -0.03906 | K42: =IF(ABS(I42/F42-1)<=5%,"On","Off") -> Off
C43: Kepala | E43: % | F43: 0.05267 | G43: O_Costing!E37 | I43: ='Batch Economics'!X18/'Batch Economics'!M18 -> 0.046732614 | J43: =I43-F43 -> -0.0059373856 | K43: =IF(ABS(I43/F43-1)<=5%,"On","Off") -> Off
C44: Ceker | E44: % | F44: 0.03026 | G44: O_Costing!E38 | I44: ='Batch Economics'!Z18/'Batch Economics'!M18 -> 0.029439151 | J44: =I44-F44 -> -0.000820849 | K44: =IF(ABS(I44/F44-1)<=5%,"On","Off") -> On
C45: Usus (incl. limbah) | E45: % | F45: 0.04192 | G45: O_Costing!E39 | I45: =('Batch Economics'!Y18+'Batch Economics'!AN18)/'Batch Economics'!M18 -> 0.046029714 | J45: =I45-F45 -> 0.0041097144 | K45: =IF(ABS(I45/F45-1)<=5%,"On","Off") -> Off
C46: HJA / giblet | E46: % | F46: 0.03193 | G46: O_Costing!E40 | I46: ='Batch Economics'!W18/'Batch Economics'!M18 -> 0.056040921 | J46: =I46-F46 -> 0.024110921 | K46: =IF(ABS(I46/F46-1)<=5%,"On","Off") -> Off
C47: Lemak | E47: % | F47: 0.00244 | G47: O_Costing!E41 | I47: ='Batch Economics'!AA18/'Batch Economics'!M18 -> 0.0033658826 | J47: =I47-F47 -> 0.00092588258 | K47: =IF(ABS(I47/F47-1)<=5%,"On","Off") -> Off
C48: Total by-product | F48: =SUM(F42:F47) -> 0.19828 | I48: =SUM(I42:I47) -> 0.18160828 | J48: =I48-F48 -> -0.016671716
C49: Produk | E49: Satuan | F49: Harga budget Sep-26 | G49: Sumber | I49: Harga laku Agustus | J49: Selisih | K49: Status
...

Sheet Segment GP
A1: GROSS PROFIT BY SEGMENT — RPA and Trading, March to August 2026 (Rp)
A2: Mar–Jul and "Aug as booked" follow the accounting mapping (PL - Performance): unbilled revenue and all its HPP sit in RPA. Columns J–L move the 10 unbilled invoices to the segment of their items and re-cost them; M is the corrected August.
B4: Line | C4: Source / basis | D4: Mar-26 | E4: Apr-26 | F4: May-26 | G4: Jun-26 | H4: Jul-26 | I4: Aug-26 as booked | J4: Adj-1 unbilled to item segment | K4: Adj-2 HPP at MA on SJ date | L4: Adj-3 later DOs re-costed | M4: Aug-26 CORRECTED | N4: YTD Mar–Aug corrected
B5: A. REVENUE
B6: Revenue — RPA | C6: GL 4101006/07/10 (+4101013 as booked) | D6: =-(SUMIFS(I_GL!$D$5:$D$29,I_GL!$C$5:$C$29,"Rev RPA")+SUMIFS(I_GL!$D$5:$D$29,I_GL!$C$5:$C$29,"Rev Unbilled")) -> 190035900 | E6: =-(SUMIFS(I_GL!$E$5:$E$29,I_GL!$C$5:$C$29,"Rev RPA")+SUMIFS(I_GL!$E$5:$E$29,I_GL!$C$5:$C$29,"Rev Unbilled")) -> 646041120 | F6: =-(SUMIFS(I_GL!$F$5:$F$29,I_GL!$C$5:$C$29,"Rev RPA")+SUMIFS(I_GL!$F$5:$F$29,I_GL!$C$5:$C$29,"Rev Unbilled")) -> 1402180774 | G6: =-(SUMIFS(I_GL!$G$5:$G$29,I_GL!$C$5:$C$29,"Rev RPA")+SUMIFS(I_GL!$G$5:$G$29,I_GL!$C$5:$C$29,"Rev Unbilled")) -> 5.0030944e+08 | H6: =-(SUMIFS(I_GL!$H$5:$H$29,I_GL!$C$5:$C$29,"Rev RPA")+SUMIFS(I_GL!$H$5:$H$29,I_GL!$C$5:$C$29,"Rev Unbilled")) -> 246532160 | I6: =-(SUMIFS(I_GL!$I$5:$I$29,I_GL!$C$5:$C$29,"Rev RPA")+SUMIFS(I_GL!$I$5:$I$29,I_GL!$C$5:$C$29,"Rev Unbilled")) -> 3044438109 | J6: =SUMIFS(I_GL!$I$5:$I$29,I_GL!$C$5:$C$29,"Rev Unbilled")+Unbilled!J44 -> -3.5275112e+08 | K6: 0 | L6: 0 | M6: =SUM(I6:L6) -> 2.691687e+09 | N6: =SUM(D6:H6)+M6 -> 5.6767864e+09
B7: Revenue — Trading | C7: GL 4101012 less 4101004 | D7: =-SUMIFS(I_GL!$D$5:$D$29,I_GL!$C$5:$C$29,"Rev Trading") -> 0 | E7: =-SUMIFS(I_GL!$E$5:$E$29,I_GL!$C$5:$C$29,"Rev Trading") -> 149939860 | F7: =-SUMIFS(I_GL!$F$5:$F$29,I_GL!$C$5:$C$29,"Rev Trading") -> 44220195 | G7: =-SUMIFS(I_GL!$G$5:$G$29,I_GL!$C$5:$C$29,"Rev Trading") -> 922384240 | H7: =-SUMIFS(I_GL!$H$5:$H$29,I_GL!$C$5:$C$29,"Rev Trading") -> 2.8764258e+09 | I7: =-SUMIFS(I_GL!$I$5:$I$29,I_GL!$C$5:$C$29,"Rev Trading") -> 5317322794 | J7: =Unbilled!J45 -> 3.5275112e+08 | K7: 0 | L7: 0 | M7: =SUM(I7:L7) -> 5.6700739e+09 | N7: =SUM(D7:H7)+M7 -> 9.663044e+09
B8: Revenue — unbilled, segment not yet known | C8: 6 invoices without item detail | D8: 0 | E8: 0 | F8: 0 | G8: 0 | H8: 0 | I8: 0 | J8: =Unbilled!J46 -> 0 | K8: 0 | L8: 0 | M8: =SUM(I8:L8) -> 0 | N8: =SUM(D8:H8)+M8 -> 0
B9: TOTAL REVENUE | D9: =SUM(D6:D8) -> 190035900 | E9: =SUM(E6:E8) -> 795980980 | F9: =SUM(F6:F8) -> 1446400969 | G9: =SUM(G6:G8) -> 1.4226937e+09 | H9: =SUM(H6:H8) -> 3.1229579e+09 | I9: =SUM(I6:I8) -> 8361760903 | J9: =SUM(J6:J8) -> 0 | K9: =SUM(K6:K8) -> 0 | ... N9: =SUM(N6:N8) -> 1.533983e+10
B10: B. PRODUCT COGS (live bird + inbound freight + maklon for RPA; purchase cost for Trading)
